Workbook

Sheet D.B. detail
E2: BUILDING NAME:
E3: PANEL NAME | M3: MOUNTING | Q3: WALL | S3: 380/220V ,3PH.4W,SN
E4: LOCATION | M4: ROOM NO. | X4: TRIP | Y4: FRAM
E5: FEEDER ENTRY | H5: BOTTOM | M5: NO. OF WAYS | Q5: 16 | S5: MAIN CIRCUIT BREAKER | X5: 250 | Y5: 250 | Z5: AMP.
B6: CONDUITE | C6: WIRE | D6: CCT | E6: DESCRIPTION | F6: CONNECTED LOAD | I6: CIRCUIT BREAKER | L6: DERI. FAC. | M6: DEMAND | N6: R. | O6: Y. | P6: B. | Q6: DEMAND | R6: DERI. FAC. | S6: CIRCUIT BREAKER | V6: CONNECTED LOAD | Y6: DESCRIPTION | Z6: CCT | AA6: WIRE | AB6: CONDUITE
B7: SIZE | C7: SIZE | D7: NO. | F7: PH."R" | G7: PH."Y" | H7: PH."B" | I7: NO. OF | J7: TRIP | K7: F.R.A. | M7: LOAD | Q7: LOAD | S7: F.R.A. | T7: TRIP | U7: NO. OF | V7: PH."R" | W7: PH."Y" | X7: PH."B" | Z7: NO. | AA7: SIZE | AB7: SIZE
B8: MM | C8: MM2 | F8: VA | G8: VA | H8: VA | I8: POLES | J8: AMP. | K8: AMP. | M8: AMP. | Q8: AMP. | S8: AMP. | T8: AMP. | U8: POLES | V8: VA | W8: VA | X8: VA | AA8: MM2 | AB8: MM
B9: 12 | C9: 2x25+10E | D9: 1 | N9: * | Z9: 2 | AA9: 2x25+10E
D10: 3 | O10: * | Z10: 4
D11: 5 | P11: * | Z11: 6
D12: 7 | N12: * | Z12: 8
D13: 9 | O13: * | Z13: 10
B14: 38P.V.C. | D14: 11 | P14: * | Z14: 12
D15: 13 | N15: * | Z15: 14
D16: 15 | O16: * | Z16: 16
D17: 17 | P17: * | Z17: 18
D18: 19 | N18: * | Z18: 20
D19: 21 | O19: * | Z19: 22
D20: 23 | P20: * | Z20: 24
D21: 25 | N21: * | Z21: 26
D22: 27 | O22: * | Z22: 28
D23: 29 | P23: * | Z23: 30
D24: 31 | N24: * | Z24: 32
D25: 33 | O25: * | Z25: 34
D26: 35 | P26: * | Z26: 36
D27: 37 | N27: * | Z27: 38
D28: 39 | O28: * | Z28: 40
D29: 41 | P29: * | Z29: 42
D30: 43 | N30: * | Z30: 44
D31: 45 | O31: * | Z31: 46
D32: 47 | F32: 30600 | G32: 28200 | H32: 29600 | P32: * | V32: 29600 | W32: 31200 | X32: 22800 | Z32: 48
C33: SUB. TOTA CONNECTED LOAD V.A. | F33: =SUM(F9:F32) -> 30600 | G33: =SUM(G9:G32) -> 28200 | H33: =SUM(H9:H32) -> 29600 | V33: =SUM(V9:V32) -> 29600 | W33: =SUM(W9:W32) -> 31200 | X33: =SUM(X9:X32) -> 22800 | Y33: SUB. TOTA CONNECTED LOAD V.A.
C34: SUB. TOTA DEMAND LOAD | F34: =F33*G37 -> 22338 | G34: =G33*G37 -> 20586 | H34: =H33*G37 -> 21608 | V34: =V33*G37 -> 21608 | W34: =W33*G37 -> 22776 | X34: =X33*G37 -> 16644 | Y34: SUB. TOTA DEMAND LOAD
C36: TOTAL CONNECTED LOAD | G36: =SUM(F33+G33+H33+V33+W33+X33)/1000 -> 172 | I36: K.V.A. | M36: 1CABLE = | S36: =G38*1000/(380*1.7321) -> 190.76327 | U36: AMP. | X36: NOTE:
C37: DEMAND FACTOR | G37: 0.73
C38: TOTAL DEMAND LOAD | G38: =G36*G37 -> 125.56 | I38: K.V.A. | M38: CABLE SIZE = | R38: 4X300+70EPVC SINGL CORE CABLE

Sheet Laminaire cal.
B2: ='D.B. detail'!H2 -> 0
J3: GROUND FLOOR
B4: Room NO. | C4: LIGHTING
C5: L | D5: W | E5: A | F5: h | G5: K * | H5: Type | J5: Selected Laminaire Specs. | K5: Rated Fluxe | L5: Lamp/lami Z | M5: Lumi. FluxQ | N5: Lampe Power | O5: Utaliation Factor B* | P5: Maintenance Factor V* | Q5: NO. of Laminaire n* | R5: Actual NO. N | S5: Actual Fluxe e* | T5: Total power
B6: EN /LOOPY | C6: 18 | D6: 8 | E6: =C6*D6 -> 144 | F6: 3 | G6: =E6/((C6+D6)*F6) -> 1.8461538 | H6: loppy | J6: Recessed Circular Modular Laminaire with Compact Fluorecsent Lamp 36w warm wight | K6: 300 | L6: 1 | M6: 2800 | N6: 36 | O6: 48 | P6: 0.8 | Q6: =K6*E6*100/(L6*M6*O6*P6) -> 40.178571 | R6: 27 | S6: =R6*L6*M6*O6*P6/(E6*100) -> 201.6 | T6: =R6*N6*L6 -> 972
B7: Hall Part | C7: 18 | D7: 8 | E7: =C7*D7 -> 144 | F7: 3 | G7: =E7/((C7+D7)*F7) -> 1.8461538 | H7: Hall | J7: Recessed Modular Fluorescent Laminaire with brightness louvers (reflection) with Fluorecsent Lamp 4x18w warm wight | K7: 200 | L7: 4 | M7: 1450 | N7: 21 | O7: 51 | P7: 0.8 | Q7: =K7*E7*100/(L7*M7*O7*P7) -> 12.170385 | R7: 12 | S7: =R7*L7*M7*O7*P7/(E7*100) -> 197.2 | T7: =R7*N7*L7 -> 1008
C8: 7.2 | D8: 5.6 | E8: =C8*D8 -> 40.32 | F8: 2 | G8: =E8/((C8+D8)*F8) -> 1.575 | H8: Office | K8: 300 | L8: 4 | M8: 1450 | N8: 21 | O8: 59 | P8: 0.8 | Q8: =K8*E8*100/(L8*M8*O8*P8) -> 4.4184687 | R8: 6 | S8: =R8*L8*M8*O8*P8/(E8*100) -> 407.38095 | T8: =R8*N8*L8 -> 504
C9: 9.3 | D9: 3.6 | E9: =C9*D9 -> 33.48 | F9: 2 | G9: =E9/((C9+D9)*F9) -> 1.2976744 | H9: Office | K9: 300 | L9: 4 | M9: 1450 | N9: 21 | O9: 58 | P9: 0.8 | Q9: =K9*E9*100/(L9*M9*O9*P9) -> 3.7321641 | R9: 4 | S9: =R9*L9*M9*O9*P9/(E9*100) -> 321.52927 | T9: =R9*N9*L9 -> 336
C10: 6.75 | D10: 5.7 | E10: =C10*D10 -> 38.475 | F10: 2 | G10: =E10/((C10+D10)*F10) -> 1.5451807 | H10: Office | K10: 300 | L10: 4 | M10: 1450 | N10: 21 | O10: 59 | P10: 0.8 | Q10: =K10*E10*100/(L10*M10*O10*P10) -> 4.2162843 | R10: 4 | S10: =R10*L10*M10*O10*P10/(E10*100) -> 284.61079 | T10: =R10*N10*L10 -> 336
C11: 6.75 | D11: 4.5 | E11: =C11*D11 -> 30.375 | F11: 2 | G11: =E11/((C11+D11)*F11) -> 1.35 | H11: Office | K11: 300 | L11: 4 | M11: 1450 | N11: 21 | O11: 58 | P11: 0.8 | Q11: =K11*E11*100/(L11*M11*O11*P11) -> 3.386036 | R11: 4 | S11: =R11*L11*M11*O11*P11/(E11*100) -> 354.39671 | T11: =R11*N11*L11 -> 336
C12: 6.75 | D12: 5.7 | E12: =C12*D12 -> 38.475 | F12: 2 | G12: =E12/((C12+D12)*F12) -> 1.5451807 | H12: Office | K12: 300 | L12: 4 | M12: 1450 | N12: 21 | O12: 59 | P12: 0.8 | Q12: =K12*E12*100/(L12*M12*O12*P12) -> 4.2162843 | R12: 4 | S12: =R12*L12*M12*O12*P12/(E12*100) -> 284.61079 | T12: =R12*N12*L12 -> 336
C13: 8.3 | D13: 6.4 | E13: =C13*D13 -> 53.12 | F13: 2 | G13: =E13/((C13+D13)*F13) -> 1.8068027 | H13: Office | K13: 500 | L13: 4 | M13: 1450 | N13: 21 | O13: 61.5 | P13: 0.8 | Q13: =K13*E13*100/(L13*M13*O13*P13) -> 9.3075414 | R13: 9 | S13: =R13*L13*M13*O13*P13/(E13*100) -> 483.47892 | T13: =R13*N13*L13 -> 756
C14: 8 | D14: 3 | E14: =C14*D14 -> 24 | F14: 2 | G14: =E14/((C14+D14)*F14) -> 1.0909091 | H14: Office | K14: 300 | L14: 4 | M14: 1450 | N14: 21 | O14: 57.5 | P14: 0.8 | Q14: =K14*E14*100/(L14*M14*O14*P14) -> 2.6986507 | R14: 3 | S14: =R14*L14*M14*O14*P14/(E14*100) -> 333.5 | T14: =R14*N14*L14 -> 252
C15: 6.75 | D15: 4.5 | E15: =C15*D15 -> 30.375 | F15: 2 | G15: =E15/((C15+D15)*F15) -> 1.35 | H15: Office | K15: 300 | L15: 4 | M15: 1450 | N15: 21 | O15: 58 | P15: 0.8 | Q15: =K15*E15*100/(L15*M15*O15*P15) -> 3.386036 | R15: 4 | S15: =R15*L15*M15*O15*P15/(E15*100) -> 354.39671 | T15: =R15*N15*L15 -> 336
C16: 2.6 | D16: 3 | E16: =C16*D16 -> 7.8 | F16: 2 | G16: =E16/((C16+D16)*F16) -> 0.69642857 | H16: Office | K16: 300 | L16: 4 | M16: 1450 | N16: 21 | O16: 51 | P16: 0.8 | Q16: =K16*E16*100/(L16*M16*O16*P16) -> 0.98884381 | R16: 1 | S16: =R16*L16*M16*O16*P16/(E16*100) -> 303.38462 | T16: =R16*N16*L16 -> 84
C17: 8.3 | D17: 4.4 | E17: =C17*D17 -> 36.52 | F17: 2 | G17: =E17/((C17+D17)*F17) -> 1.4377953 | H17: Office | K17: 300 | L17: 4 | M17: 1450 | N17: 21 | O17: 59 | P17: 0.8 | Q17: =K17*E17*100/(L17*M17*O17*P17) -> 4.0020456 | R17: 4 | S17: =R17*L17*M17*O17*P17/(E17*100) -> 299.84666 | T17: =R17*N17*L17 -> 336
C18: 12 | D18: 3 | E18: =C18*D18 -> 36 | F18: 2 | G18: =E18/((C18+D18)*F18) -> 1.2 | H18: Waiting | K18: 150 | L18: 4 | M18: 1450 | N18: 21 | O18: 57.5 | P18: 0.8 | Q18: =K18*E18*100/(L18*M18*O18*P18) -> 2.023988 | R18: 3 | S18: =R18*L18*M18*O18*P18/(E18*100) -> 222.33333 | T18: =R18*N18*L18 -> 252
C19: K *=A/((L+W)*H) | E19: h=H-hs-wl | H19: v*=.8normal,.7high,.6special | K19: B*From luminaire Table | O19: n*=E*A*100/(Z*Q*B*v) | Q19: e*=N*Z*Q*B*V/(A*100)
J22: LOWER BASE.FLOOR
B23: Room NO. | C23: LIGHTING
C24: L | D24: W | E24: A | F24: h | G24: K * | H24: Type | J24: Selected Laminaire Specs. | K24: Rated Fluxe | L24: Lamp/lami Z | M24: Lumi. FluxQ | N24: Lampe Power | O24: Utaliation Factor B* | P24: Maintenance Factor V* | Q24: NO. of Laminaire n* | R24: Actual NO. N | S24: Actual Fluxe e* | T24: Total power
B25: EN /LOOPY | C25: 18 | D25: 8 | E25: =C25*D25 -> 144 | F25: 3 | G25: =E25/((C25+D25)*F25) -> 1.8461538 | H25: Parking | J25: Surface Mounted Modular Fluorescent Laminaire with brightness louvers (reflection) with Fluorecsent Lamp 2x36w warm wight | K25: 100 | L25: 2 | M25: 3100 | N25: 36 | O25: 54 | P25: 0.8 | Q25: =K25*E25*100/(L25*M25*O25*P25) -> 5.3763441 | R25: 6 | S25: =R25*L25*M25*O25*P25/(E25*100) -> 111.6 | T25: =R25*N25*L25 -> 432
C26: 7.25 | D26: 7.25 | E26: =C26*D26 -> 52.5625 | F26: 3 | G26: =E26/((C26+D26)*F26) -> 1.2083333 | H26: Lifts lobby | J26: Recessed Circular Modular Laminaire with Compact Fluorecsent Lamp 36w warm wight | K26: 150 | L26: 1 | M26: 2800 | N26: 36 | O26: 54 | P26: 0.8 | Q26: =K26*E26*100/(L26*M26*O26*P26) -> 6.5181672 | R26: 7 | S26: =R26*L26*M26*O26*P26/(E26*100) -> 161.08823 | T26: =R26*N26*L26 -> 252
C39: K *=A/((L+W)*H) | E39: h=H-hs-wl | H39: v*=.8normal,.7high,.6special | K39: B*From luminaire Table | O39: n*=E*A*100/(Z*Q*B*v) | Q39: e*=N*Z*Q*B*V/(A*100)

Sheet Table1
B2: ='D.B. detail'!H2 -> 0
B3: Table1
B4: Effective resistance per unit length of plastic -shethed cables NYM and
B5: power cables NYY,NYCY and NYCWY with copper conductors.
B7: Number of | C7: D.C.resistance | D7: Ohmic resistance | E7: Inductive | F7: Effective resistance per unit length | I7: R'LCOSФ+X'LSINФ
B8: conductors and | C8: at 70 °c | D8: at 70 °c | E8: Reactance | F8: at COS Ф
B9: cross section | C9: R'_ | D9: R'L | E9: X'L | F9: 0.95 | G9: 0.9 | H9: 0.8 | I9: 0.7 | J9: 0.6
B10: mm2 | C10: Ω/Km | D10: Ω/Km | E10: Ω/Km | F10: Ω/Km | G10: Ω/Km | H10: Ω/Km | I10: Ω/Km | J10: Ω/Km
B11: 4X1.5 | C11: 14.47 | D11: 14.47 | E11: 0.115 | F11: 13.8 | G11: 13.1 | H11: 11.65 | I11: 10.2 | J11: 8.77
B12: 4X2.5 | C12: 8.71 | D12: 8.71 | E12: 0.11 | F12: 8.31 | G12: 7.89 | H12: 7.03 | I12: 6.18 | J12: 5.31
B13: 4X4 | C13: 5.45 | D13: 5.45 | E13: 0.107 | F13: 5.21 | G13: 4.95 | H13: 4.42 | I13: 3.89 | J13: 3.36
B14: 4X6 | C14: 3.62 | D14: 3.62 | E14: 0.1 | F14: 3.47 | G14: 3.3 | H14: 2.96 | I14: 2.61 | J14: 2.25
B15: 4X10 | C15: 2.16 | D15: 2.16 | E15: 0.094 | F15: 2.08 | G15: 1.99 | H15: 1.78 | I15: 1.85 | J15: 1.37
B16: 4X16 | C16: 1.36 | D16: 1.36 | E16: 0.09 | F16: 1.32 | G16: 1.26 | H16: 1.14 | I16: 1.02 | J16: 0.888
B17: 4X25 | C17: 0.863 | D17: 0.863 | E17: 0.086 | F17: 0.847 | G17: 0.814 | H17: 0.742 | I17: 0.666 | J17: 0.587
B18: 4X35 | C18: 0.627 | D18: 0.627 | E18: 0.083 | F18: 0.622 | G18: 0.6 | H18: 0.55 | I18: 0.498 | J18: 0.443
B19: 4X50 | C19: 0.463 | D19: 0.463 | E19: 0.083 | F19: 0.466 | G19: 0.453 | H19: 0.42 | I19: 0.38 | J19: 0.344
B20: 4X70 | C20: 0.621 | D20: 0.621 | E20: 0.082 | F20: 0.331 | G20: 0.326 | H20: 0.306 | I20: 0.283 | J20: 0.258
B21: 4X95 | C21: 0.231 | D21: 0.232 | E21: 0.082 | F21: 0.246 | G21: 0.254 | H21: 0.235 | I21: 0.221 | J21: 0.205
B22: 4X120 | C22: 0.183 | D22: 0.184 | E22: 0.08 | F22: 0.2 | G22: 0.2 | H22: 0.195 | I22: 0.168 | J22: 0.174
... B26: 4X300 | C26: 0.0718 | D26: 0.0745 | E26: 0.079 | F26: 0.0954 | G26: 0.101 | H26: 0.107 | I26: 0.109 | J26: 0.108

Sheet Table2
B2: ='D.B. detail'!H2 -> 0
B3: Table2
B4: Effective resistance per unit length of plastic -shethed cables NYM and
B5: power cables NYY,NYCY and NYCWY with aluminum conductors.
B7: Number of | C7: D.C.resistance | D7: Ohmic resistance | E7: Inductive | F7: Effective resistance per unit length | I7: R'LCOSФ+X'LSINФ
B8: conductors and | C8: at 20 °c | D8: at 70 °c | E8: Reactance | F8: at COS Ф
B9: cross section | C9: R'_ | D9: R'L | E9: X'L | F9: 0.95 | G9: 0.9 | H9: 0.8 | I9: 0.7 | J9: 0.6
B10: mm2 | C10: Ω/Km | D10: Ω/Km | E10: Ω/Km | F10: Ω/Km | G10: Ω/Km | H10: Ω/Km | I10: Ω/Km | J10: Ω/Km
B15: 4X10 | C15: 3.08 | D15: 3.3 | E15: 0.094 | F15: 3.1643515 | G15: 3.0109737 | H15: 2.6964 | I15: 2.3771294 | J15: 2.0552
B16: 4X16 | C16: 1.91 | D16: 2.29 | E16: 0.086489881 | F16: 2.2025065 | G16: 2.0987001 | H16: 1.8838939 | I16: 1.6647661 | J16: 1.4431919
B17: 4X25 | C17: 1.2 | D17: 1.44 | E17: 0.085329935 | F17: 1.3946443 | G17: 1.3331945 | H17: 1.203198 | I17: 1.0689378 | J17: 0.93226395
B18: 4X35 | C18: 0.868 | D18: 1.043 | E18: 0.078689768 | F18: 1.0154209 | G18: 0.97300007 | H18: 0.88161386 | I18: 0.78629573 | J18: 0.68875181
B19: 4X50 | C19: 0.641 | D19: 0.771 | E19: 0.078588016 | F19: 0.7569891 | G19: 0.72815572 | H19: 0.66395281 | I19: 0.59582307 | J19: 0.52547041
B20: 4X70 | C20: 0.443 | D20: 0.553 | E20: 0.050749784 | F20: 0.54119662 | G20: 0.51982132 | H20: 0.47284987 | I20: 0.4233426 | J20: 0.37239983
B21: 4X95 | C21: 0.32 | D21: 0.385 | E21: 0.076526192 | F21: 0.3896453 | G21: 0.37985699 | H21: 0.35391572 | I21: 0.32415063 | J21: 0.29222095
B22: 4X120 | C22: 0.253 | D22: 0.305 | E22: 0.074458558 | F22: 0.31299968 | G22: 0.30695573 | H22: 0.28867513 | I22: 0.26667405 | J22: 0.24256685
B23: 4X150 | C23: 0.206 | D23: 0.249 | E23: 0.073107439 | F23: 0.25937779 | G23: 0.25596679 | H23: 0.24306446 | I23: 0.22650915 | J23: 0.20788595
B24: 4X185 | C24: 0.164 | D24: 0.199 | E24: 0.073378825 | F24: 0.21196253 | G24: 0.21108509 | H24: 0.20322729 | I24: 0.19170296 | J24: 0.17810306
B25: 4X240 | C25: 0.125 | D25: 0.151 | E25: 0.071870295 | F25: 0.16651599 | G25: 0.16809932 | H25: 0.16512218 | I25: 0.15845394 | J25: 0.14969624
B26: 4X300 | C26: 0.1 | D26: 0.123 | E26: 0.07175136 | F26: 0.13925435 | G26: 0.14197569 | H26: 0.14145082 | I26: 0.13734072 | J26: 0.13120109

Sheet cable cal 1ph
B2: ='D.B. detail'!H2 -> 0
C4: ELECTRICAL CALCULATION
B6: Project name: | D6: WAHAT AL KHARTOUM | H6: Date:
B7: Project no.: | H7: Designer: | I7: Mohammed moustafa
B9: * LOAD INFORMATION
B10: LOAD REFERENCE
B11: VOLTAGE USED | I11: 220 | J11: V
B12: NO.OF PHASES | I12: 1 | J12: PHASES
B13: CONTINUOUS LOAD IN KVA | I13: 2.5 | J13: KVA
B14: CONTINUOUS LOAD IN AMPS | I14: =I13*1000/I11 -> 11.363636 | J14: AMPS
B15: CIRCUIT BREAKER AMPS
B16: ICB = Ia x B/A
B17: Ia | C17: Actual full load current or (RMS)current | I17: =I14 -> 11.363636
B18: A | C18: Ambient temperature factor | G18: at 50 °C | I18: 0.9
B19: B | C19: Safety factor | I19: 1.1
B20: IC.B | I20: =I17*I19/I18 -> 13.888889 | J20: AMPS
B21: CORRECT SIZE CIRCUIT BREAKER AMPS | I21: 20 | J21: AMPS
B22: CABLE SELECTION | E22: ACC to NEC
C23: We planning to use cable with size | I23: 3 | J23: mm2
C24: Cable current rating before the correction factors
C25: according to NEC for one copper cable XLPE inslated&PVCsheahed. | I25: 21 | J25: AMPS
C26: Correction factors:
C27: Ambient Temperature factor | I27: 0.85
C28: Grouping factor | I28: 0.8
C29: Cable current rating after the correction factors | I29: =I25*I27*I28 -> 14.28 | J29: AMPS
C30: NO. of cables | E30: N\ | I30: =I20/I29 -> 0.97261127
B31: Actual | C31: NO. of cables | E31: N | I31: 1
C32: Cable size after correction factors | F32: 2x3 | H32: mm2
C33: Length of cable per kilometer | F33: L | I33: 0.02
B34: VOLTAGE DROP
C35: R'LCOSФ+X'LSINФ from table (1) | H35: = | I35: 7.03
C36: Voltage drop ∆V = | E36: 2*I*L* | F36: (R'LCOSФ+X'LSINФ)/N
D37: = | I37: =2*I14*I33*I35/I31 -> 3.1954545 | J37: V
C38: Voltage drop%= | I38: =I37/I11% -> 1.4524793
B39: CABLE SELECTION | E39: ACC to VDE
C40: Voltage drop= | E40: 2*I*L* | F40: (R'LCOSФ+X'LSINФ)
D41: ∆V Shall not exdeed 3-5% = | I41: =0.03*I11 -> 6.6 | J41: V
D42: (R'LCOSФ+X'LSINФ) = | G42: ∆V /(2*I*L*)
F43: = | I43: =I41/(2*I14*I33) -> 14.52
C44: Ambient Temperature factor | F44: = | I44: 0.85
...

Sheet Cable cal.3ph
B2: ='D.B. detail'!H2 -> 0
C4: ELECTRICAL CALCULATION
B6: Project name: | D6: WAHAT AL KHARTOUM | H6: Date:
B7: Project no.: | H7: Designer: | I7: Mohammed moustafa
B9: * LOAD INFORMATION
B10: LOAD REFERENCE | I10: TRANSFORMER
B11: VOLTAGE USED | I11: 380 | J11: V
B12: NO.OF PHASES | I12: 3 | J12: PHASES | M12: KW | N12: KVA
B13: CONTINUOUS LOAD IN KVA | I13: 630 | J13: KVA | M13: 80 | N13: =M13/0.8 -> 100
B14: CONTINUOUS LOAD IN AMPS | I14: =I13*1000/(1.732051*I11) -> 957.18587 | J14: AMPS
B15: CIRCUIT BREAKER AMPS
B16: ICB = Ia x B/A
B17: Ia | C17: Actual full load current or (RMS)current | I17: =I14 -> 957.18587
B18: A | C18: Ambient temperature factor | G18: at 50 °C | I18: 0.9
B19: B | C19: Safety factor | I19: 1.1
B20: IC.B | I20: =I17*I19/I18 -> 1169.8938 | J20: AMPS
B21: CORRECT SIZE CIRCUIT BREAKER AMPS | I21: 1200 | J21: AMPS
B22: CABLE SELECTION | E22: ACC to NEC
C23: We planning to use cable with size | I23: 240 | J23: mm2
C24: Cable current rating before the correction factors
C25: according to NEC for one copper cable XLPE inslated&PVCsheahed. | I25: 374 | J25: AMPS
C26: Correction factors:
C27: Ambient Temperature factor | I27: 0.85
C28: Grouping factor | I28: 0.9
C29: Cable current rating after the correction factors | I29: =I25*I27*I28 -> 286.11 | J29: AMPS
C30: NO. of cables | E30: N\ | I30: =I20/I29 -> 4.0889652
B31: Actual | C31: NO. of cables | E31: N | I31: 4
C32: Cable size after correction factors | F32: 4(3x240+120+120) | H32: mm2
C33: Length of cable per kilometer | F33: L | I33: 0.05
B34: VOLTAGE DROP
C35: R'LCOSФ+X'LSINФ from table (1) | H35: = | I35: 0.121
C36: Voltage drop ∆V = | E36: √3*I*L* | F36: (R'LCOSФ+X'LSINФ)/N
D37: = | I37: =1.7321*I14*I33*I35/I31 -> 2.5076367 | J37: V
C38: Voltage drop%= | I38: =I37/I11% -> 0.6599044
B40: CABLE SELECTION | E40: ACC to VDE
C41: Voltage drop= | E41: √3*I*L* | F41: (R'LCOSФ+X'LSINФ)
D42: ∆V Shall not exdeed 3-5% = | I42: =0.03*I11 -> 11.4 | J42: V
D43: (R'LCOSФ+X'LSINФ) = | G43: ∆V /(√3*I*L*)
F44: = | I44: =I42/(1.7321*I14*I33) -> 0.13751992
C45: Ambient Temperature factor | F45: = | I45: 0.85
...
