Workbook

Sheet Earthing
G1: SUBSTATION EARTHING DESIGN | L1: https://www.flasysdesign.com/
L2: Email: contact@flasysdesign.com
A4: Input data :- | AA4: Description | AB4: Material conductivity (%) | AC4: αr factor at 20°C (1/°C) | AD4: Ko at 20°C | AE4: temperature Tm (°C) | AF4: ρr 20°C (μΩcm) | AG4: TCAP thermal capacity [J/(cm3. °C)]
AA5: Copper annealed soft drawn | AB5: 100 | AC5: 0.00393 | AD5: 234 | AE5: 1083 | AF5: 1.72 | AG5: 3.42
A6: 1 | B6: Conductor material | F6: = | G6: Steel, 1020 | I6: 18 | J6: Length of one earth mat conductor Lx | M6: = | N6: 100 | O6: metre | AA6: Copper commercial hard drawn | AB6: 97 | AC6: 0.00381 | AD6: 242 | AE6: 1084 | AF6: 1.78 | AG6: 3.42
AA7: Copper-clad steel wire | AB7: 40 | AC7: 0.00378 | AD7: 245 | AE7: 1084 | AF7: 4.4 | AG7: 3.85
A8: 2 | B8: System Voltage | F8: = | G8: 132 | H8: kV | I8: 19 | J8: Width of one earth mat conductor Ly | M8: = | N8: 50 | O8: metre | AA8: Copper-clad steel wire | AB8: 30 | AC8: 0.00378 | AD8: 245 | AE8: 1084 | AF8: 5.86 | AG8: 3.85
AA9: Copper-clad steel rodb | AB9: 20 | AC9: 0.00378 | AD9: 245 | AE9: 1084 | AF9: 8.62 | AG9: 3.85
A10: 3 | B10: Fault Current, If | F10: = | G10: 31.5 | H10: kA | I10: 20 | J10: Additional length of conductor considered | N10: 12 | O10: metre | AA10: Aluminum EC Grade | AB10: 61 | AC10: 0.00403 | AD10: 228 | AE10: 657 | AF10: 2.86 | AG10: 2.56
AA11: Aluminum 5005 alloy | AB11: 53.5 | AC11: 0.00353 | AD11: 263 | AE11: 652 | AF11: 3.22 | AG11: 2.6
A12: 4 | B12: Fault Duration, tc | F12: = | G12: 1 | H12: sec | I12: 21 | J12: Grid conductor combined length, Lc | M12: = | N12: =(G40*G30+G32*N40)+N10 -> 3162 | O12: metre | AA12: Aluminum 6201 alloy | AB12: 52.5 | AC12: 0.00347 | AD12: 268 | AE12: 654 | AF12: 3.28 | AG12: 2.6
AA13: Aluminum-clad steel wire | AB13: 20.3 | AC13: 0.0036 | AD13: 258 | AE13: 657 | AF13: 8.48 | AG13: 3.58
A14: 5 | B14: Max. Allowable Temperature, Tm | F14: = | G14: =IF(G6=AA5,AE5,IF(G6=AA6,AE6,IF(G6=AA7,AE7,IF(G6=AA8,AE8,IF(G6=AA9,AE9,IF(G6=AA10,AE10,IF(G6=AA11,AE11,IF(G6=AA12,AE12,IF(G6=AA13,AE13,IF(G6=AA14,AE14,IF(G6=AA15,AE15,IF(G6=AA16,AE16,IF(G6=AA17,AE17,))))))))))))) -> 1510 | H14: 0C | I14: 22 | J14: Total no. of ground rods (Untreated) | AA14: Steel, 1020 | AB14: 10.8 | AC14: 0.0016 | AD14: 605 | AE14: 1510 | AF14: 15.9 | AG14: 3.28
J15: SA | N15: 0 | AA15: stainless-clad steel rodc | AB15: 9.8 | AC15: 0.0016 | AD15: 605 | AE15: 1400 | AF15: 17.5 | AG15: 4.44
A16: 6 | B16: Ambient Temperature, Ta | F16: = | G16: 50 | H16: 0C | J16: Transformers (Body earthing) | N16: 1 | AA16: Zinc-coated steel rod | AB16: 8.6 | AC16: 0.0032 | AD16: 293 | AE16: 419 | AF16: 20.1 | AG16: 3.93
J17: Towers with peak | N17: 1 | AA17: Stainless steel | AB17: 2.4 | AC17: 0.0013 | AD17: 749 | AE17: 1400 | AF17: 72 | AG17: 4.03
A18: 7 | B18: Reference temp for material constant,Tr | F18: = | G18: 20 | H18: 0C | J18: Switchyard corners | N18: 1 | AA18: weight
J19: Additional ground rods | N19: 1 | AA19: 50
A20: 8 | B20: Thermal Co-eff.of resistivity at reference | J20: Total no of rods | N20: =SUM(N15:N19) -> 4 | AA20: 70
B21: Temperature, ar | F21: = | G21: =IF(G6=AA5,AC5,IF(G6=AA6,AC6,IF(G6=AA7,AC7,IF(G6=AA8,AC8,IF(G6=AA9,AC9,IF(G6=AA10,AC10,IF(G6=AA11,AC11,IF(G6=AA12,AC12,IF(G6=AA13,AC13,IF(G6=AA14,AC14,IF(G6=AA15,AC15,IF(G6=AA16,AC16,IF(G6=AA17,AC17,))))))))))))) -> 0.0016 | I21: 23 | J21: length of each rod in m Lr | M21: = | N21: 3 | O21: meter
J22: Total ground rod length, LR | M22: = | N22: =SUM(N15:N19)*N21 -> 12 | O22: metre
A23: 9 | B23: Resistivity of Ground Conductor at ref.
B24: Temperature, rr | F24: = | G24: =IF(G6=AA5,AF5,IF(G6=AA6,AF6,IF(G6=AA7,AF7,IF(G6=AA8,AF8,IF(G6=AA9,AF9,IF(G6=AA10,AF10,IF(G6=AA11,AF11,IF(G6=AA12,AF12,IF(G6=AA13,AF13,IF(G6=AA14,AF14,IF(G6=AA15,AF15,IF(G6=AA16,AF16,IF(G6=AA17,AF17,))))))))))))) -> 15.9 | H24: mW/cm3 | I24: 24 | J24: Effective length of buried conductor | M24: = | N24: =N12+N22 -> 3174 | O24: metre
J25: LT = LR + Lc
A26: 10 | B26: Thermal Capacity Factor, TCAP | F26: = | G26: =IF(G6=AA5,AG5,IF(G6=AA6,AG6,IF(G6=AA7,AG7,IF(G6=AA8,AG8,IF(G6=AA9,AG9,IF(G6=AA10,AG10,IF(G6=AA11,AG11,IF(G6=AA12,AG12,IF(G6=AA13,AG13,IF(G6=AA14,AG14,IF(G6=AA15,AG15,IF(G6=AA16,AG16,IF(G6=AA17,AG17,))))))))))))) -> 3.28 | H26: J/cm3/oC | I26: 25 | J26: Soil Resistivityconsidered for design, r | M26: = | N26: 49.12 | O26: W-meter
A28: 11 | B28: K0 = (1/ar) -Tr | F28: = | G28: =IF(G6=AA5,AD5,IF(G6=AA6,AD6,IF(G6=AA7,AD7,IF(G6=AA8,AD8,IF(G6=AA9,AD9,IF(G6=AA10,AD10,IF(G6=AA11,AD11,IF(G6=AA12,AD12,IF(G6=AA13,AD13,IF(G6=AA14,AD14,IF(G6=AA15,AD15,IF(G6=AA16,AD16,IF(G6=AA17,AD17,))))))))))))) -> 605 | I28: 26 | J28: Surface Resistivity, rs | M28: = | N28: 3000 | O28: W-meter
A30: 12 | B30: Length of Earth grid | F30: = | G30: 100 | H30: metre | I30: 27 | J30: Spacing for Earthing Mat ,D | M30: = | N30: 4 | O30: meter
A32: 13 | B32: Width of Earth grid | F32: = | G32: 50 | H32: metre | I32: 28 | J32: Corrective weighting factor, Kii | M32: = | N32: 1
A34: 14 | B34: Area of Earth grid, A | F34: = | G34: =G30*G32 -> 5000 | H34: sq.metre | I34: 29 | J34: Reference Depth of grid, h0 | M34: = | N34: =G36 -> 1 | O34: meter
A36: 15 | B36: Depth of burial w.r.t. ground level, h | F36: = | G36: 1 | H36: metre | I36: 29 | J36: Thickness of Concrete , hs | M36: = | N36: 0.15 | O36: meter
A38: 16 | B38: Calculate w.r.t to person weight(50/70) | F38: = | G38: 50 | H38: Kg | I38: 30 | J38: Fault Current division factor (Sf) | M38: = | N38: 0.5
A40: 17 | B40: No. of conductors parallel to length side( nl) | F40: = | G40: =ROUND(G30/N30,0) -> 25 | I40: 31 | J40: No. of conductors parallel to width side ( ns) | M40: = | N40: =ROUND(G32/N30,0) -> 13
A42: Output:
B43: Conductor size, A | F43: = | G43: =G10*SQRT(((G12*G21*G24*10000)/G26)/((LN(1+(G28+G14)/(G28+G16))))) -> 231.0226 | H43: SQMM | J43: Effective Buried Length for mesh voltage, LM | M43: = | N43: =Calculations!D140 -> 3180.9928 | O43: Meter
B45: By considering 30% allowance | F45: = | G45: =G43*1.3 -> 300.32938 | H45: SQMM | J45: Effective Buried Length for step voltage, LS | M45: = | N45: =Calculations!D211 -> 2381.7 | O45: Meter
D46: A | F46: = | G46: 300 | H46: SQMM
J47: Grid Resistance | M47: = | N47: =Calculations!D101 -> 0.25770792 | O47: Ohms
B48: Ground Potential Rise(GPR) | F48: = | G48: =Calculations!F112 -> 4058.8997 | H48: Volts
B50: Tolerable | J50: Tolerable
B51: Touch Voltage Etouch | F51: = | G51: =IF(G38=Calculations!B20,Calculations!E32,IF(G38=Calculations!B21,Calculations!E33,"Error")) -> 734.69925 | H51: Volts | J51: Step Voltage Estep | M51: = | N51: =IF(G38=Calculations!B36,Calculations!E41,IF(G38=Calculations!B37,Calculations!E42,"Error")) -> 2446.6507 | O51: Volts
...

Sheet Calculations
M2: https://www.flasysdesign.com/
A3: Conductor Size :- | M3: Email: contact@flasysdesign.com
B5: As per Eq.37 of IEEE Std 80-2000, conductor size is given by
D7: tc ar rr x 104
D8: TCAP
A9: A | B9: = | C9: If | E9: Ko + Tm
D10: ln 1 +
E11: Ko + Ta
A16: 2.2) | B16: Calculation of Tolerable Etouch & Estep Voltage :
A18: a) | B18: Tolerable Etouch :
B19: From IEEE Std 80-2000
A20: For | B20: 50 | C20: Tolerable Etouch50= | E20: [(1000 + 1.5CS rS) 0.116/ ÖtS ] | H20: ( From eq.32of IEEE Std 80-2000 )
A21: For | B21: 70 | C21: Tolerable Etouch70= | E21: [(1000 + 1.5CS rS) 0.157/ ÖtS ]
B22: Where,
C23: Cs = Reduction factor for derating the nominal value of surface layer
C24: resistivity.
C26: Cs = 1 - 0.09 [(1-r/rs)/(2hs + 0.09)] | G26: ( From eq.27 of IEEE Std 80-2000 )
C28: Cs | D28: = | E28: =1-(0.09*((1-(Earthing!N26/Earthing!N28))/((2*Earthing!N36)+0.09))) -> 0.77300923
C29: tS = Duration of shock current in seconds = | G29: 0.5
D30: ( from clause 16.2.2 of IEEE Std 80-2000 )
B31: Substituting the above values,
B32: Tolerable Etouch50 | D32: = | E32: =((1000+(1.5*E28*Earthing!N28))*0.116)/SQRT(Earthing!N38) -> 734.69925 | F32: Volts
B33: Tolerable Etouch70 | D33: = | E33: =((1000+(1.5*E28*Earthing!N28))*0.157)/SQRT(Earthing!N38) -> 994.37743 | F33: Volts
A35: b) | B35: Tolerable Estep | H35: (from eq.29 of IEEE Std 80-2000)
A36: For | B36: 50 | C36: Tolerable Estep50 = | E36: [(1000 + 6CS rS) 0.116/ ÖtS ]
A37: For | B37: 70 | C37: Tolerable Estep70 = | E37: [(1000 + 6CS rS) 0.157/ ÖtS ]
B39: Substituting the values,
B41: Tolerable Estep50 | D41: = | E41: =((1000+(6*E28*Earthing!N28))*0.116)/SQRT(Earthing!N38) -> 2446.6507 | F41: Volts
B42: Tolerable Estep70 | D42: = | E42: =((1000+(6*E28*Earthing!N28))*0.157)/SQRT(Earthing!N38) -> 3311.4151 | F42: Volts
A45: 2.3) | B45: Calculation of Grid Resistance, Rg :
B47: As per IEEE Std 80-2000,
F48: R1 R2 - Rm2
B49: The total system resistance, Rg | E49: =
F50: R1 + R2 - 2Rm
B51: Where,
B52: R1 | C52: = | D52: Ground resistance of grid conductors in Ω
B53: R2 | C53: = | D53: Ground resistance of of all ground rods in Ω
B54: Rm | C54: = | D54: Mutual ground resistance between the group of grid conductors, R1 and
D55: group of ground rods, R2 in Ω
B57: Ground resistance of the grid, R1
...
