Workbook
Name A1_: #REF!
Name A1_: #REF!
Name A10_: #REF!
Name A10_: #REF!
Name A13_: #REF!
Name A13_: #REF!
Name A13_: #REF!
Name A2_: #REF!
Name A2_: #REF!
Name A3_: #REF!
Name A3_: #REF!
Name A4_: #REF!
Name A4_: #REF!
Name A5_: #REF!
Name A5_: #REF!
Name A6_: #REF!
Name A6_: #REF!
Name A7_: #REF!
Name A7_: #REF!
Name A8_: #REF!
Name A8_: #REF!
Name A9_: #REF!
Name A9_: #REF!
Name AddPage: [1]!AddPage
Name AddPage: [1]!AddPage
Name AddPage: [1]!AddPage
Name AddSheet: [1]!AddSheet
Name AddSheet: [1]!AddSheet
Name AddSheet: [1]!AddSheet
Name ca: #REF!
Name ca: #REF!
Name di: #REF!
Name di: #REF!
Name Eh: #REF!
Name Eh: #REF!
Name Es: #REF!
Name Es: #REF!
Name HS: #REF!
Name HS: #REF!
Name hsh: #REF!
Name hsh: #REF!
Name II: [1]!AddSheet
Name II: [1]!AddSheet
Name II: [1]!AddSheet
Name myrange: 'Annex-1'!$62:$1080
Name myrange: Index!$3:$1062
Name myrange: 'Sheet 10'!$3:$950
Name myrange: 'Sheet 11'!$3:$950
Name myrange: 'Sheet 12'!$3:$941
Name myrange: 'Sheet 13'!$4:$955
Name myrange: 'Sheet 2'!$3:$1076
Name myrange: 'Sheet 3'!$3:$1076
Name myrange: 'Sheet 4'!$3:$1078
Name myrange: 'Sheet 5'!$3:$1078
Name myrange: 'Sheet 6'!$3:$1084
Name myrange: 'Sheet 7'!$3:$1210
Name myrange: 'Sheet 8'!$3:$1214
Name myrange: 'Sheet 9'!$3:$1236
Name myrange: 'Sheet 1'!$3:$1077
Name PD: #REF!

Sheet Front Sheet-Potrait
I1: https://www.flasysdesign.com/
I2: Email: contact@flasysdesign.com
B11: Earthing & Lightning Protection Calculation
D19: Contractor:
D20: Client:
D21: Location:
D22: Job No.:
D23: APG Project No:
B37: Rev | C37: Date | D37: Status | E37: Document Status | H37: Prepared by | J37: Checked By | K37: Approved By

Sheet Hold Sheet-Potrait
A2: Earthing & Lightning Protection Calculation
A5: Record of Revisions
A8: Rev. | B8: Date | C8: Revision Details
A22: Table of Holds
A25: The following holds have been identified. They will be cleared as soon as practicable.
A27: Section | C27: Details of Hold | J27: Hold Cleared (rev)
J37: Page 2 of 9

Sheet Index
AK1: https://www.flasysdesign.com/
A2: Earthing & Lightning Protection Calculation | AK2: Email: contact@flasysdesign.com
N5: TABLE OF CONTENTS
D8: Section-1 : Earthing Study
C9: 1 | D9: Scope | AC9: 4
C10: 2 | D10: Reference documents | AC10: 4
C11: 3 | D11: Design inputs | AC11: 4
C12: 4 | D12: Formulae | AC12: 4
C13: 5 | D13: Calculations | AC13: 6
D14: A | E14: Main earth grid GI strip sizing | AC14: 6
D15: B | E15: Plant earth grid GI strip sizing | AC15: 6
D16: C | E16: Calculation of number of earth electrodes | AC16: 7
D17: D | E17: System resistance | AC17: 8
D18: E | E18: Grid resistance | AC18: 8
C19: 6 | D19: Conclusion | AC19: 8
C20: 7 | D20: Recommendations | AC20: 8
D22: Section-2 : Lightning Study
C23: 1 | D23: Scope | AC23: 1
C24: 2 | D24: Reference documents | AC24: 1
C25: 3 | D25: Design inputs | AC25: 1
C26: 4 | D26: Formulae | AC26: 1
C27: 5 | D27: Calculation for Requirement of LPS | AC27: 2
D28: A | E28: Substation Building | AC28: 2
D29: B | E29: Plant Interface Building (PIB) | AC29: 3
D30: C | E30: Maintenance Building | AC30: 4
D31: D | E31: Catalyst Storage Building | AC31: 5
D32: E | E32: LPS For Metallic Structures/Buildings | AC32: 6
C33: 6 | D33: Summary | AC33: 7
D35: Annexure-1 -- Fault current calculation | AC35: -
AB44: Page | AD44: 3 | AF44: of | AH44: 9

Sheet Sheet 1
AM1: https://www.flasysdesign.com/
A2: Earthing & Lightning Protection Calculation | AM2: Email: contact@flasysdesign.com
O4: Section-1 : Earthing Study
B6: 1 | C6: Scope:
C7: This section of document covers the calculation to determine the size of main earth strip & number of total earth electrodes required for
C8: the earthing system .
B10: 2 | C10: Reference Documents:
C11: This calculation is based on following documents :
B18: 3 | C18: Design Inputs:
C19: 1> Soil Resistivity is taken as 45 ohm-m as per Clause no 11 (Page 25 of 42) of Ref Documents as mentioned under 5> above.
C20: 2> Depth of pipe electrode in contact with earth is considered as pipe length = 3 m
C21: 3> For earth grid design, duration of fault current considered is 0.5 sec as per Electrical Design Basis.
C22: 4> | D22: 11kV System : Resistance earthed by 250A NER.
D23: 6.6kV System : Resistance earthed by 250A NER.
D24: 0.415kV & 0.690kV System : Solidly earthed.
C25: 5> Material of earth electrode is considered as 100NB Class 'B' GI pipe Electrode ‐ 3m long as per Standard Specifiaction for Cable Trays &
D26: earthing Material.
B28: 4 | C28: Formulae:
C29: 4.1. Resistance of pipe electrode (ref. 9.2.2. of IS: 3043 - Amend No. 2)
D30: Re | E30: = | F30: [100р/2Лl] x [loge (2l/d)] ohm
D32: where, | F32: l = length of pipe in cm.
F33: d = diameter of pipe in cm
F34: р = resistivity of soil in ohm-m
C36: 4.2. Permissible current density for given value of soil resistivity & for given duration (ref. 10.3 of IS: 3043)
E37: J = | G37: 7.57 x 103
H38: Ört
E39: where t = duration of fault (sec)
C41: 4.3. The cross-sectional area of earthing conductor for disconnection time not exceeding 5 sec (ref. 12.2.2.1 of IS: 3043)
E43: 1/S = | F43: K | G43: * | H43: 1 / I Öt
E45: where,
E46: S = cross sectional area in sq.mm.
E47: I = r.m.s. value of fault current of system in amperes
E48: K = factor from IS: 3043 table 6.
D50: Table 6A | T50: Table 6D
D51: Bare Conductor with No Risk of Fire or Danger | T51: Protective Bare Conductors in Hazardous Areas Where There is Risk
D52: to Any Other Touching or Surrounding Material | T52: of Fire from Petroleum Bound Oil or Other Surrounding Material
D54: Copper | H54: 205 | T54: Copper | X54: 153
D55: Aluminium | H55: 126 | T55: Aluminium | X55: 101
D56: Steel | H56: 80 | T56: Steel | X56: 56
AB61: Page | AD61: 4 | AF61: of | AH61: 9

Sheet Sheet 2
AM1: https://www.flasysdesign.com/
A2: Earthing & Lightning Protection Calculation | AM2: Email: contact@flasysdesign.com
B4: 4.4 | D4: Inputs:
B6: 1 | C6: : Maximum Fault Current (for Main Earth grid sizing) | S6: (LV Switchboard / PCC design fault current) | AE6: 65 | AI6: kA
C7: : Maximum Fault Current (for Plant Earth grid sizing) | S7: (Refer - Annexure-1) * | AE7: ='Annex-1'!O30 -> 15.445092 | AI7: kA
B8: 2 | C8: : Duration of Fault (Fault Clearing Time) | AE8: 0.5 | AI8: Sec.
B9: 3 | C9: : Average soil resistivity | AE9: 45 | AI9: Ohm-m
B10: 4 | C10: : Pipe electrode length (l) | AE10: 300 | AI10: cm
B11: 5 | C11: : Pipe electrode length in contact with ground (l) | AE11: =AE10 -> 300 | AI11: cm
B12: 6 | C12: : Pipe electrode diameter (D) | AE12: 10 | AI12: cm
B13: 7 | C13: : Corrosion allowance for GI strip | S13: (As per Design Basis CL No. 8.10) | AE13: 30 | AI13: %
C14: * 11kV & 6.6kV Systems are resistively earthed with NGR rating 250A. Therefore plant earthing is designed considering Maximum earth
C15: fault current on 415V & 690V system 15.45kA as calculated in Annexure-1.
B17: 4.5 | D17: Symbols
B19: I | C19: : Fault Current in kA | AE19: =AE6 -> 65
B21: t | C21: : Fault duration in seconds | AE21: =AE8 -> 0.5
B23: K | C23: : Constant (for GI Earth strip in safe area) | P23: (ref. Table 6A of IS 3043:1987) | AE23: ='Sheet 1'!H56 -> 80
C25: (for GI Earth strip in Hazardous area) | P25: (ref. Table 6D of IS 3043:1987) | AE25: ='Sheet 1'!X56 -> 56
B27: w | C27: : Depth of burial of the strip in cm | P27: (ref. Cl 20.6.3.2 of IS 3043:1987) | AE27: 60
B29: t | C29: : Width of strip in cm | AE29: 7.5
B32: 4.6 | D32: Estimated Strip Laid Area (Substation): | U32: Estimated Strip Laid Area (Plant):
C34: Strip laid 600mm below ground over (Approx) | P34: 250 | Q34: mtr | U34: Strip laid 600mm below ground over (Approx) | AH34: 2260 | AI34: mtr
AH37: N
F38: 32 | AR38: 530
F39: Substation | K39: 80 | AR39: =195*2 -> 390
AA40: 150 | AE40: 130 | AR40: 195
V41: 269 | X41: 269 | AR41: 385
AA42: 150 | AR42: 120
AB43: 195 | AR43: 120
AR44: 175
W45: - Plot | AR45: 170
W46: 296 | AG46: NTS | AR46: 175
K49: NTS
C56: Earth Grid around the Substation | V56: Earth Grid around the Plot & below Piperacks
C57: (Approx length for calculation purpose only) | V57: (Approx length for calculation purpose only)
AB59: Page | AD59: 5 | AF59: of | AH59: 9

Sheet Sheet 3
AF1: https://www.flasysdesign.com/
A2: Earthing & Lightning Protection Calculation | AF2: Email: contact@flasysdesign.com
B4: 5 | C4: Calculation:
B6: A | C6: Main Earth Grid GI Strip Sizing (Around Substation)
C8: Cross sectional area of Main earth strip (GI) required to carry the rated fault current for 0.5 sec
C9: Design fault level for LV Switchboard / PCC is 65 kA for 1sec.
C10: Hence Main earth strip shall be designed for this fault current
D11: 1/S = | E11: K | F11: * | G11: 1 / I Öt
C13: K= | D13: ='Sheet 2'!AE23 -> 80 | H13: (for Non hazardous area near Substation)
C15: S = | D15: I/K | E15: * | F15: Öt | H15: = | I15: 65 * 1000 * | M15: Ö 0.5
J16: 80
C17: = | D17: ='Sheet 2'!AE19*1000*SQRT('Sheet 2'!AE8)/D13 -> 574.52426
C18: Required Cross sect. area of GI strip = | O18: =ROUNDUP(D17,0) -> 575 | S18: sq.mm
C20: Considering 30% Corrosion allowance : | O20: =O18*(100+'Sheet 2'!AE13)/100 -> 747.5 | S20: sq.mm
C22: Since Cross sect area of 75 x 10mm GI Stip = | O22: 750 | S22: sq.mm
O24: 75 x 10 | S24: mm GI strip to be selected
C26: Therefore, Earth grid around Substation shall be by 75 x 10mm GI earth Strip
B28: B | C28: Plant Earth Grid GI Strip Sizing
D29: The max. earth fault current to be dessipated by plant earth grid is same as that of the earth fault current of the largest kW motor
D30: (LV) located near the source. Refer Annexure-1 for earth fault current calculation of SEED BED BLOWER MOTOR
D31: (Tag no. MA-CHC501-M5613, 5614) of rating 225 kW on 415V system & PELLET WATER PUMP MOTOR (Tag no. MP-CHC501-M7012 /
D32: 7017) of rating 250kW on 690V system.
D34: Max Cross sectional area of Plant earth strip (GI) required to carry the fault current of 15.45 kA for 0.5 sec is calculated as follows,
E35: 1/S = | F35: K | G35: * | H35: 1/ I Öt
D37: K= | E37: ='Sheet 1'!X56 -> 56 | I37: (for hazardous area)
D39: S = | E39: I/K | F39: * | G39: Öt | L39: = | M39: 15.45 * 1000 | Q39: * Ö 0.5
M40: 56
D41: = | E41: =('Sheet 2'!AE7*1000*SQRT('Sheet 2'!AE21))/E37 -> 195.02374
D43: Required Cross sect. area of GI strip = | R43: =ROUNDUP(E41,0) -> 196 | U43: sq.mm
D45: Considering 30% Corrosion allowance: | R45: =R43*(100+'Sheet 2'!AE13)/100 -> 254.8 | U45: sq.mm
D47: Since Cross sect area of 50 x 6mm GI Stip = | R47: 300 | V47: sq.mm
R49: 50 x 6 | U49: mm GI earth strip may be selected.
C51: However for Standardization purpose, Earth grid for Plant shall be by selected as 75 x 10mm GI earth Strip
AB59: Page | AD59: 6 | AF59: of | AH59: 9

Sheet Sheet 4
AL1: https://www.flasysdesign.com/
A2: Earthing & Lightning Protection Calculation | AL2: Email: contact@flasysdesign.com
A4: C | B4: Calculation for Number of Earth Electrodes:
C5: 1. Resistance to pipe electrode
D7: r | E7: = | F7: ='Sheet 2'!AE9 -> 45 | J7: ohm-m
D8: l | E8: = | F8: ='Sheet 2'!AE11 -> 300 | J8: cm (length in contact with ground)
D9: d | E9: = | F9: ='Sheet 2'!AE12 -> 10 | J9: cm
D11: Re | E11: = | F11: [100р/2Лl] x [loge (2l/d)] ohm
E13: = | F13: =((100*F7)/(2*PI()*F8))*(LN((2*F8)/F9)) -> 9.7745276 | J13: ohm
C15: In order to achieve an overall earth resistance below 1 ohm, | T15: =ROUNDUP(F13,0) -> 10 | W15: nos min. pipe electrodes are required.
C17: 2. Permissible current density for given value of soil resistivity & for given duration of | AA17: ='Sheet 2'!AE8 -> 0.5 | AD17: sec.
D19: J | E19: = | F19: 7.57 x 103 | J19: A/sq.m
G20: Ört
D21: r | E21: = | F21: ='Sheet 2'!AE9 -> 45 | J21: ohm-mtr
D22: t | E22: = | F22: =AA17 -> 0.5 | J22: sec
D24: J | E24: = | F24: =(7.57*1000)/(SQRT(F21*F22)) -> 1595.8961 | I24: A/sq.m
C26: 3. Total area of each pipe electrode in contact with ground
F27: A | G27: = | H27: pDl
G28: = | H28: =PI()*'Sheet 2'!AE12*'Sheet 2'!AE11/(100*100) -> 0.9424778 | K28: sq. m
C30: Considering 5% reduction in the gross area of pipe electrodes due to perforations & also tapering of pipe electrodes at bottom.
C31: Hence net area of each pipe electrode | N31: =H28*0.95 -> 0.89535391 | Q31: sq.m.
C33: 4. Total surface area of pipe electrode required for fault current dissipation =
F34: Fault current component in amperes for dissipation through earthing elements
K35: current density in A/sq.m
S36: Substation | AE36: Plant
C37: Total Fault kA | O37: = | P37: ='Sheet 2'!AE6 -> 65 | S37: kA | AB37: ='Sheet 2'!AE7 -> 15.445092 | AE37: kA
C38: Current Density | O38: = | P38: =F24 -> 1595.8961 | S38: A/sq.m | AB38: =F24 -> 1595.8961 | AE38: A/sq.m
C39: Total surface area of earth elements required | O39: = | P39: =P37*1000/P38 -> 40.729468 | S39: sq.m | AB39: =AB37*1000/AB38 -> 9.6780058 | AE39: sq.m
C41: 5. Minimum Total number of pipe electrode required to be interconnected for Plot spread
C43: Total Earth Electrode Area | N43: = | O43: =MAX(P39,AB39) -> 40.729468 | S43: sqm | U43: (Max of the surface area calculated above in 4.)
C45: Considering corrossion allowance : | N45: = | O45: =O43*((100+'Sheet 2'!AE13)/100) -> 52.948308 | S45: sqm
C47: Area of each earth electrode | N47: = | O47: =N31 -> 0.89535391 | S47: sqm
C49: Total no. of earth electrodes | N49: = | O49: =O45/O47 -> 59.136737 | S49: Nos.
C51: In order to achieve an overall earth resistance below 1 ohm & dessipation of 65kA of earth fault current, min | AF51: =ROUNDUP(O49,0) -> 60 | AI51: Nos.
C52: electrodes will be required.
C54: 6. Earth Strip Areas =
C55: Substation | U55: Plant
C56: Area of Strip in contact with ground | M56: 250 * {(75 * 2) + (10 *2)} | U56: Area of Strip in contact with ground | AE56: 2260 * {(75 * 2) + (10 *2)}
C57: (Refer Section B) | O57: 1000 | U57: (Refer Section C) | AG57: 1000
C58: Strip run around Substation | N58: ='Sheet 2'!P34*((75*2)+(10*2))/1000 -> 42.5 | Q58: sq.m | U58: Strip run over Plant | AF58: ='Sheet 2'!AH34*((75*2)+(10*2))/1000 -> 384.2 | AI58: sq.m
...

Sheet Sheet 5
AP1: https://www.flasysdesign.com/
A2: Earthing & Lightning Protection Calculation | AP2: Email: contact@flasysdesign.com
A4: D. | B4: System Resistance:
C6: Resistance of one electrode: | O6: ='Sheet 4'!F13 -> 9.7745276 | S6: ohm
C8: No. of electrodes forming Grid: | O8: ='Sheet 4'!AF51 -> 60
C10: Effective Resistance achieved: | M10: Re = | O10: =O6/O8 -> 0.16290879 | S10: ohm
A12: E. | B12: Grid Resistance
B14: Substation | U14: Plant
B15: Resistance of strip electrode (ref. 9.2.3 of IS: 3043_Amend 2) | U15: Resistance of strip electrode (ref. 9.2.3 of IS: 3043_Amend 2)
B16: Rs | C16: = | D16: [100p/2pi*l] x [loge(4l/t)] | U16: Rs | V16: = | W16: [100p/2pi*l] x [loge(4l/t)]
B18: where, | U18: where,
B19: r | C19: = | D19: ='Sheet 2'!AE9 -> 45 | H19: resistivity of soil in ohm-metre | U19: r | V19: = | W19: =D19 -> 45 | AA19: resistivity of soil in ohm-metre
B20: l | C20: = | D20: ='Sheet 2'!P34*100 -> 25000 | H20: length of strip in cm | U20: l | V20: = | W20: ='Sheet 2'!AH34*100 -> 226000 | AA20: length of strip in cm
B21: w | C21: = | D21: ='Sheet 2'!AE27 -> 60 | H21: depth of burial of the electrode in cm | U21: w | V21: = | W21: =D21 -> 60 | AA21: depth of burial of the electrode in cm
B22: t | C22: = | D22: ='Sheet 2'!AE29 -> 7.5 | H22: width of strip in cm | U22: t | V22: = | W22: =D22 -> 7.5 | AA22: width of strip in cm
B24: Rs | D24: =((100*D19)/(2*PI()*D20))*(LN((4*D20)/(D22))) -> 0.2720983 | H24: ohm | U24: Rs | W24: =((100*W19)/(2*PI()*W20))*(LN((4*W20)/(W22))) -> 0.037076459 | AA24: ohm
B26: Hence, Effective resistance of Substation & Plant Earth Strip, | T26: = | U26: Substation Strip Rs x Plant Strip Rs
U27: Substation Strip Rs + Plant Strip Rs
T29: = | U29: =D24*W24/(D24+W24) -> 0.032630223 | Y29: Ohm
B31: Effective Plant Earth Resistance | M31: = | N31: Electrodes Re x Strip Rs
N32: Electrodes Re x Strip Rs
M34: = | O34: =O10*U29/(O10+U29) -> 0.027185113 | S34: Ohm
B36: 6 | C36: Conclusion:
C37: The effective resistance of the grounding system is 0.03 ohm, which is within the maximum permissible value of 1 ohm.
B39: 7 | C39: Recommendations:
B41: 1. Provide min. | G41: 60 | J41: nos. | L41: 3 | O41: m. Long, | R41: ='Sheet 2'!AE12*10 -> 100 | U41: NB Class 'B' GI, pipe electrodes Distributed around substation & Plant
B42: 2. Each Transformer shall have 2 Nos. dedicated earth pits for Neutral grounding.
B43: 3. Provide GI Earth strip for main earth grid | O43: 75 x 10 | R43: mm bare strip | X43: … installed at 600mm depth around Substation
B44: 4. Provide GI Earth strip for plant earth grid | O44: 75 x 10 | R44: mm bare strip | X44: … installed at 600mm depth in plant area
B45: 5. Plant earth grid shall be connected to substation earth grid at Minimum two locations.
B46: 6. Further, this plant earth grid shall be connected to earth grids of the adjacent areas surrounding to plant at Minimum two locations.
B47: 7. Size of Earth conductors for various equipments shall be as given in the table below (referred from electrical standard installation dwg):
E49: Type of Equipment | Y49: Bare GI Strip / AL or Cu cable
C52: 1. Motors above 2.2kW up to and including 30 kW | Q52: (Refer E12-048) | Y52: 1C x 35 sqmm AL, PVC Cable | AH52: 2 Nos.
C53: 2. Motors from 37 kW and above including MV motors | Q53: (Refer E12-048) | Y53: 1C x 70 sqmm AL, PVC Cable | AH53: 2 Nos.
C54: 3. HV / MV / LV switchgear, Main earth grid around substation, Plant earth grid | Y54: 75 x 10 mm GI strip
C55: 4. NGR Earth Terminal | Q55: (Refer E12-041) | Y55: 75 x 10 mm GI strip | AH55: 2 Nos.
C56: 5. Distribution Transformer Neutral | Q56: (Refer E12-040) | Y56: 75 x 10 mm GI strip | AH56: 2 Nos.
C57: 6. Power & Distribution Transformer Body | Q57: (Refer E12-040 / 041) | Y57: 75 x 10 mm GI strip | AH57: 2 Nos.
C58: 7. Transformer HV Terminal Box | Q58: (Refer E12-040 / 041) | Y58: 75 x 10 mm GI strip | AH58: 2 Nos.
...

Sheet Sheet 6
AR1: https://www.flasysdesign.com/
A2: Earthing & Lightning Protection Calculation | AR2: Email: contact@flasysdesign.com
E5: Type of Equipment | Y5: Bare GI Strip / GI Wire
D8: Contd from previous sheet…
C10: 8. Local Control stations (LCS) ** | Y10: 1C x 6 sqmm Cu, PVC Cable | AH10: 1 No.
C11: 9. Rectifier / battery charger, Local Panels | Y11: 1C x 35 sqmm AL, PVC Cable | AH11: 2 Nos.
C12: 10. Lighting Transformers | Y12: 50 x 6 mm GI strip | AH12: 2 Nos.
C13: 11. Lighting, Small Power and Instrument panels, UPS | Y13: 1C x 70 sqmm AL, PVC Cable | AH13: 2 Nos.
C14: 12. Street lighting poles | Q14: (Refer E12-012) | Y14: 1C x 35 sqmm AL, PVC Cable | AH14: 2 Nos.
C15: 13. Pipe racks & cable Trays on Piperack | Q15: (Refer E12-042) | Y15: 50 x 6 mm GI strip at min 30 m interval | AI15: 1 No.
C16: 14. Bonding of pipeworks | Q16: (Refer E12-047) | Y16: 1C x 35 sqmm AL, PVC Cable | AH16: 1 No.
D17: (For pipelines entering & leaving hazardous area)
C18: 15. Building columns / Steel Structure | Y18: 50 x 6 mm GI strip at min 30 m interval
C19: 16. Storage tanks (vertical and horizontal) | Y19: 50 x 6 mm GI strip | AH19: 2 Nos.
C20: 17. Stairs & Ladders | Q20: (Refer E12-046) | Y20: 1C x 35 sqmm AL, PVC Cable | AH20: 1 No.
C21: 18. Vessels and heat exchangers | Q21: (Refer E12-042) | Y21: 1C x 35 sqmm AL, PVC Cable | AH21: 2 Nos.
C22: 19. Small equipment and instruments | Y22: 1C x 16 sqmm AL, PVC Cable | AH22: 1 No.
C23: 20. | D23: Instrument reference earth Bus (Insulated earth bus) | R23: (Refer E12-044) | Y23: 1C x 70 sqmm AL, PVC Cable from Earth pit to
Y24: earth Bus & 1C x 6 sqmm Cu, PVC Cable from
Y25: Earth Bus to equipment
C26: 21. Horizontal Air Termination for lightning protection of buildings | Y26: 50 x 6 mm GI Strip | AE26: (mesh of 20 m x 10 m)
C27: 22. Down conductor for lightning protection of buildings ## | Y27: 50 x 6 mm GI Strip | AE27: (Qty As calculated)
C28: 23. Power JBs | Y28: 1C x 35 sqmm AL, PVC Cable | AH28: 2 Nos.
C29: 24. Motors up to and including 2.2 kW $$ | Y29: 1C x 6 sqmm Cu, PVC Cable | AH29: 2 Nos.
C31: ** Based on mail dated 10th Feb 2014
C32: ## Based on mail dated 20th May 2014
C33: $$ based on confirmation to TQ-0077 dated 07th July 2014
B35: Summary of Earth Electrodes
B37: 1. | C37: Earth Pits for 4 Nos Power Transformers Neutral Earthing | AB37: : | AC37: 8 | AD37: Nos
B38: 2. | C38: Earth Pits for 8 Nos Distribution Transformers Neutral Earthing | AB38: : | AC38: 16 | AD38: Nos
B39: 3. | C39: Earth pits along the piperack (Approx. every 30m) | AB39: : | AC39: 30 | AD39: Nos
B40: 4. | C40: Earth pits inside plant | AB40: : | AC40: =81-AC39-AC38-AC37 -> 27 | AD40: Nos
B41: 5. | C41: Earth Pits for Instrument Clean Earthing - Near Substation Treated Earthpits (Refer E12-38) | AB41: : | AC41: 3 | AD41: Nos
B42: 6. | C42: Earth Pits for Instrument Clean Earthing - Near PIB Treated Earthpits (Refer E12-38) | AB42: : | AC42: 3 | AD42: Nos
B43: 7. | C43: Earth Pits for Instrument Clean Earthing - in Reaction Area Treated Earthpits (Refer E12-38) | AB43: : | AC43: 3 | AD43: Nos
B44: 8. | C44: Earth Pits for Instrument Clean Earthing - in Elutriator Area Treated Earthpits (Refer E12-38) | AB44: : | AC44: 3 | AD44: Nos
B45: 9. | C45: Earth Pits for Lightning Protection System (Various structures as calculated in Section-2) | AB45: : | AC45: 26 | AD45: Nos
C47: Note : For actual location of earth electrodes refer Overall Plot Plan (ISBL) Earthing layout Dwg No. 10013-E61-CHC501-000001.
AC61: Page | AE61: 9 | AG61: of | AI61: 9

Sheet Sheet 7
AM1: https://www.flasysdesign.com/
A2: Earthing & Lightning Protection Calculation | AM2: Email: contact@flasysdesign.com
N4: Section-2 : Lightning Study
B5: 1 | C5: Scope:
C6: This document covers the calculation to determine and establish the adequecy of Llightning Protection System (LPS) requirements
C7: (for the Tall structures, Substation, PIB building & Maintenance building) .
B9: 2 | C9: Reference Documents:
C10: 1. IS 2309 : Protection of Buildings and Allied Structures Against Lightning - Code of Practice
C11: 2. Doc No. 10013-P50-CHC501-001-REV-3 : Unit Plot plan
B13: 3 | C13: Design Inputs:
C14: 1. No. of thunderstorm days per year = 6 | T14: (Ref Fig. 1 of IS 2309)
C15: 2. Number of flashes to ground per sq.km per year = 0.5 | T15: (Ref section 8.1.2 of IS 2309)
C16: 3. Earth resistance: 10 Ω for lightning
C17: 4. Down comer size 32x6 mm GI strip
C19: Lightning Protection System (LPS)- General
B20: The principal components of Lightning Protection System are:
B22: a. Air terminations (e.g. rods, horizontal roof conductors, metallic roofs, hand rails etc) b. Down conductors (e.g. metal strips, part of building metal frame work, interconnected steel frame work of structure etc) c. Earth termination network/electrode (e.g. main earthing grid & earth electrodes)
C23: Lightning Protection System - Plant
B24: From lightning protection point of view, buildings / process units of the Plant can be broadly classified in two categories viz.
B26: a. RCC Buildings (e.g. Substations, PIB building & Maintenance building).
B27: b. Metallic structures/buildings (e.g. Resin Degassing & Pelletising Building, Reaction Area (including Compressor shed), Seed Bed Silos, Pellet Blending Silos, Vent Gas Recovery & Compression and Purification )
B29: 4 | C29: Formulae:
C30: 1. Total Collection Area (in m2) (Ref.equation 1 of 8.1.2 of IS-2309-1989)
D31: Ac | E31: =
D32: where, | F32: Ac = Collection Area in m2
F33: L = Length of the structure in meter
F34: W = Width of the structure in meter
F35: H = Height of the structure in meter
C37: 2. The probable no. of strikes (Risk) to the structure per year (Ref.equation 2 of 8.1.2 of IS-2309-1989)
D39: P | E39: =
D40: where, | F40: P = The probable no. of strikes (Risk) to the structure per year
F41: Ac = Collection Area in m2
F42: Ng = Lightning flashes per sq. Kilometer per year
C44: 3. Recommended No. of Down Conductors (Ref.12.2.3 of IS-2309)
C46: For a structure having a base area exceeding 100 sq.meter , the number of Down conductors should be at least
C47: the smaller of the following:
C49: a) | D49: One plus an additional one for each 300 sq.meter, or a part thereof , in excess of the first 100 sq.meter.
C51: b) | D51: One for each 30 meter of perimeter of the structure protected.
AB57: Page | AD57: 1 | AF57: of | AH57: 7

Sheet Sheet 8
AM1: https://www.flasysdesign.com/
A2: Earthing & Lightning Protection Calculation | AM2: Email: contact@flasysdesign.com
B4: 5 | C4: Calculations:
B6: A. | C6: Determination of requirement of lightning protection for substation building
C8: Determination of “Ng” ( Lightning flash density ) :
C9: The lightning flash density “Ng” is the number of flashes to ground per sq.km per year.
C11: Ng = | E11: 0.5
C13: Determination of “Ac” ( Effective collection area of structure ):
C14: The effective collection area of structure is the area of the plan of the structure extended in all direction to take account of its height.
C16: Substation Dimensions : Length (L) = 78 m, Width (W) = 18 m, Height (H) = 11 m
C17: Ac = (L x W) + 2(L x H) + 2(W x H) + (Π x H2 ) | U17: (Refer IS 2309, Figure 2)
C18: Ac = (78 x 18) + 2(78 x 11) + 2(18 x 11) + (3.14 x 112 )
C19: Ac = | E19: =(78*18)+2*(78*11)+2*(18*11)+(PI()*11^2) -> 3896.1327 | H19: m2
C21: Calculation of “Probable number of strikers”:
C22: P = Ac x Ng x 10-6 | L22: (Ref section 8.1.2 of IS 2309)
C23: P = 3896.1 x 0.5 x 10-6
C24: P = | D24: =E19*E11*10^-6 -> 0.0019480664 | H24: = 1.95 x 10 -3
C26: Calculation of “Overall weighting Factors” :
C28: Overall weigthing factors = A x B x C x D x E
I29: = 0.7 x 0.4 x 0.8 x 1 x 0.3 ( Ref. IS 2309, Table 1 )
I30: = | J30: =0.7*0.4*0.8*1*0.3 -> 0.0672
C32: · Determination of “Overall Risk Factor”
C34: Overall Risk Factor = P x Overall weigthing Factor
F35: = | G35: =D24 -> 0.0019480664 | J35: x | K35: =J30 -> 0.0672
F36: = | G36: =G35*K35 -> 0.00013091006 | M36: = 13.1 x 10 -5
G37: 13.1 x 10-5 | K37: > | L37: 10-5
C38: As per IS 2309 Clause 8.1.3 If Overall Risk Factor is greater than 10-5, protection is required.
C40: Air termination (mesh of 20 m x 10 m) GI strip of size 50 x 6 mm may be employed as shown in typical arrangement fig 5 of IS 2309
C42: Calculation for number of Down conductors required :
C43: As per Clause 12.2.3 and 12.2.4 & Tabel - 4 of IS 2309, Down conductors required shall be as follows:
E45: Base Area of Substation building = (Area of Switchgear room ) + (Area of VFD & maint room) + (Area of Staircases)
E46: Base Area of Substation building = (78 x 12) + (6 x 24) + 3 x (6 x 6) | X46: =(78*12)+(6*24)+3*(6*6) -> 1188 | AB46: m2 | AC46: > 100 m2
E47: Number of down conductors shall be at least the smaller of the following,
E49: i) One + Additional one for each 300 m2 of base area in excess of first 100 m2
E51: Number of down conductors | M51: = 1 + (1188 - 100) | T51: = | U51: =1+(X46-100)/300 -> 4.6266667 | W51: ~ 5
O52: 300
E53: ii) one for each 30 m of perimeter of structure,
G54: Perimeter of Substation building = 2 x (78 + 12) + (8 x 6) = | V54: =2*(78+12)+(8*6) -> 228 | Y54: m
F56: Number of down conductors = | O56: =V54 -> 228 | T56: = | U56: =V54/30 -> 7.6 | W56: ~ 8
O57: 30
...

Sheet Sheet 9
AM1: https://www.flasysdesign.com/
A2: Earthing & Lightning Protection Calculation | AM2: Email: contact@flasysdesign.com
C4: B. | D4: Determination of lightning protection for Plant Interface Building (PIB)
D6: Determination of “Ng” ( Lightning flash density ) :
D7: The lightning flash density “Ng” is the number of flashes to ground per sq.km per year.
D9: Ng = | F9: ='Sheet 8'!E11 -> 0.5 | M9: (Ref section 8.1.2 of IS 2309)
D11: Determination of “Ac” ( Effective collection area of structure ):
D12: The effective collection area of structure is the area of the plan of the structure extended in all direction to take account of its height.
D14: PIB Building Dimensions : Length (L) = 37 m, Width (W) = 10 m, Height (H) = 5.65 m
D16: Ac = (L x W) + 2(L x H) + 2(W x H) + (Π x H2 ) | V16: (Refer IS 2309, Figure 2)
D17: Ac = (37 x 10) + 2(37 x 5.65) + 2(10 x 5.65) + (3.14 x 5.652 )
D18: Ac = | F18: =(37*10)+2*(37*5.65)+2*(10*5.65)+(3.14*5.65*5.65) -> 1001.3367 | I18: m2
D20: Calculation of “Probable number of strikers”:
D21: P = Ac x Ng x 10-6 | M21: (Ref section 8.1.2 of IS 2309)
D22: P = 1001.34 x 0.5 x 10-6
D23: P = | E23: =F18*F9*10^-6 -> 0.00050066833 | I23: = 0.5 x 10 -3
D25: Calculation of “Overall weighting Factors” :
D27: Overall weigthing factors = A x B x C x D x E
J28: = 0.7 x 0.4 x 0.8 x 1 x 0.3 ( Ref. IS 2309, Table 1 )
J29: = | K29: =0.7*0.4*0.8*1*0.3 -> 0.0672
D31: · Determination of “Overall Risk Factor”
C32: Overall Risk Factor = P x Overall weigthing Factor
F33: = | G33: ='Sheet 9'!E23 -> 0.00050066833 | J33: x | K33: ='Sheet 9'!K29 -> 0.0672
F34: = | G34: =G33*K33 -> 3.3644911e-05 | K34: = 3.4 x 10 -5
F35: = | G35: 3.4 x 10-5 | K35: > | L35: 10-5
C37: As per IS 2309 Clause 8.1.3 If Overall Risk Factor is greater than 10-5, protection is required.
C39: Air termination (mesh of 20 m x 10 m) GI strip of size 50 x 6 mm may be employed as shown in typical arrangement fig 5 of IS 2309
C41: Calculation for number of Down conductors required :
C42: As per Clause 12.2.3 and 12.2.4 & Tabel - 4 of IS 2309, Down conductors required shall be as follows:
E44: Base Area of PIB building = 37 x 10 = 370 m2 > 100 m2
E45: Number of down conductors shall be at least the smaller of the following,
E47: i) One + Additional one for each 300 m2 of base area in excess of first 100 m2
E49: Number of down conductors | L49: = 1 + (370 - 100) | S49: = | T49: =1+(370-100)/300 -> 1.9 | V49: ~ 2 | AX49: .
M50: 300
E52: ii) one for each 30 m of perimeter of structure,
G53: Perimeter of PIB building = (2 x 30) + (2 x 10) = | T53: =(2*30)+(2*10) -> 80
F55: Number of down conductors = | O55: =T53 -> 80 | T55: = | U55: =O55/30 -> 2.6666667 | W55: ~ 3
O56: 30
D57: Hence 2 numbers down conductors of GI earth strip size 50 x 6 mm are required. Down conductors shall be further
D58: connected to dedicated earth pits (2 nos).
...

Sheet Sheet 10
AN1: https://www.flasysdesign.com/
A2: Earthing & Lightning Protection Calculation | AN2: Email: contact@flasysdesign.com
C4: C. | D4: Determination of lightning protection for Maintenance Building
D6: Determination of “Ng” ( Lightning flash density ) :
D7: The lightning flash density “Ng” is the number of flashes to ground per sq.km per year.
D9: Ng = | F9: ='Sheet 9'!F9:G9 -> 0.5 | M9: (Ref section 8.1.2 of IS 2309)
D11: Determination of “Ac” ( Effective collection area of structure ):
D12: The effective collection area of structure is the area of the plan of the structure extended in all direction to take account of its height.
D14: Maintenance Building Dimensions : Length (L) = 34.5 m, Width (W) = 23.50 m, Height (H) = 7.7 m
D16: Ac = (L x W) + 2(L x H) + 2(W x H) + (Π x H2 ) | V16: (Refer IS 2309, Figure 2)
D17: Ac = (34.5 x 23.5) + 2(34.5 x 7.7) + 2(23.5 x 7.7) + (3.14 x 7.72 )
D18: Ac = | F18: =(34.5*23.5)+2*(34.5*7.7)+2*(23.5*7.7)+(3.14*7.7*7.7) -> 1890.1206 | I18: m2
D20: Calculation of “Probable number of strikers”:
D21: P = Ac x Ng x 10-6 | M21: (Ref section 8.1.2 of IS 2309)
D22: P = 1890.12 x 0.5 x 10-6
D23: P = | E23: =F18*F9*10^-6 -> 0.0009450603 | I23: = 0.95 x 10 -3
D25: Calculation of “Overall weighting Factors” :
D27: Overall weigthing factors = A x B x C x D x E
J28: = 0.7 x 0.4 x 0.8 x 1 x 0.3 ( Ref. IS 2309, Table 1 )
J29: = | K29: =0.7*0.4*0.8*1*0.3 -> 0.0672
D30: · Determination of “Overall Risk Factor”
C32: Overall Risk Factor = P x Overall weigthing Factor
F33: = | G33: ='Sheet 10'!$E$23 -> 0.0009450603 | J33: x | K33: ='Sheet 10'!K29 -> 0.0672
F34: = | G34: =G33*K33 -> 6.3508052e-05 | K34: = 6.4 x 10 -5
F35: = | G35: 6.4 x 10-5 | K35: > | L35: 10-5
C37: As per IS 2309 Clause 8.1.3 If Overall Risk Factor is greater than 10-5, protection is required.
C39: Air termination (mesh of 20 m x 10 m) GI strip of size 50 x 6 mm may be employed as shown in typical arrangement fig 6 of IS 2309
C41: Calculation for number of Down conductors required :
C42: As per Clause 12.2.3 and 12.2.4 & Tabel - 4 of IS 2309, Down conductors required shall be as follows:
E44: Base Area of the building = 34.5 x 23.5 = 810.75 m2 > 100 m2
E45: Number of down conductors shall be at least the smaller of the following,
E47: i) One + Additional one for each 300 m2 of base area in excess of first 100 m2
E49: Number of down conductors | L49: = 1 + (810.7 - 100) | S49: = | T49: =1+(810.75-100)/300 -> 3.3691667 | V49: ~ 4 | AX49: .
M50: 300
E52: ii) one for each 30 m of perimeter of structure,
G53: Perimeter of the building = (2 x 34.5) + (2 x 23.5) = | T53: =(2*34.5)+(2*23.5) -> 116
F55: Number of down conductors = | O55: =T53 -> 116 | T55: = | U55: =O55/30 -> 3.8666667 | W55: ~ 4
O56: 30
D57: Hence 4 numbers down conductors of GI earth strip size 50 x 6 mm are required. Down conductors shall be further
D58: connected to dedicated earth pits (4 nos).
...

Sheet Sheet 11
AL1: https://www.flasysdesign.com/
A2: Earthing & Lightning Protection Calculation | AL2: Email: contact@flasysdesign.com
C4: D. | D4: Determination of lightning protection for Catalyst Storage Building
D6: Determination of “Ng” ( Lightning flash density ) :
D7: The lightning flash density “Ng” is the number of flashes to ground per sq.km per year.
D9: Ng = | F9: ='Sheet 9'!F9:G9 -> 0.5 | M9: (Ref section 8.1.2 of IS 2309)
D11: Determination of “Ac” ( Effective collection area of structure ):
D12: The effective collection area of structure is the area of the plan of the structure extended in all direction to take account of its height.
D14: Catalyst storage Building Dimensions : Length (L) = 40 m, Width (W) = 40 m, Height (H) = 8.7 m
D16: Ac = (L x W) + 2(L x H) + 2(W x H) + (Π x H2 ) | V16: (Refer IS 2309, Figure 2)
D17: Ac = (40 x 40) + 2(40 x 8.7) + 2(40 x 8.7) + (3.14 x 8.72 )
D18: Ac = | F18: =(40*40)+2*(40*8.7)+2*(40*8.7)+(3.14*8.7*8.7) -> 3229.6666 | I18: m2
D20: Calculation of “Probable number of strikers”:
D21: P = Ac x Ng x 10-6 | M21: (Ref section 8.1.2 of IS 2309)
D22: P = 3229.67 x 0.5 x 10-6
D23: P = | E23: =F18*F9*10^-6 -> 0.0016148333 | I23: = 1.61 x 10 -3
D25: Calculation of “Overall weighting Factors” :
D27: Overall weigthing factors = A x B x C x D x E
J28: = 0.7 x 0.4 x 0.8 x 1 x 0.3 ( Ref. IS 2309, Table 1 )
J29: = | K29: =0.7*0.4*0.8*1*0.3 -> 0.0672
D30: · Determination of “Overall Risk Factor”
C32: Overall Risk Factor = P x Overall weigthing Factor
F33: = | G33: ='Sheet 11'!$E$23 -> 0.0016148333 | J33: x | K33: ='Sheet 11'!K29 -> 0.0672
F34: = | G34: =G33*K33 -> 0.0001085168 | K34: = 10.9 x 10 -5
F35: = | G35: 10.9 x 10-5 | K35: > | L35: 10-5
C37: As per IS 2309 Clause 8.1.3 If Overall Risk Factor is greater than 10-5, protection is required.
C39: Air termination (mesh of 20 m x 10 m) GI strip of size 50 x 6 mm may be employed as shown in typical arrangement fig 6 of IS 2309
C41: Calculation for number of Down conductors required :
C42: As per Clause 12.2.3 and 12.2.4 & Tabel - 4 of IS 2309, Down conductors required shall be as follows:
E44: Base Area of the building = 40 x 40 = 1600 m2 > 100 m2
E45: Number of down conductors shall be at least the smaller of the following,
E47: i) One + Additional one for each 300 m2 of base area in excess of first 100 m2
E49: Number of down conductors | L49: = 1 + (1600 - 100) | S49: = | T49: =1+(1600-100)/300 -> 6 | AX49: .
M50: 300
E52: ii) one for each 30 m of perimeter of structure,
G53: Perimeter of the building = (2 x 40) + (2 x 40) = | T53: =(2*40)+(2*40) -> 160
F55: Number of down conductors = | O55: =T53 -> 160 | T55: = | U55: =O55/30 -> 5.3333333 | W55: ~ 6
O56: 30
D57: Hence 6 numbers down conductors of GI earth strip size 50 x 6 mm are required. Down conductors shall be further
D58: connected to dedicated earth pits (6 nos).
...

Sheet Sheet 12
AP1: https://www.flasysdesign.com/
A2: Earthing & Lightning Protection Calculation | AP2: Email: contact@flasysdesign.com
A4: E. | B4: LPS FOR METALLIC STRUCTURES / BUILDINGS
A6: a. | B6: Resin Degassing & Pelletising Building:
B7: Area of the Structure : 50.3 Mtr. x 45.5 Mtr. | M7: (Base Area)
B8: Height of the Structure : 133.7 Mtr.
B10: Resin Degassing & Pelletising is having Concrete Structure upto EL 69.8 m and metallic structures above (made of structural steel columns, beams, interconnecting framework, platforms at different elevations, handrails etc.). Since the total structure is metallic and firmly bonded from top to bottom they can be considered as “Natural components” of LPS. Hence no separate “Air Termination Network” and “Down Conductors” are envisaged for Structure above EL 69.8 m Peripheral steel columns of these structures shall be connected (at every 30 Mtrs interval) to main Earthing Network via 50 x 6 mm GI strips,
B11: However Lightning Protection for the Concrete structure (terrace) at EL 63.300 & EL 69.800 shall be provided.
B12: Air termination (mesh of 20 m x 10 m) GI strip of size 50 x 6 mm may be employed as shown in typical arrangement fig 5 of IS 2309
B14: Since the Structure is above 20 m Height, calculation for Probable no. of strikes & Risk factor is omitted.
B15: And it is considered that Lightning protection is required.
C17: Calculation for number of Down conductors required :
C18: As per Clause 12.2.3 and 12.2.4 & Tabel - 4 of IS 2309, Down conductors required shall be as follows:
E20: Base Area of Structure = 50.3 x 45.5 = 2288.65 m2 > 100 m2
E21: Number of down conductors shall be at least the smaller of the following,
E23: i) One + Additional one for each 300 m2 of base area in excess of first 100 m2
E25: Number of down conductors | L25: = 1 + (2288.65 - 100) | S25: = | T25: =1+(2288.65-100)/300 -> 8.2955 | V25: ~ 9 | AX25: .
M26: 300
E28: ii) one for each 30 m of perimeter of structure,
G29: Perimeter of Structure = (2 x 50.3) + (2 x 45.5) = | T29: =(2*50.3)+(2*45.5) -> 191.6
F31: Number of down conductors = | O31: =T29 -> 191.6 | T31: = | U31: =O31/30 -> 6.3866667 | W31: ~ 7
O32: 30
C33: Hence 7 Nos numbers down conductors of GI earth strip size 50 x 6 mm are required for the Lightning protection Grid.
C34: Additionally 2 Nos Down conductors are required for Direct connection of Steel structure (above EL 69.8 m) to the Earth grid.
C35: Therefore Total 9 Nos Down conductors shall be required to be connected to dedicated earth pits (9 nos).
A37: b. | B37: Other Structures in the Plant (having Height above 20 m)
B39: Most of the process units in the plant are metallic structures (made of structural steel columns, beams, interconnecting framework, platforms at different elevations, handrails etc.) Since these structures are metallic and firmly bonded from top to bottom they can be considered as “Natural components” of LPS and hence no separate “Air Termination Network” and “Down Conductors” are necessary. (Refer sections 12.1, 12.2 & 12.5.3 of IS 2309:1989)
B41: Peripheral steel columns of these structures shall be connected (at every 30 Mtrs interval) to main Earthing Network via 50 x 6 mm GI strips. Resistance to earth for LPS shall be less than 10 Ω. (Refer IS 2309: 1989 section 12.3.1).
B43: Since earth termination network of LPS and plant main earth network is common (as recommended in IS 2309:1989 section 12.3.3) the resistance to earth shall be less than 1 Ω thus ensuring very efficient LPS.
B45: Below is the list of such structures
A46: i. | B46: Reaction Area (including Compressor shed)
B47: Area of the Structure : 66 Mtr. x 31.5 Mtr.
B48: Height of the Structure : 83.85 Mtr.
AB51: Page | AD51: 6 | AF51: of | AH51: 7

Sheet Sheet 13
T1: https://www.flasysdesign.com/
A2: Earthing & Lightning Protection Calculation | T2: Email: contact@flasysdesign.com
A4: ii. | B4: Seed Bed Silos
B5: Area of the Structure : 30.25 Mtr. x 8.5 Mtr.
B6: Height of the Structure : 81.5 Mtr.
A8: iii. | B8: Pellet Blending Silos
B9: Area of the Structure : 94.65 Mtr. x 11 Mtr.
B10: Height of the Structure : 79.5 Mtr.
A12: iv. | B12: Vent Gas Recovery & Compression
B13: VGR Structure
B14: Area of the Structure : 34 Mtr. x 25 Mtr.
B15: Height of the Structure : 59.15 Mtr.
B16: Compressor shed
B17: Area of the Structure : 42 Mtr. x 21 Mtr.
B18: Height of the Structure : 50.7 Mtr.
A20: v. | B20: Purification
B21: Hexene & Butene Area
B22: Area of the Structure : 36 Mtr. x 8 Mtr. + 12 Mtr. x 12 Mtr.
B23: Height of the Structure : 63.2 Mtr.
B25: Hydrogen Compressor Area
B26: Area of the Structure : 33.5 Mtr. x 7 Mtr.
B27: Height of the Structure : 52.5 Mtr.
B29: Nitrogen Compressor Area
B30: Area of the Structure : 30 Mtr. x 7 Mtr.
B31: Height of the Structure : 47.65 Mtr.
B33: ICA & Butane Area
B34: Area of the Structure : 24 Mtr. x 8 Mtr. + 12 Mtr. x 12 Mtr.
B35: Height of the Structure : 53 Mtr.
... B45: the structure is provided with 2 nos Lightning protection earth pits.
A47: v. | B47: Piperack PR-12
B48: Grid PR/18 to PR/96 of this piperack is having height Approx 23 m. Further this piperack is located between C&P Building & Reaction structure
B49: Which are covered in lightning protection calculation above. Therefore separate lightning protection is not required for piperack PR-12,
B50: However for additional safety 2 nos of Lightning Earth pits are considered for Lightning protection
A53: 6 | B53: SUMMARY
A55: (a) | B55: For this Plant, LPS for RCC buildings has been determined as per IS-2309:1989 guidelines.
A56: (b) | B56: For all process units which are metallic structures, no separate “Air Termination Network” and “Down Conductors” are proposed/provided. This is in line with IS recommendations. At ground level, these structures are connected to “Main Earth Network” to ensure earth connectivity below 1 Ω.
AB65: Page | AD65: 7 | AF65: of | AH65: 7

Sheet Annex-1
AP1: https://www.flasysdesign.com/
A2: Earthing & Lightning Protection Calculation | AP2: Email: contact@flasysdesign.com
N3: Annexure-1
B4: 1. | C4: Fault current calculations for 415V Motor
C5: Largest LV Motor on 415V Switchboard in the plant is SEED BED BLOWER MOTOR (Tag no. MA-CHC501-M5613, 5614) of rating 225 kW.
C6: The fault current calculated at this motor terminal is as below :
C8: Fault current available at PMCC Bus | O8: 65 | R8: kA
C10: Source Voltage | O10: 0.415 | R10: kV
C12: Source Reactance (Xs) | O12: =O10/(1.732*O8) -> 0.0036862675 | R12: Ohm
C14: Cable size used | O14: 3C X 300 | R14: sqmm Aluminium cable | Y14: (Selected based on LV cable sizing table 10080-1-ENGG-GUI-EL-003)
C16: No of runs | O16: 3
C18: Cable Length | O18: 275 | R18: m | Y18: (Estimated from plot plan)
C20: Cable Resistance | H20: (ohm/km) | O20: 0.128 | R20: ohm/km
C22: Cable Reactance | H22: (ohm/km) | O22: 0.0705 | R22: ohm/km
C24: Actual Cable Resistance | M24: Rc | O24: =(O18/1000)*O20/O16 -> 0.011733333 | R24: ohm
C26: Actual Cable Reactance | M26: Xc | O26: =(O18/1000)*O22/O16 -> 0.0064625 | R26: ohm
C28: Z total = | E28: Ö | F28: Rc2 + (Xs + Xc)2 | M28: Z total | O28: =SQRT(O24^2+(O12+O26)^2) -> 0.015513497 | R28: ohm
C30: Fault current at end of Cable | O30: =O10/(1.732*O28) -> 15.445092 | R30: kA
B32: 2. | C32: Fault current calculations for 690V Motor
C33: From substation nearest 690V Motor in the plant is PELLET WATER PUMP MOTOR (Tag no. MP-CHC501-M7012 / 7017) of rating 250kW.
C34: The fault current calculated at this motor terminal is as below :
C36: Fault current available at PMCC Bus | O36: 65 | R36: kA
C38: Source Voltage | O38: 0.69 | R38: kV
C40: Source Reactance (Xs) | O40: =O38/(1.732*O36) -> 0.006128975 | R40: Ohm
C42: Cable size used | O42: 3C X 150 | R42: sqmm Aluminium cable | Y42: (Selected as per LV cable sizing calculation 10013-EWLC-CHC501-002)
C44: No of runs | O44: 2
C46: Cable Length | O46: 190 | R46: m
C48: Cable Resistance | H48: (ohm/km) | O48: 0.264 | R48: ohm/km
C50: Cable Reactance | H50: (ohm/km) | O50: 0.0716 | R50: ohm/km
C52: Actual Cable Resistance | M52: Rc | O52: =(O46/1000)*O48/O44 -> 0.02508 | R52: ohm
C54: Actual Cable Reactance | M54: Xc | O54: =(O46/1000)*O50/O44 -> 0.006802 | R54: ohm
C56: Z total = | E56: Ö | F56: Rc2 + (Xs + Xc)2 | M56: Z total | O56: =SQRT(O52^2+(O40+O54)^2) -> 0.028217309 | R56: ohm
C58: Fault current at end of Cable | O58: =O38/(1.732*O56) -> 14.118404 | R58: kA
B60: Since calculated fault current for 415V system | O60: =O30 -> 15.445092 | Q60: kA is more than | V60: =O58 -> 14.118404 | X60: kA calculated for 690V system. Maximum fault
B61: current for Plant earth strip sizing shall be considered as | R61: =O60 -> 15.445092 | T61: kA
AB63: Page | AD63: 1 | AF63: of | AH63: 1

Sheet Portrait Page
A1: J3 Program
A2: Specification for …….
A58: Doc. No. 10013-EGC-CHC501-001 | J58: Page
A59: Rev: 0

Sheet Earth Pit Count
A2: Earth Pit Count
A4: 60 | B4: Substation & Plant Eartrh Grid including Transformer Neutral Grounding Pits
A5: 6 | B5: Instrument Clean earthing
A7: =SUM(A4:A6) -> 66 | B7: Total EP
A9: Lightning Earth Pits
A10: 5 | B10: substation building
A11: 3 | B11: Plant Interface Building (PIB)
A12: 3 | B12: Maintenance Building
A14: =SUM(A10:A13) -> 11 | B14: Total LEP
A17: =A7+A14 -> 77 | B17: Total EP + LEP
