Workbook
Name \0: #REF!
Name \0: #REF!
Name \0: #REF!
Name \0: #REF!
Name \C: #REF!
Name \C: #REF!
Name \C: #REF!
Name \C: #REF!
Name _: [1]LD!#REF!
Name _: [1]LD!#REF!
Name _: [1]LD!#REF!
Name _: [1]LD!#REF!
Name ____________________________Ki1: #REF!
Name ____________________________Ki2: #REF!
Name __________________________Ki1: #REF!
Name __________________________Ki2: #REF!
Name ________________________Ki1: #REF!
Name ________________________Ki2: #REF!
Name ________________________Re1: #REF!
Name ________________________Rs1: #REF!
Name _______________________LNK136: [2]SHEET6!$G$49
Name _______________________LNK137: [2]SHEET6!$G$50
Name _______________________Re1: #REF!
Name _______________________Rs1: #REF!
Name ______________________a1: #REF!
Name ______________________Ki1: #REF!
Name ______________________Ki1: #REF!
Name ______________________Ki1: #REF!
Name ______________________Ki1: #REF!
Name ______________________Ki2: #REF!
Name ______________________Ki2: #REF!
Name ______________________Ki2: #REF!
Name ______________________Ki2: #REF!
Name ______________________LNK136: [2]SHEET6!$G$49
Name ______________________LNK137: [2]SHEET6!$G$50
Name ______________________Re1: #REF!
Name ______________________Re1: #REF!
Name ______________________Re1: #REF!
Name ______________________Re1: #REF!
Name ______________________Rs1: #REF!
Name ______________________Rs1: #REF!
Name ______________________Rs1: #REF!
Name ______________________Rs1: #REF!
Name _____________________a1: #REF!
Name _____________________Ki1: #REF!
Name _____________________Ki1: #REF!
Name _____________________Ki1: #REF!
Name _____________________Ki1: #REF!
Name _____________________Ki2: #REF!
Name _____________________Ki2: #REF!
Name _____________________Ki2: #REF!
Name _____________________Ki2: #REF!
Name _____________________LNK136: [2]SHEET6!$G$49
Name _____________________LNK137: [2]SHEET6!$G$50
Name _____________________Re1: #REF!
Name _____________________Re1: #REF!
Name _____________________Re1: #REF!
Name _____________________Re1: #REF!
Name _____________________Rs1: #REF!
Name _____________________Rs1: #REF!

Sheet INV Earthing
B1: EARTHING DESIGN CALCULATION - INVERTER ROOM
B2: INPUT DATA:
B3: 1) | C3: Design Basis:
B5: i) | C5: Earth Electrode shall be GI pipe & main earth loop material shall be GI strip.
B6: ii) | C6: The earth conductor shall be adequately sized to carry the applicable maximum earth fault current
C7: without undue temperature rise.
B8: iii) | C8: All the earth connections shall be made in accordance with IS: 3043.
B10: 2) | C10: Reference:
B12: i) | C12: Code of Practice for Earthing (IS: 3043: 1987).
B13: ii) | C13: We have considered the highest fault level at the 33 kV level to be 25kA for 1 Sec.
B14: iii) | C14: Mean Electrical Soil Resistivity for the plant is considered as 100 Ohm-m (Average Condition assumed)
B15: iv) | C15: GI strip shall be of 50 x 6 mm.
B17: 3) | C17: Assumptions
B19: i) | C19: Earthing conductor shall be buried under a depth of 60 cm from the ground level.
B20: ii) | C20: Electrode shall be 65mm dia, 3 M long GI Pipe as per IS 3043
B22: 4) | C22: System Parameters
B24: i) | C24: Inverter Transformer Rating | I24: = | J24: 6000 | K24: kVA | L24: ( as maximum Inv. Trafo rating)
B25: ii) | C25: Operating Voltage | I25: = | J25: 33/ 0.400 | K25: kV
B26: iii) | C26: Impedance of Transformer | I26: = | J26: 6.25 | K26: %
B27: iv) | C27: Transformer Full Load Current on LV side | I27: =
I29: = | J29: =J24/ (1.732*0.4) -> 8660.5081 | K29: A
B30: v) | C30: Through Fault Current at Transformer (I) | I30: = | J30: 25000 | K30: A
B31: vi) | C31: Maximum opening time for VCB | I31: = | J31: 40 | K31: msec.
C32: during earth fault
B33: vii) | C33: Time considered for sizing the earth | I33: = | J33: 40+450 | K33: msec.
C34: conductor | I34: = | J34: 490 | K34: msec.
B35: viii) | C35: Mean Soil Resistivity, ρ | I35: = | J35: 100 | K35: Ohm - m
B36: ix) | C36: Buried Earthing Conductor | I36: = | J36: 50 x 6 | K36: GS flat
B37: x) | C37: Depth of Buried earthing, ω | I37: = | J37: 60 | K37: cm
B38: xi) | C38: Width of the buried conductor (t) | I38: = | J38: 6.5 | K38: cm
B39: xii) | C39: Total Length of the buried earthing | I39: = | J39: 15000 | K39: cm
C40: conductor (l) | J40: [Peripheral earthing and Branch Interconnections)
B41: xiii) | C41: Type of Electrode | I41: = | J41: 65mm dia, 3 m Long GI Pipe
B42: xiv) | C42: Number of Electrodes/ Inverter room | I42: = | J42: 10
B45: 5) | C45: Calculation
B47: i) | C47: Check for Fault current withstand capability of selected earthing conductor
B49: a) | C49: Required cross section of Earthing | I49: =
C50: Conductor , A
C51: (As per Cl.12.2.2.1 of IS: 3043)
C52: where,
...

Sheet PCSS & Sub PCSS
A1: EARTHING DESIGN CALCULATION - SUB PCSS & PCSS BUILDING
B2: INPUT DATA:
B3: 1) | C3: Design Basis:
B5: i) | C5: Earth Electrode shall be 65mm Dia, 3Metre long Pipe Electrode.
B6: ii) | C6: Buried Earth Grid shall be 50 x 8 mm G.I Flat Strip
B7: ii) | C7: The earth conductor shall be adequately sized to carry the applicable maximum earth fault current
B8: iii) | C8: All the earth connections shall be made in accordance with IS: 3043.
B10: 2) | C10: Assumption:
B12: i) | C12: Code of Practice for Earthing ( IS: 3043: 1987).
B13: ii) | C13: We have considered the fault level of 25kA for designing the Earth Grid and system
B14: iii) | C14: Mean Electrical Soil Resistivity for the plant is considered as 55 Ohm-m (Average Condition assumed)
B15: iv) | C15: Earthing conductor shall be buried under a depth of 60 cm from the ground level.
B17: 4) | C17: System Parameters
B19: i) | C19: Through Fault Current at LT Switchboard | I19: = | J19: 25000 | K19: A
B20: ii) | C20: Maximum opening time for Breaker | I20: = | J20: 1 | K20: sec.
C21: during earth fault
B22: iv) | C22: Mean Soil Resistivity, ρ | I22: = | J22: 100 | K22: Ohm - m | L22: Assumed 55 ohm-m for calculation purpose
B23: v) | C23: Buried Earthing Conductor | I23: = | J23: 50 | K23: mm G.I Flat Strip
B24: vi) | C24: Depth of Buried earthing, ω | I24: = | J24: 60 | K24: cm
B25: vii) | C25: Width of the buried conductor (t) | I25: = | J25: 5 | K25: cm
B26: vii) | C26: Total Length of the buried earthing | I26: = | J26: =(439+105)*100 -> 54400 | K26: cm
C27: conductor (l)
B28: viii) | C28: Type of Electrode | I28: = | J28: 65mm dia, 3m Long G.I Pipe Electrode
B29: ix) | C29: Number of Electrodes | I29: = | J29: 95
B32: 5) | C32: Calculation
B34: i) | C34: Check for Fault current withstand capability of selected earthing conductor
B36: a) | C36: Required cross section of Earthing | I36: =
C37: Conductor , A
C38: (As per Cl.12.2.2.1 of IS: 3043)
C39: where,
C40: I = fault current for which fault of negliable impedance can flow through the device
C41: K= factor dependent on the material of the protective conductor, the insulation and other parts, 80 for steel
C42: T = time for fault clearing in sec.
B43: b) | C43: Required cross section of Earthing | I43: = | J43: =""&J19&"""X""√"&J20&"" -> 25000"X"√1
J44: 80
I45: = | J45: =(J19* SQRT(J20) )/ 80 -> 312.5 | K45: Sq.mm
B46: c) | C46: Corrosion factor (15%) | I46: = | J46: =J45*1.15 -> 359.375 | K46: Sq.mm
B47: d) | C47: Selected cross sectional of earthing conductor | I47: = | J47: 400 | K47: Sq.mm
B49: ii) | C49: Calculation of Effective Resistance of buried earthing conductor (R cond )
B51: a) | C51: Resistance of Total buried earthing conductor, R cond = | M51: ohm
...

Sheet Solar Field Earthing Calc_ShedA
A1: EARTHING DESIGN CALCULATION - FLASYS DESIGN | Q1: https://www.flasysdesign.com/
Q2: Email: contact@flasysdesign.com
B3: INPUT DATA:
B4: 1) | C4: Design Basis:
B6: i) | C6: Earth Electrode shall be Chemical maintainance free earth pits & main earth loop material shall be GI strip.
B7: ii) | C7: The earth conductor shall be adequately sized to carry the applicable maximum earth fault current
B8: iii) | C8: All the earth connections shall be made in accordance with IS: 3043.
B10: 2) | C10: Reference:
B12: i) | C12: Code of Practice for Earthing ( IS: 3043: 1987).
B13: ii) | C13: Mean Electrical Soil Resistivity for the plant is considered as 100 Ohm-m (Average Value)
B14: iii) | C14: GI strip shall be of 25 x 6 mm.
B16: 3) | C16: Assumptions
B18: i) | C18: Earthing conductor shall be buried under a depth of 60 cm from the ground level.
B19: ii) | C19: Electrode shall be 17.2mm dia, 3 M long Cu bonded steel rod (chemical earthing)
B21: 4) | C21: System Parameters
B22: i) | C22: Module / String Current Isc is (for 340Wp) | I22: = | J22: 9.53 | K22: A
B23: ii) | C23: Total number of strings/Inverter. | I23: = | J23: 18 | K23: Nos | L23: Max Isc possible
B24: iii) | C24: Maximum Possibility of fault current that flows through the System DC Side | I24: = | J24: =J22*J23*1.2 -> 205.848 | K24: A
B26: iv) | C26: Through Fault Current at DC Side | I26: = | J26: =J24 -> 205.848 | K26: A
B27: v) | C27: Maximum opening time DC Combiner box fuse | I27: = | J27: 0.2 | K27: Sec
B28: vi) | C28: Mean Soil Resistivity, ρ | I28: = | J28: ='PCSS & Sub PCSS'!J22 -> 100 | K28: Ohm - m | L28: Assumed 100 ohm-m for calculation purpose
B30: vii) | C30: Buried Earthing Conductor | I30: = | J30: 25 x 6 | K30: GI flat
B31: viii) | C31: Depth of Buried earthing, ω | I31: = | J31: 60 | K31: cm
B32: ix) | C32: Width of the buried conductor (t) | I32: = | J32: 2.5 | K32: cm
B33: x) | C33: Total Length of the earthing | I33: = | J33: =439*100 -> 43900 | K33: cm
C34: conductor (l)
B36: xi) | C36: Type of Electrode | I36: = | J36: 17.2mm dia, 3 m Long Cu Bonded rod
B37: xii) | C37: Number of Electrodes | I37: = | J37: 4 | K37: No. of earth electrode for complete plant
B40: 5) | C40: Calculation
B42: i) | C42: Check for Fault current withstand capability of selected earthing conductor
B43: a) | C43: Required cross section of Earthing | I43: =
C44: Conductor , A
C45: (As per Cl.12.2.2.1 of IS: 3043)
C46: where,
C47: I = fault current for which fault of negliable impedance can flow through the device
C48: K= factor dependent on the material of the protective conductor, the insulation and other parts, 80 for steel
C49: T = time for fault clearing in sec.
B50: b) | C50: Required cross section of Earthing | I50: = | J50: =""&J26&""" X ""√"&J27&"" -> 205.848" X "√0.2
J51: 80
I52: = | J52: =(J26* SQRT(J27) )/ 80 -> 1.1507253 | K52: Sq.mm
...

Sheet Solar Field Earthing Calc_ShedB
A1: EARTHING DESIGN CALCULATION - FLASYS DESIGN | Q1: https://www.flasysdesign.com/
Q2: Email: contact@flasysdesign.com
B3: INPUT DATA:
B4: 1) | C4: Design Basis:
B6: i) | C6: Earth Electrode shall be Chemical maintainance free earth pits & main earth loop material shall be GI strip.
B7: ii) | C7: The earth conductor shall be adequately sized to carry the applicable maximum earth fault current
B8: iii) | C8: All the earth connections shall be made in accordance with IS: 3043.
B10: 2) | C10: Reference:
B12: i) | C12: Code of Practice for Earthing ( IS: 3043: 1987).
B13: ii) | C13: Mean Electrical Soil Resistivity for the plant is considered as 100 Ohm-m (Average Value)
B14: iii) | C14: GI strip shall be of 25 x 6 mm.
B16: 3) | C16: Assumptions
B18: i) | C18: Earthing conductor shall be buried under a depth of 60 cm from the ground level.
B19: ii) | C19: Electrode shall be 17.2mm dia, 3 M long Cu bonded steel rod (chemical earthing)
B21: 4) | C21: System Parameters
B22: i) | C22: Module / String Current Isc is (for 340Wp) | I22: = | J22: 9.53 | K22: A
B23: ii) | C23: Total number of strings/Inverter. | I23: = | J23: 18 | K23: Nos | L23: Max Isc possible
B24: iii) | C24: Maximum Possibility of fault current that flows through the System DC Side | I24: = | J24: =J22*J23*1.2 -> 205.848 | K24: A
B26: iv) | C26: Through Fault Current at DC Side | I26: = | J26: =J24 -> 205.848 | K26: A
B27: v) | C27: Maximum opening time DC Combiner box fuse | I27: = | J27: 0.2 | K27: Sec
B28: vi) | C28: Mean Soil Resistivity, ρ | I28: = | J28: ='PCSS & Sub PCSS'!J22 -> 100 | K28: Ohm - m | L28: Assumed 100 ohm-m for calculation purpose
B30: vii) | C30: Buried Earthing Conductor | I30: = | J30: 25 x 6 | K30: GI flat
B31: viii) | C31: Depth of Buried earthing, ω | I31: = | J31: 60 | K31: cm
B32: ix) | C32: Width of the buried conductor (t) | I32: = | J32: 2.5 | K32: cm
B33: x) | C33: Total Length of the earthing | I33: = | J33: =290*100 -> 29000 | K33: cm
C34: conductor (l)
B36: xi) | C36: Type of Electrode | I36: = | J36: 17.2mm dia, 3 m Long Cu Bonded rod
B37: xii) | C37: Number of Electrodes | I37: = | J37: 2 | K37: No. of earth electrode for complete plant
B40: 5) | C40: Calculation
B42: i) | C42: Check for Fault current withstand capability of selected earthing conductor
B43: a) | C43: Required cross section of Earthing | I43: =
C44: Conductor , A
C45: (As per Cl.12.2.2.1 of IS: 3043)
C46: where,
C47: I = fault current for which fault of negliable impedance can flow through the device
C48: K= factor dependent on the material of the protective conductor, the insulation and other parts, 80 for steel
C49: T = time for fault clearing in sec.
B50: b) | C50: Required cross section of Earthing | I50: = | J50: =""&J26&""" X ""√"&J27&"" -> 205.848" X "√0.2
J51: 80
I52: = | J52: =(J26* SQRT(J27) )/ 80 -> 1.1507253 | K52: Sq.mm
...
