Workbook
Name OLE_LINK1: 'Residential Calculation'!#REF!
Name Z_469DBDDD_1BF4_42DF_8346_CCEB36A66610_.wvu.PrintArea: 'Residential Calculation'!$A$1:$P$68
Name Z_B5324BE9_0109_4818_9111_08F05DCB7214_.wvu.PrintArea: 'Residential Calculation'!$A$1:$P$53

Sheet equipment set-up sheet
E5: =CHOOSE(E7,C8,C9,C10,C11,C12,C13,C14) -> 0 | G5: =CHOOSE(G7,G8,G9,G10,G11,G12,G13,G14,G15,G16) -> 1400 | I5: =CHOOSE(I7,I8,I9,I10,I11,I12,I13,I14) -> 800 | K5: =CHOOSE(K7,K8,K9,K10,K11,K12,K13,K14) -> 1200 | M5: =CHOOSE(M7,M8,M9,M10,M11,M12,M13,M14) -> 1127 | Q5: =CHOOSE(Q7,Q8,Q9,Q10,Q11,Q12,Q13,Q14,Q15,Q16) -> 1400
E6: Water Heater | G6: Refrigerator | I6: Freezer | K6: Dishwasher | M6: Disposal | Q6: Microwave
E7: 1 | G7: 1 | I7: 3 | K7: 3 | M7: 3 | Q7: 6
C8: 0 | E8: GAS | G8: 1400 | I8: 600 | K8: 1030 | M8: 690 | N8: 1/4hp | Q8: 1630
C9: =E9 -> 4500 | E9: 4500 | G9: 1500 | I9: 700 | K9: 1100 | M9: 828 | N9: 1/3hp | Q9: 1000
C10: =E10 -> 3500 | E10: 3500 | G10: 1600 | I10: 800 | K10: 1200 | M10: 1127 | N10: 1/2hp | Q10: 1100
C11: =E11 -> 6000 | E11: 6000 | G11: 1700 | I11: 900 | K11: 1300 | M11: 1587 | N11: 3/4hp | Q11: 1200
C12: =E12 -> 9000 | E12: 9000 | G12: 1800 | I12: 1000 | K12: 1400 | M12: 1840 | N12: 1 hp | Q12: 1300
C13: =E13 -> 0 | G13: 1900 | Q13: 1400
C14: =E14 -> 0 | G14: 2000 | Q14: 1500
Q15: 1700
E18: =CHOOSE(E20,E21,E22,E23,E24,E25) -> 1440 | G18: =CHOOSE(G20,G21,G22,G23,G24,G25) -> 288 | I18: =CHOOSE(I20,I21,I22,I23,I24,I25) -> 400 | K18: =CHOOSE(K20,K21,K22,K23,K24,K25) -> 12000 | M18: =CHOOSE(M20,M21,M22,M23,M24,M25) -> 540 | Q18: =CHOOSE(Q20,Q21,Q22,Q23,Q24,Q25) -> 1500
E19: Central Vac | G19: Mini Refrig | I19: Compactor | K19: Insta Hot | M19: Range Hood | Q19: Wine Cooler
E20: 1 | G20: 4 | I20: 1 | K20: 2 | M20: 2 | Q20: 1
E21: 1440 | G21: 170 | I21: 400 | K21: 6670 | M21: 400 | Q21: 1500
E22: 1600 | G22: 230 | I22: 780 | K22: 12000 | M22: 540 | Q22: 1800
E23: 1800 | G23: 340 | I23: 850 | M23: 700 | Q23: 2400
G24: 288 | M24: 1200
M27: Yellow cells are for Your entries
M28: Enter numerals only, DO NOT type VA.
E29: =CHOOSE(E31,E32,E33,E34,E35,E36,E37,E38,E39,E40) -> #VALUE! | AA29: 5 ton | AB29: 5 ton
E30: Central Air Strip Heat Units
E31: Select | G31: Blower/fan | I31: Total Load | M31: Blue cells are fixed and the first value is the default
A32: =CHOOSE(C$32,0,I$32,I$33,I$34,I$35,I$36,I$37,I$38,I$39,I$40,I$41,I$42,I$43,I$44,I$45) -> 11600 | C32: 6 | E32: 5kW | F32: + | G32: 800 | H32: = | I32: 5800
A33: =CHOOSE(C33,0,I$32,I$33,I$34,I$35,I$36,I$37,I$38,I$39,I$40,I$41,I$42,I$43,I$44,I$45) -> 8300 | C33: 3 | E33: 7.5kW | F33: + | G33: 800 | H33: = | I33: 8300
A34: =CHOOSE(C34,0,I$32,I$33,I$34,I$35,I$36,I$37,I$38,I$39,I$40,I$41,I$42,I$43,I$44,I$45) -> 0 | C34: 1 | E34: 8kW | F34: + | G34: 800 | H34: = | I34: 8800 | M34: Condensing Units / Heat Pumps | S34: Supplementary Heat & Blower | AA34: Step 2
A35: =CHOOSE(C35,0,I$32,I$33,I$34,I$35,I$36,I$37,I$38,I$39,I$40,I$41,I$42,I$43,I$44,I$45) -> 0 | C35: 1 | E35: 9.6kW | F35: + | G35: 1200 | H35: = | I35: 10800 | M35: Select | N35: Condensing Unit | Q35: Heat Pump | S35: Select | U35: Blower/fan | W35: Total Load | Z35: Qty | AA35: Qty | AE35: 1 | AG35: 1 | AI35: 1 | AK35: 1 | AM35: 1
A36: =CHOOSE(C36,0,I$32,I$33,I$34,I$35,I$36,I$37,I$38,I$39,I$40,I$41,I$42,I$43,I$44,I$45) -> 0 | C36: 1 | E36: 10 | F36: + | G36: 1600 | H36: = | I36: =SUM((E36*1000)+G36) -> 11600 | M36: 1 ton | N36: 1840 | S36: 2.5 | T36: + | U36: 1200 | V36: = | W36: =(S36*1000)+U36 -> 3700 | Y36: 1 | Z36: 1 | AA36: =CHOOSE(Y36,0,Z$36,Z$37,Z$38,Z$39,Z$40,Z$41,Z$42,Z$43,Z$44,Z$45) -> 0 | AB36: AHU 1 | AD36: CU | AE36: =CHOOSE(AE35,0,$N$36,$N$37,$N$38,$N$39,$N$40,$N$41,$N$42,$N$43,$N$44,$N$45,$N$46) -> 0 | AF36: CU | AG36: =CHOOSE(AG35,0,$N$36,$N$37,$N$38,$N$39,$N$40,$N$41,$N$42,$N$43,$N$44,$N$45,$N$46) -> 0 | AH36: CU | AI36: =CHOOSE(AI35,0,$N$36,$N$37,$N$38,$N$39,$N$40,$N$41,$N$42,$N$43,$N$44,$N$45,$N$46) -> 0 | AJ36: CU | AK36: =CHOOSE(AK35,0,$N$36,$N$37,$N$38,$N$39,$N$40,$N$41,$N$42,$N$43,$N$44,$N$45,$N$46) -> 0 | AL36: CU | AM36: =CHOOSE(AM35,0,$N$36,$N$37,$N$38,$N$39,$N$40,$N$41,$N$42,$N$43,$N$44,$N$45,$N$46) -> 0
E37: 12.5 | F37: + | G37: 1600 | H37: = | I37: =SUM((E37*1000)+G37) -> 14100 | M37: 1.5 ton | N37: 2200 | Q37: 2230 | S37: 3 | T37: + | U37: 800 | V37: = | W37: =(S37*1000)+U37 -> 3800 | Y37: 1 | Z37: 2 | AA37: =CHOOSE(Y37,0,Z$36,Z$37,Z$38,Z$39,Z$40,Z$41,Z$42,Z$43,Z$44,Z$45) -> 0 | AB37: AHU 2 | AD37: HP | AE37: =CHOOSE(AE35,0,$Q$36,$Q$37,$Q$38,$Q$39,$Q$40,$Q$41,$Q$42,$Q$43,$Q$44,$Q$45,$Q$46) -> 0 | AF37: HP | AG37: =CHOOSE(AG35,0,$Q$36,$Q$37,$Q$38,$Q$39,$Q$40,$Q$41,$Q$42,$Q$43,$Q$44,$Q$45,$Q$46) -> 0 | AH37: HP | AI37: =CHOOSE(AI35,0,$Q$36,$Q$37,$Q$38,$Q$39,$Q$40,$Q$41,$Q$42,$Q$43,$Q$44,$Q$45,$Q$46) -> 0 | AJ37: HP | AK37: =CHOOSE(AK35,0,$Q$36,$Q$37,$Q$38,$Q$39,$Q$40,$Q$41,$Q$42,$Q$43,$Q$44,$Q$45,$Q$46) -> 0 | AL37: HP | AM37: =CHOOSE(AM35,0,$Q$36,$Q$37,$Q$38,$Q$39,$Q$40,$Q$41,$Q$42,$Q$43,$Q$44,$Q$45,$Q$46) -> 0
E38: 15 | F38: + | G38: 1600 | H38: = | I38: =SUM((E38*1000)+G38) -> 16600 | M38: 2 ton | N38: 2850 | Q38: 3100 | S38: 4 | T38: + | U38: 1000 | V38: = | W38: =(S38*1000)+U38 -> 5000 | Y38: 1 | Z38: 3 | AA38: =CHOOSE(Y38,0,Z$36,Z$37,Z$38,Z$39,Z$40,Z$41,Z$42,Z$43,Z$44,Z$45) -> 0 | AB38: AHU 3 | AE38: =IF('Residential Calculation'!$R$13,"A/C #1","HP #1") -> A/C #1 | AG38: =IF('Residential Calculation'!$R$13,"A/C #2","HP #2") -> A/C #2 | AI38: =IF('Residential Calculation'!$R$13,"A/C #3","HP #3") -> A/C #3 | AK38: =IF('Residential Calculation'!$R$13,"A/C #4","HP #4") -> A/C #4 | AM38: =IF('Residential Calculation'!$R$13,"A/C #5","HP #5") -> A/C #5
E39: 18 | F39: + | G39: 2400 | H39: = | I39: =SUM((E39*1000)+G39) -> 20400 | M39: 2.5 ton | N39: 3600 | Q39: 3496 | S39: 4.5 | T39: + | U39: 1200 | V39: = | W39: =(S39*1000)+U39 -> 5700 | Y39: 1 | Z39: 4 | AA39: =CHOOSE(Y39,0,Z$36,Z$37,Z$38,Z$39,Z$40,Z$41,Z$42,Z$43,Z$44,Z$45) -> 0 | AB39: AHU 4 | AE39: 1 ton | AG39: 1 ton | AI39: 1 ton | AK39: 1 ton | AM39: 1 ton
E40: 21 | F40: + | G40: 2400 | H40: = | I40: =SUM((E40*1000)+G40) -> 23400 | M40: 3 ton | N40: 4275 | Q40: 4370 | S40: 10 | T40: + | U40: 1600 | V40: = | W40: =(S40*1000)+U40 -> 11600 | Y40: 1 | Z40: 5 | AA40: =CHOOSE(Y40,0,Z$36,Z$37,Z$38,Z$39,Z$40,Z$41,Z$42,Z$43,Z$44,Z$45) -> 0 | AB40: AHU 5 | AE40: 1.5 ton | AG40: 1.5 ton | AI40: 1.5 ton | AK40: 1.5 ton | AM40: 1.5 ton
E41: 23 | F41: + | G41: 2400 | H41: = | I41: =SUM((E41*1000)+G41) -> 25400 | M41: 3.5 ton | N41: 5000 | Q41: 5152 | S41: 6.5 | T41: + | U41: 1600 | V41: = | W41: =(S41*1000)+U41 -> 8100 | Z41: 6 | AE41: 2 ton | AG41: 2 ton | AI41: 2 ton | AK41: 2 ton | AM41: 2 ton
E42: 25 | F42: + | G42: 3600 | H42: = | I42: =SUM((E42*1000)+G42) -> 28600 | M42: 4 ton | N42: 5700 | Q42: 5313 | S42: 7.5 | T42: + | U42: 1600 | V42: = | W42: =(S42*1000)+U42 -> 9100 | Z42: 7 | AE42: 2.5 ton | AG42: 2.5 ton | AI42: 2.5 ton | AK42: 2.5 ton | AM42: 2.5 ton
E43: 29 | F43: + | G43: 3600 | H43: = | I43: =SUM((E43*1000)+G43) -> 32600 | M43: 5 ton | N43: 7130 | Q43: 6371 | T43: + | V43: = | W43: =(S43*1000)+U43 -> 0 | Z43: 8 | AE43: 3 ton | AG43: 3 ton | AI43: 3 ton | AK43: 3 ton | AM43: 3 ton
E44: GAS 1 | F44: + | G44: 1200 | H44: = | I44: =SUM(G44) -> 1200 | T44: + | V44: = | W44: =(S44*1000)+U44 -> 0 | Z44: 9 | AE44: 3.5 ton | AG44: 3.5 ton | AI44: 3.5 ton | AK44: 3.5 ton | AM44: 3.5 ton
E45: GAS 2 | F45: + | G45: 1800 | H45: = | I45: =SUM(G45) -> 1800 | T45: + | V45: = | W45: =(S45*1000)+U45 -> 0 | Z45: 10 | AE45: 4 ton | AG45: 4 ton | AI45: 4 ton | AK45: 4 ton | AM45: 4 ton
T46: + | V46: = | W46: =(S46*1000)+U46 -> 0 | AE46: 5 ton | AG46: 5 ton | AI46: 5 ton | AK46: 5 ton | AM46: 5 ton
T47: + | V47: = | W47: =(S47*1000)+U47 -> 0 | AE47: =M44 -> 0 | AG47: =$M$44 -> 0 | AI47: =$M$44 -> 0 | AK47: =$M$44 -> 0 | AM47: =$M$44 -> 0
S48: GAS 1 | T48: + | U48: 1200 | V48: = | W48: =(U48) -> 1200 | AE48: =M45 -> 0 | AG48: =$M$45 -> 0 | AI48: =$M$45 -> 0 | AK48: =$M$45 -> 0 | AM48: =$M$45 -> 0
...

Sheet Residential Calculation
E2: =IF(E121,"Residential Optional Calculation","Residential Standard Calculation") -> Residential Standard Calculation | J2: 35698 | L2: (Project Name) | V2: =IF(E121,"OPTIONAL","STANDARD") -> STANDARD | W2: =IF(R13,"A/C","HP") -> A/C
D4: =IF($E$121,"STEP 1 Article 220.82 (B) (1),(2)","STEP 1 Article 220.42 & 220.52") -> STEP 1 Article 220.42 & 220.52 | L4: ='User Info'!B6 -> Company Name | V4: standard | W4: optional | Y4: =IF(E121," optional","standard") -> standard
F5: General Lighting load | H5: =E5*F483 -> 0 | L5: ='User Info'!B9 -> Address | U5: ahu | V5: =W20+X20 -> #REF! | W5: =W24 -> #REF! | Y5: =IF($E$121,W5,V5) -> #REF! | Z5: =IF(R13,Y5,Y8) -> #REF!
F6: Small Appliance | H6: =1500*E6 -> 0 | L6: ='User Info'!B12 -> City, State, Zip Code | U6: cool | V6: =IF($V$20=0,0,SUM($V$20+$X$20)) -> 0 | W6: =IF($V$20=0,0,SUM($V$20+$X$20)) -> 0 | Y6: =IF($E$121,W6,V6) -> 0 | CL6: =CK6
F7: Laundry circuit | H7: =1500*E7 -> 0 | L7: ='User Info'!B15 -> Telephone & Fax
E8: Gen.Lgt, Sm App.& Laun. Load | H8: =SUM(H5:H7) -> 0 | L8: =NOW() -> 45736.723 | N8: ='User Info'!B18 | U8: ahu | V8: =SUM(W20+X20+V20) -> #REF! | W8: =W24+V20 -> #REF! | Y8: =IF($E$121,W8,V8) -> #REF!
H9: =IF($E$121," ",K549) -> 0 | I9: =IF($E$121," "," @ 100%=") -> @ 100%= | J9: =IF(E121," ",H9) -> 0 | U9: hp | V9: =IF($V$20=0,0,SUM($V$20+$X$20)) -> 0 | W9: =IF(V20=0,0,SUM(V20+X20)) -> 0 | Y9: =IF($E$121,W9,V9) -> 0
H10: =IF($E$121," ",K550) -> 0 | I10: =IF($E$121," "," @ 35% =") -> @ 35% = | J10: =IF(E121," ",M550) -> 0
H11: =IF($E$121," ",K551) -> 0 | I11: =IF($E$121," "," @ 25% =") -> @ 25% = | J11: =IF(E121," ",M551) -> 0
D12: =IF($E$121,"STEP 2 Article 220.82 (C)","STEP 2 Article 220.50 & 220.51") -> STEP 2 Article 220.50 & 220.51 | J12: =IF(E121,"General lighting, Sm. Appl. & Laundry","General Lighting Demand Load") -> General Lighting Demand Load | N12: =IF(E121,I553,N553) -> 0 | CK12: FALSE | CL12: FALSE | CM12: =OR(CK12,CL12) -> FALSE
D13: =IF(R13,"A/C Condenser & Fixed Electric Space Heating","Heat Pump w/ Concurrent Supplementary Heating") -> A/C Condenser & Fixed Electric Space Heating | I13: QTY | J13: =IF(E121,"Total"," ") | K13: =IF(E121,U19," ") | L13: =IF(E121,W22," ") | R13: TRUE | V13: CU / HP | W13: AHU 1 | X13: Blower
E14: ='equipment set-up sheet'!AE50 -> 0 | F14: AHU 1 | H14: ='equipment set-up sheet'!#REF! -> #REF! | J14: Heating Load | L14: =Z5 -> #REF! | U14: ='equipment set-up sheet'!AA36 -> 0 | V14: =SUM(E14*U14) -> 0 | W14: =SUM(H14*U14) -> #REF! | X14: =IF(R13,'equipment set-up sheet'!AF54*U14,'equipment set-up sheet'!AF55*U14) -> 0
E15: ='equipment set-up sheet'!AG50 -> 0 | F15: AHU 2 | H15: ='equipment set-up sheet'!#REF! -> #REF! | J15: =IF(R13," CU Load"," HP Load") -> CU Load | L15: =IF(R13,Y9,Y6) -> 0 | U15: ='equipment set-up sheet'!AA37 -> 0 | V15: =SUM(E15*U15) -> 0 | W15: =SUM(H15*U15) -> #REF! | X15: =IF(R13,'equipment set-up sheet'!AH54*U15,'equipment set-up sheet'!AH55*U15) -> 0
E16: ='equipment set-up sheet'!AI50 -> 0 | F16: AHU 3 | H16: ='equipment set-up sheet'!#REF! -> #REF! | U16: ='equipment set-up sheet'!AA38 -> 0 | V16: =SUM(E16*U16) -> 0 | W16: =SUM(H16*U16) -> #REF! | X16: =IF(R13,'equipment set-up sheet'!AJ54*U16,'equipment set-up sheet'!AJ55*U16) -> 0
E17: ='equipment set-up sheet'!AK50 -> 0 | F17: AHU 4 | H17: ='equipment set-up sheet'!#REF! -> #REF! | I17: =IF(E121," Electric Space Heat @ 65% <4, 40% >3, vs. A/C @ 100%"," Greater of Heat @ 100% vs.A/C @ 100%") -> Greater of Heat @ 100% vs.A/C @ 100% | N17: =IF(L14>L15,L14,L15) -> #REF! | U17: ='equipment set-up sheet'!AA39 -> 0 | V17: =SUM(E17*U17) -> 0 | W17: =SUM(H17*U17) -> #REF! | X17: =IF(R13,'equipment set-up sheet'!AL54*U17,'equipment set-up sheet'!AL55*U17) -> 0
E18: ='equipment set-up sheet'!AM50 -> 0 | F18: AHU 5 | H18: ='equipment set-up sheet'!#REF! -> #REF! | U18: ='equipment set-up sheet'!AA40 -> 0 | V18: =SUM(E18*U18) -> 0 | W18: =SUM(H18*U18) -> #REF! | X18: =IF(R13,'equipment set-up sheet'!AN54*U18,'equipment set-up sheet'!AN55*U18) -> 0
D19: =IF($E$121,"STEP 3 Article 220.82 (B) (3)","STEP 3 Article 220.53") -> STEP 3 Article 220.53 | K19: Appliance Demand Load | N19: =IF(E121,I555,N555) -> 0 | U19: =SUM(U14:U18) -> 0 | Z19: Art 220.82 ( C ) (4)
F20: ='equipment set-up sheet'!E6 -> Water Heater | H20: =E20*'equipment set-up sheet'!E5 -> 0 | V20: =SUM(V14:V18) -> 0 | W20: =SUM(W14:W18)-X20 -> #REF! | X20: =SUM(X14:X18) -> 0 | Y20: Heat Load | Z20: =SUM(V20+W20*V24) -> #REF! | AA20: Optional
F21: ='equipment set-up sheet'!G6 -> Refrigerator | H21: =$E21*'equipment set-up sheet'!G$5 -> 0 | K21: Dryer Demand Load | N21: =H42 -> 0 | Z21: HP + (AHU(t) X 65%)
F22: ='equipment set-up sheet'!I6 -> Freezer | H22: =$E22*'equipment set-up sheet'!I$5 -> 0 | V22: DEM FACTOR | W22: =IF(U19<=4,V24,V25) -> 0.65
F23: ='equipment set-up sheet'!K6 -> Dishwasher | H23: =$E23*'equipment set-up sheet'!K$5 -> 0 | K23: Range Demand Load | N23: =IF(E121=FALSE,E119,I557) -> 0 | W23: =SUM(W20*W22) -> #REF!
F24: ='equipment set-up sheet'!M6 -> Disposal | H24: =$E24*'equipment set-up sheet'!M$5 -> 0 | U24: <4 | V24: 0.65 | W24: =W23+X20 -> #REF!
F25: ='equipment set-up sheet'!M19 -> Range Hood | H25: =$E25*'equipment set-up sheet'!$M$18 -> 0 | K25: Service Demand | N25: =IF(E121,G120,L120) -> #REF! | U25: >3 | V25: 0.4
F26: ='equipment set-up sheet'!Q6 -> Microwave | H26: =$E26*'equipment set-up sheet'!Q$5 -> 0
F27: ='equipment set-up sheet'!E19 -> Central Vac | H27: =$E27*'equipment set-up sheet'!E$18 -> 0 | L27: ="Demand Load" -> Demand Load | M27: =IF(E120," @ 208V, 1ph"," @ 240V, 1ph") -> @ 208V, 1ph | N27: =IF(E121,I117,N118) -> #REF!
F28: ='equipment set-up sheet'!G19 -> Mini Refrig | H28: =$E28*'equipment set-up sheet'!G$18 -> 0
F29: ='equipment set-up sheet'!I19 -> Compactor | H29: =$E29*'equipment set-up sheet'!I$18 -> 0 | L29: Neutral Demand | N29: =IF($E$191>=4,SUM((((H21+H22+H23+H24+H25+H26+H28+H31+H191)*0.75)+N553+Q606)+(SUM($N$556+$N$559)*0.7))/J119,SUM((((H21+H22+H23+H24+H25+H26+H28+H31+H191)*1)+N553+Q606)+(SUM($N$556+$N$559)*0.7))/J119) -> 0
F30: Tankless heater | H30: =$E30*'equipment set-up sheet'!K$18 -> 0
F31: ='equipment set-up sheet'!Q19 -> Wine Cooler | H31: =$E31*'equipment set-up sheet'!Q$18 -> 0 | L31: =IF(Y147,"See Service Riser","Min.Service Req.") -> Min.Service Req. | N31: =IF(Y147," ",K117) -> #REF!
F32: Jacuzzi Tub | H32: =G584 -> 0
F33: Sprinkler | H33: =G585 -> 0
F34: Well Pump | H34: =G586 -> 0
F35: Fountain Pump | H35: =G587 -> 0
F36: Elevator | H36: =G588 -> 0
F37: Pool Equip. Panel | H37: =IF(E121,SUM(I56+I57+AE409+AE410+AE411+I61+I62+I63+I64+J56+J57+AH409+AH410+AH411+J61+J62+J63+J64),SUM(I56+I57+I58+I59+I60+I61+I62+I63+I64+J56+J57+J58+J59+J60+J61+J62+J63+J64)) -> 0 | I37: =IF($E$121,"Apply Demand","100% Demand") -> 100% Demand
F38: Other load | H38: =E38 -> 0 | I38: =IF(E131,"Apply Demand","No Demand") -> No Demand
F39: Other load | H39: =E39 -> 0 | I39: =IF(E132,"Apply Demand","No Demand") -> No Demand | K39: Total Appliance Load | M39: =SUM(H20:H39) -> 0
I40: =IF(E121," ","4 or more demand @ 75% plus 100% demand loads") -> 4 or more demand @ 75% plus 100% demand loads | N40: =IF(E121," ",O555) -> 0
E41: =IF($E$121,"STEP 4 Article 220.82 (B) (3)","STEP 4 Article 220.54") -> STEP 4 Article 220.54
E42: Electric Clothes Dryers
...

Sheet User Info
B5: Company Name
B6: Company Name
B8: Address
B9: Address
B11: City, State, Zip Code
B12: City, State, Zip Code
B14: Telephone & Fax
B15: Telephone & Fax
B17: Serial Number
