Workbook
Name DropDown434_Change: #REF!

Sheet 0

Sheet 00000

Sheet 2
G3: VOLTAGE DROP CALCULATION
A5: Serial No. | B5: CABLE ROUTE | D5: CABLE LENGTH (M) | E5: INSTALLATION | G5: CONNECTED LOAD (KVA) | H5: CURRENT DESIGNED (lb AMP) | I5: CIRCUIT BREAKER RATING (AMP) (150 % of lb) | J5: CIRCUIT BREAKER PROPOSED (AMP) Ic | K5: DERATING FACTORS | P5: CURRRENT CARRYING CAPACITY REQUIRED Ia = Ic T1 x T2 | Q5: CABLE CURRENT RATING (AMP) | R5: CABLE SIZE | S5: VOLTAGE DROP | U5: VOLTAGE REGULATION | V5: CABLE SIZE AS PER CONTRACT | W5: REMARKS
K6: DIRECT BURRIED | N6: IN AIR
B7: From | C7: To | E7: LOCATION (T2) | F7: TYPE (T1) | K7: Variation of depth (T1) | L7: Variation of Temp. (T2) | M7: Variation of Resistivity (T3) | N7: Grouping Factor (T1) | O7: Variation of Temp. (T2) | S7: vd mv/A/m | T7: VOLTAGE DROP (vd) | U7: % = vd x 100 Vs
A8: 1 | B8: SWGR-1 | C8: MDP1 | D8: 150 | E8: =VLOOKUP(Y8,'3'!A$95:B$98,2,FALSE) -> NO CEILING | F8: =VLOOKUP(X8,'3'!A$88:B$92,2,FALSE) -> CABLE TRAY | G8: 50 | H8: =(G8*1000)/(SQRT(3)*380) -> 75.967141 | I8: =H8*1.5 -> 113.95071 | J8: =VLOOKUP(AA$8,'1'!A$15:X$50,2,FALSE) -> 125 | N8: =VLOOKUP(X8,'3'!A$88:C$92,3,FALSE) -> 0.85 | O8: =VLOOKUP(Y8,'3'!A$95:C$98,3,FALSE) -> 0.96 | P8: =IF(J8<=0,"",J8/(N8*O8)) -> 153.18627 | Q8: =VLOOKUP(Z8,'3'!A$8:F$85,6,FALSE) -> 345 | R8: =VLOOKUP(Z8,'3'!A$8:F$85,2,FALSE) -> 4C-120mm2 Cu XLPE PVC CABLE | S8: =VLOOKUP(Z8,'3'!A$8:F$85,3,FALSE) -> 0.368 | T8: =(D8*H8*S8)/1000 -> 4.1933862 | U8: =(T8*100)/380 -> 1.1035227 | V8: 3(3.5-300mm2) | X8: 5 | Y8: 3 | Z8: 30 | AA8: 15
B9: MDP1 | C9: SMDP1 | D9: 0 | E9: =VLOOKUP(Y9,'3'!A$95:B$98,2,FALSE) -> OUTDOOR | F9: =VLOOKUP(X9,'3'!A$88:B$92,2,FALSE) -> PVC DUCT | G9: 0 | H9: =(G9*1000)/(SQRT(3)*380) -> 0 | I9: =H9*1.5 -> 0 | J9: =VLOOKUP(AA9,'1'!A$15:X$50,2,FALSE) -> 40 | N9: =VLOOKUP(X9,'3'!A$88:C$92,3,FALSE) -> 1 | O9: =VLOOKUP(Y9,'3'!A$95:C$98,3,FALSE) -> 0.82 | P9: =IF(J9<=0,"",J9/(N9*O9)) -> 48.780488 | Q9: =VLOOKUP(Z9,'3'!A$8:F$85,6,FALSE) -> 784 | R9: =VLOOKUP(Z9,'3'!A$8:F$85,2,FALSE) -> 2(3.5C-150mm2 Cu XLPE PVC CABLE) | S9: =VLOOKUP(Z9,'3'!A$8:F$85,3,FALSE) -> 0.1575 | T9: =(D9*H9*S9)/1000 -> 0 | U9: =(T9*100)/380 -> 0 | V9: 2(3.5-150mm2) | X9: 1 | Y9: 4 | Z9: 38 | AA9: 9
B10: SMDP1 | C10: PG1 | D10: 0 | E10: =VLOOKUP(Y10,'3'!A$95:B$98,2,FALSE) -> ABOVE CEILING | F10: =VLOOKUP(X10,'3'!A$88:B$92,2,FALSE) -> CABLE TRAY | G10: 0 | H10: =(G10*1000)/(SQRT(3)*380) -> 0 | I10: =H10*1.5 -> 0 | J10: =VLOOKUP(AA10,'1'!A$15:X$50,2,FALSE) -> 32 | N10: =VLOOKUP(X10,'3'!A$88:C$92,3,FALSE) -> 0.85 | O10: =VLOOKUP(Y10,'3'!A$95:C$98,3,FALSE) -> 0.91 | P10: =IF(J10<=0,"",J10/(N10*O10)) -> 41.370394 | Q10: =VLOOKUP(Z10,'3'!A$8:F$85,6,FALSE) -> 135 | R10: =VLOOKUP(Z10,'3'!A$8:F$85,2,FALSE) -> 4C-25mm2 Cu XLPE PVC CABLE | S10: =VLOOKUP(Z10,'3'!A$8:F$85,3,FALSE) -> 1.114 | T10: =(D10*H10*S10)/1000 -> 0 | U10: =(T10*100)/380 -> 0 | V10: 4C-25mm | X10: 5 | Y10: 2 | Z10: 15 | AA10: 8
B11: PG1 | C11: LOAD | D11: 0 | E11: =VLOOKUP(Y11,'3'!A$95:B$98,2,FALSE) -> ABOVE CEILING | F11: =VLOOKUP(X11,'3'!A$88:B$92,2,FALSE) -> CONDUIT | G11: 0 | H11: =(G11*1000)/(SQRT(3)*380) -> 0 | I11: =H11*1.5 -> 0 | J11: =VLOOKUP(AA11,'1'!A$15:X$50,2,FALSE) -> 32 | N11: =VLOOKUP(X11,'3'!A$88:C$92,3,FALSE) -> 1 | O11: =VLOOKUP(Y11,'3'!A$95:C$98,3,FALSE) -> 0.91 | P11: =IF(J11<=0,"",J11/(N11*O11)) -> 35.164835 | Q11: =VLOOKUP(Z11,'3'!A$8:F$85,6,FALSE) -> 49 | R11: =VLOOKUP(Z11,'3'!A$8:F$85,2,FALSE) -> 2C-4.0mm2 Cu PVC/PVC CABLE | S11: =VLOOKUP(Z11,'3'!A$8:F$85,3,FALSE) -> 8.624 | T11: =(D11*H11*S11)/1000 -> 0 | U11: =(T11*100)/380 -> 0 | W11: =SUM(U8:U11) -> 1.1035227 | X11: 4 | Y11: 2 | Z11: 3 | AA11: 8
A12: 2 | B12: SMDP1 | C12: PG6 | D12: 0 | E12: =VLOOKUP(Y12,'3'!A$95:B$98,2,FALSE) -> ABOVE CEILING | F12: =VLOOKUP(X12,'3'!A$88:B$92,2,FALSE) -> CABLE TRAY | G12: 0 | H12: =(G12*1000)/(SQRT(3)*380) -> 0 | I12: =H12*1.5 -> 0 | J12: =VLOOKUP(AA12,'1'!A$15:X$50,2,FALSE) -> 100 | N12: =VLOOKUP(X12,'3'!A$88:C$92,3,FALSE) -> 0.85 | O12: =VLOOKUP(Y12,'3'!A$95:C$98,3,FALSE) -> 0.91 | P12: =IF(J12<=0,"",J12/(N12*O12)) -> 129.28248 | Q12: =VLOOKUP(Z12,'3'!A$8:F$85,6,FALSE) -> 135 | R12: =VLOOKUP(Z12,'3'!A$8:F$85,2,FALSE) -> 4C-25mm2 Cu XLPE PVC CABLE | S12: =VLOOKUP(Z12,'3'!A$8:F$85,3,FALSE) -> 1.114 | T12: =(D12*H12*S12)/1000 -> 0 | U12: =(T12*100)/380 -> 0 | V12: 4C-25mm2 | X12: 5 | Y12: 2 | Z12: 15 | AA12: 13
B13: PG6 | C13: LOAD | D13: 0 | E13: =VLOOKUP(Y13,'3'!A$95:B$98,2,FALSE) -> ABOVE CEILING | F13: =VLOOKUP(X13,'3'!A$88:B$92,2,FALSE) -> CONDUIT | G13: 0 | H13: =(G13*1000)/(SQRT(3)*380) -> 0 | I13: =H13*1.5 -> 0 | J13: =VLOOKUP(AA13,'1'!A$15:X$50,2,FALSE) -> 25 | N13: =VLOOKUP(X13,'3'!A$88:C$92,3,FALSE) -> 1 | O13: =VLOOKUP(Y13,'3'!A$95:C$98,3,FALSE) -> 0.91 | P13: =IF(J13<=0,"",J13/(N13*O13)) -> 27.472527 | Q13: =VLOOKUP(Z13,'3'!A$8:F$85,6,FALSE) -> 49 | R13: =VLOOKUP(Z13,'3'!A$8:F$85,2,FALSE) -> 2C-4.0mm2 Cu PVC/PVC CABLE | S13: =VLOOKUP(Z13,'3'!A$8:F$85,3,FALSE) -> 8.624 | T13: =(D13*H13*S13)/1000 -> 0 | U13: =(T13*100)/380 -> 0 | X13: 4 | Y13: 2 | Z13: 3 | AA13: 7
A14: 3 | B14: SMDP1 | C14: PG7 | D14: 0 | E14: =VLOOKUP(Y14,'3'!A$95:B$98,2,FALSE) -> ABOVE CEILING | F14: =VLOOKUP(X14,'3'!A$88:B$92,2,FALSE) -> CABLE TRAY | G14: 0 | H14: =(G14*1000)/(SQRT(3)*380) -> 0 | I14: =H14*1.5 -> 0 | J14: =VLOOKUP(AA14,'1'!A$15:X$50,2,FALSE) -> 32 | N14: =VLOOKUP(X14,'3'!A$88:C$92,3,FALSE) -> 0.85 | O14: =VLOOKUP(Y14,'3'!A$95:C$98,3,FALSE) -> 0.91 | P14: =IF(J14<=0,"",J14/(N14*O14)) -> 41.370394 | Q14: =VLOOKUP(Z14,'3'!A$8:F$85,6,FALSE) -> 46 | R14: =VLOOKUP(Z14,'3'!A$8:F$85,2,FALSE) -> 4C-4.0mm2 Cu XLPE PVC CABLE | S14: =VLOOKUP(Z14,'3'!A$8:F$85,3,FALSE) -> 8.747 | T14: =(D14*H14*S14)/1000 -> 0 | U14: =(T14*100)/380 -> 0 | V14: 4C-4.0mm2 | X14: 5 | Y14: 2 | Z14: 11 | AA14: 8
B15: PG7 | C15: LOAD | D15: 0 | E15: =VLOOKUP(Y15,'3'!A$95:B$98,2,FALSE) -> ABOVE CEILING | F15: =VLOOKUP(X15,'3'!A$88:B$92,2,FALSE) -> CONDUIT | G15: 0 | H15: =(G15*1000)/(SQRT(3)*380) -> 0 | I15: =H15*1.5 -> 0 | J15: =VLOOKUP(AA15,'1'!A$15:X$50,2,FALSE) -> 25 | N15: =VLOOKUP(X15,'3'!A$88:C$92,3,FALSE) -> 1 | O15: =VLOOKUP(Y15,'3'!A$95:C$98,3,FALSE) -> 0.91 | P15: =IF(J15<=0,"",J15/(N15*O15)) -> 27.472527 | Q15: =VLOOKUP(Z15,'3'!A$8:F$85,6,FALSE) -> 49 | R15: =VLOOKUP(Z15,'3'!A$8:F$85,2,FALSE) -> 2C-4.0mm2 Cu PVC/PVC CABLE | S15: =VLOOKUP(Z15,'3'!A$8:F$85,3,FALSE) -> 8.624 | T15: =(D15*H15*S15)/1000 -> 0 | U15: =(T15*100)/380 -> 0 | X15: 4 | Y15: 2 | Z15: 3 | AA15: 7
B16: SMDP1 | C16: PG8 | D16: 0 | E16: =VLOOKUP(Y16,'3'!A$95:B$98,2,FALSE) -> ABOVE CEILING | F16: =VLOOKUP(X16,'3'!A$88:B$92,2,FALSE) -> CABLE TRAY | G16: 0 | H16: =(G16*1000)/(SQRT(3)*380) -> 0 | I16: =H16*1.5 -> 0 | J16: =VLOOKUP(AA16,'1'!A$15:X$50,2,FALSE) -> 25 | N16: =VLOOKUP(X16,'3'!A$88:C$92,3,FALSE) -> 0.85 | O16: =VLOOKUP(Y16,'3'!A$95:C$98,3,FALSE) -> 0.91 | P16: =IF(J16<=0,"",J16/(N16*O16)) -> 32.320621 | Q16: =VLOOKUP(Z16,'3'!A$8:F$85,6,FALSE) -> 135 | R16: =VLOOKUP(Z16,'3'!A$8:F$85,2,FALSE) -> 4C-25mm2 Cu XLPE PVC CABLE | S16: =VLOOKUP(Z16,'3'!A$8:F$85,3,FALSE) -> 1.114 | T16: =(D16*H16*S16)/1000 -> 0 | U16: =(T16*100)/380 -> 0 | V16: 4C-25mm2 | X16: 5 | Y16: 2 | Z16: 15 | AA16: 7
B17: PG8 | C17: LOAD | D17: 0 | E17: =VLOOKUP(Y17,'3'!A$95:B$98,2,FALSE) -> ABOVE CEILING | F17: =VLOOKUP(X17,'3'!A$88:B$92,2,FALSE) -> CONDUIT | G17: 0 | H17: =(G17*1000)/(SQRT(3)*380) -> 0 | I17: =H17*1.5 -> 0 | J17: =VLOOKUP(AA17,'1'!A$15:X$50,2,FALSE) -> 25 | N17: =VLOOKUP(X17,'3'!A$88:C$92,3,FALSE) -> 1 | O17: =VLOOKUP(Y17,'3'!A$95:C$98,3,FALSE) -> 0.91 | P17: =IF(J17<=0,"",J17/(N17*O17)) -> 27.472527 | Q17: =VLOOKUP(Z17,'3'!A$8:F$85,6,FALSE) -> 49 | R17: =VLOOKUP(Z17,'3'!A$8:F$85,2,FALSE) -> 2C-4.0mm2 Cu PVC/PVC CABLE | S17: =VLOOKUP(Z17,'3'!A$8:F$85,3,FALSE) -> 8.624 | T17: =(D17*H17*S17)/1000 -> 0 | U17: =(T17*100)/380 -> 0 | X17: 4 | Y17: 2 | Z17: 3 | AA17: 7
B18: SMDP1 | C18: PG9 | D18: 0 | E18: =VLOOKUP(Y18,'3'!A$95:B$98,2,FALSE) -> ABOVE CEILING | F18: =VLOOKUP(X18,'3'!A$88:B$92,2,FALSE) -> CABLE TRAY | G18: 0 | H18: =(G18*1000)/(SQRT(3)*380) -> 0 | I18: =H18*1.5 -> 0 | J18: =VLOOKUP(AA18,'1'!A$15:X$50,2,FALSE) -> 25 | N18: =VLOOKUP(X18,'3'!A$88:C$92,3,FALSE) -> 0.85 | O18: =VLOOKUP(Y18,'3'!A$95:C$98,3,FALSE) -> 0.91 | P18: =IF(J18<=0,"",J18/(N18*O18)) -> 32.320621 | Q18: =VLOOKUP(Z18,'3'!A$8:F$85,6,FALSE) -> 76 | R18: =VLOOKUP(Z18,'3'!A$8:F$85,2,FALSE) -> 4C-10mm2 Cu XLPE PVC CABLE | S18: =VLOOKUP(Z18,'3'!A$8:F$85,3,FALSE) -> 3.519 | T18: =(D18*H18*S18)/1000 -> 0 | U18: =(T18*100)/380 -> 0 | V18: 4C-10mm2 | X18: 5 | Y18: 2 | Z18: 13 | AA18: 7
B19: PG9 | C19: LOAD | D19: 0 | E19: =VLOOKUP(Y19,'3'!A$95:B$98,2,FALSE) -> ABOVE CEILING | F19: =VLOOKUP(X19,'3'!A$88:B$92,2,FALSE) -> CONDUIT | G19: 0 | H19: =(G19*1000)/(SQRT(3)*380) -> 0 | I19: =H19*1.5 -> 0 | J19: =VLOOKUP(AA19,'1'!A$15:X$50,2,FALSE) -> 25 | N19: =VLOOKUP(X19,'3'!A$88:C$92,3,FALSE) -> 1 | O19: =VLOOKUP(Y19,'3'!A$95:C$98,3,FALSE) -> 0.91 | P19: =IF(J19<=0,"",J19/(N19*O19)) -> 27.472527 | Q19: =VLOOKUP(Z19,'3'!A$8:F$85,6,FALSE) -> 49 | R19: =VLOOKUP(Z19,'3'!A$8:F$85,2,FALSE) -> 2C-4.0mm2 Cu PVC/PVC CABLE | S19: =VLOOKUP(Z19,'3'!A$8:F$85,3,FALSE) -> 8.624 | T19: =(D19*H19*S19)/1000 -> 0 | U19: =(T19*100)/380 -> 0 | X19: 4 | Y19: 2 | Z19: 3 | AA19: 7
B20: SMDP1 | C20: PG10 | D20: 0 | E20: =VLOOKUP(Y20,'3'!A$95:B$98,2,FALSE) -> ABOVE CEILING | F20: =VLOOKUP(X20,'3'!A$88:B$92,2,FALSE) -> CABLE TRAY | G20: 0 | H20: =(G20*1000)/(SQRT(3)*380) -> 0 | I20: =H20*1.5 -> 0 | J20: =VLOOKUP(AA20,'1'!A$15:X$50,2,FALSE) -> 25 | N20: =VLOOKUP(X20,'3'!A$88:C$92,3,FALSE) -> 0.85 | O20: =VLOOKUP(Y20,'3'!A$95:C$98,3,FALSE) -> 0.91 | P20: =IF(J20<=0,"",J20/(N20*O20)) -> 32.320621 | Q20: =VLOOKUP(Z20,'3'!A$8:F$85,6,FALSE) -> 135 | R20: =VLOOKUP(Z20,'3'!A$8:F$85,2,FALSE) -> 4C-25mm2 Cu XLPE PVC CABLE | S20: =VLOOKUP(Z20,'3'!A$8:F$85,3,FALSE) -> 1.114 | T20: =(D20*H20*S20)/1000 -> 0 | U20: =(T20*100)/380 -> 0 | V20: 4C-25mm2 | X20: 5 | Y20: 2 | Z20: 15 | AA20: 7
B21: PG10 | C21: LOAD | D21: 0 | E21: =VLOOKUP(Y21,'3'!A$95:B$98,2,FALSE) -> ABOVE CEILING | F21: =VLOOKUP(X21,'3'!A$88:B$92,2,FALSE) -> CONDUIT | G21: 0 | H21: =(G21*1000)/(SQRT(3)*380) -> 0 | I21: =H21*1.5 -> 0 | J21: =VLOOKUP(AA21,'1'!A$15:X$50,2,FALSE) -> 25 | N21: =VLOOKUP(X21,'3'!A$88:C$92,3,FALSE) -> 1 | O21: =VLOOKUP(Y21,'3'!A$95:C$98,3,FALSE) -> 0.91 | P21: =IF(J21<=0,"",J21/(N21*O21)) -> 27.472527 | Q21: =VLOOKUP(Z21,'3'!A$8:F$85,6,FALSE) -> 49 | R21: =VLOOKUP(Z21,'3'!A$8:F$85,2,FALSE) -> 2C-4.0mm2 Cu PVC/PVC CABLE | S21: =VLOOKUP(Z21,'3'!A$8:F$85,3,FALSE) -> 8.624 | T21: =(D21*H21*S21)/1000 -> 0 | U21: =(T21*100)/380 -> 0 | X21: 4 | Y21: 2 | Z21: 3 | AA21: 7
B22: SMDP1 | C22: PG11 | D22: 0 | E22: =VLOOKUP(Y22,'3'!A$95:B$98,2,FALSE) -> ABOVE CEILING | F22: =VLOOKUP(X22,'3'!A$88:B$92,2,FALSE) -> CABLE TRAY | G22: 0 | H22: =(G22*1000)/(SQRT(3)*380) -> 0 | I22: =H22*1.5 -> 0 | J22: =VLOOKUP(AA22,'1'!A$15:X$50,2,FALSE) -> 40 | N22: =VLOOKUP(X22,'3'!A$88:C$92,3,FALSE) -> 0.85 | O22: =VLOOKUP(Y22,'3'!A$95:C$98,3,FALSE) -> 0.91 | P22: =IF(J22<=0,"",J22/(N22*O22)) -> 51.712993 | Q22: =VLOOKUP(Z22,'3'!A$8:F$85,6,FALSE) -> 135 | R22: =VLOOKUP(Z22,'3'!A$8:F$85,2,FALSE) -> 4C-25mm2 Cu XLPE PVC CABLE | S22: =VLOOKUP(Z22,'3'!A$8:F$85,3,FALSE) -> 1.114 | T22: =(D22*H22*S22)/1000 -> 0 | U22: =(T22*100)/380 -> 0 | V22: 4C-25mm2 | X22: 5 | Y22: 2 | Z22: 15 | AA22: 9
B23: PG11 | C23: LOAD | D23: 0 | E23: =VLOOKUP(Y23,'3'!A$95:B$98,2,FALSE) -> ABOVE CEILING | F23: =VLOOKUP(X23,'3'!A$88:B$92,2,FALSE) -> CONDUIT | G23: 0 | H23: =(G23*1000)/(SQRT(3)*380) -> 0 | I23: =H23*1.5 -> 0 | J23: =VLOOKUP(AA23,'1'!A$15:X$50,2,FALSE) -> 40 | N23: =VLOOKUP(X23,'3'!A$88:C$92,3,FALSE) -> 1 | O23: =VLOOKUP(Y23,'3'!A$95:C$98,3,FALSE) -> 0.91 | P23: =IF(J23<=0,"",J23/(N23*O23)) -> 43.956044 | Q23: =VLOOKUP(Z23,'3'!A$8:F$85,6,FALSE) -> 49 | R23: =VLOOKUP(Z23,'3'!A$8:F$85,2,FALSE) -> 2C-4.0mm2 Cu PVC/PVC CABLE | S23: =VLOOKUP(Z23,'3'!A$8:F$85,3,FALSE) -> 8.624 | T23: =(D23*H23*S23)/1000 -> 0 | U23: =(T23*100)/380 -> 0 | X23: 4 | Y23: 2 | Z23: 3 | AA23: 9
B24: SMDP1 | C24: X-RAY | D24: 0 | E24: =VLOOKUP(Y24,'3'!A$95:B$98,2,FALSE) -> ABOVE CEILING | F24: =VLOOKUP(X24,'3'!A$88:B$92,2,FALSE) -> CABLE TRAY | G24: 0 | H24: =(G24*1000)/(SQRT(3)*380) -> 0 | I24: =H24*1.5 -> 0 | J24: =VLOOKUP(AA24,'1'!A$15:X$50,2,FALSE) -> 40 | N24: =VLOOKUP(X24,'3'!A$88:C$92,3,FALSE) -> 0.85 | O24: =VLOOKUP(Y24,'3'!A$95:C$98,3,FALSE) -> 0.91 | P24: =IF(J24<=0,"",J24/(N24*O24)) -> 51.712993 | Q24: =VLOOKUP(Z24,'3'!A$8:F$85,6,FALSE) -> 135 | R24: =VLOOKUP(Z24,'3'!A$8:F$85,2,FALSE) -> 4C-25mm2 Cu XLPE PVC CABLE | S24: =VLOOKUP(Z24,'3'!A$8:F$85,3,FALSE) -> 1.114 | T24: =(D24*H24*S24)/1000 -> 0 | U24: =(T24*100)/380 -> 0 | V24: 4C-25mm2 | X24: 5 | Y24: 2 | Z24: 15 | AA24: 9
B25: MDP1 | C25: SMDP2 | D25: 0 | E25: =VLOOKUP(Y25,'3'!A$95:B$98,2,FALSE) -> ABOVE CEILING | F25: =VLOOKUP(X25,'3'!A$88:B$92,2,FALSE) -> CABLE TRAY | G25: 0 | H25: =(G25*1000)/(SQRT(3)*380) -> 0 | I25: =H25*1.5 -> 0 | J25: =VLOOKUP(AA25,'1'!A$15:X$50,2,FALSE) -> 40 | N25: =VLOOKUP(X25,'3'!A$88:C$92,3,FALSE) -> 0.85 | O25: =VLOOKUP(Y25,'3'!A$95:C$98,3,FALSE) -> 0.91 | P25: =IF(J25<=0,"",J25/(N25*O25)) -> 51.712993 | Q25: =VLOOKUP(Z25,'3'!A$8:F$85,6,FALSE) -> 240 | R25: =VLOOKUP(Z25,'3'!A$8:F$85,2,FALSE) -> 4C-70mm2 Cu XLPE PVC CABLE | S25: =VLOOKUP(Z25,'3'!A$8:F$85,3,FALSE) -> 0.585 | T25: =(D25*H25*S25)/1000 -> 0 | U25: =(T25*100)/380 -> 0 | V25: 4C-70mm2 | X25: 5 | Y25: 2 | Z25: 28 | AA25: 9
B26: SMDP2 | C26: PF2 | D26: 0 | E26: =VLOOKUP(Y26,'3'!A$95:B$98,2,FALSE) -> ABOVE CEILING | F26: =VLOOKUP(X26,'3'!A$88:B$92,2,FALSE) -> CABLE TRAY | G26: 0 | H26: =(G26*1000)/(SQRT(3)*380) -> 0 | I26: =H26*1.5 -> 0 | J26: =VLOOKUP(AA26,'1'!A$15:X$50,2,FALSE) -> 40 | N26: =VLOOKUP(X26,'3'!A$88:C$92,3,FALSE) -> 0.85 | O26: =VLOOKUP(Y26,'3'!A$95:C$98,3,FALSE) -> 0.91 | P26: =IF(J26<=0,"",J26/(N26*O26)) -> 51.712993 | Q26: =VLOOKUP(Z26,'3'!A$8:F$85,6,FALSE) -> 76 | R26: =VLOOKUP(Z26,'3'!A$8:F$85,2,FALSE) -> 4C-10mm2 Cu XLPE PVC CABLE | S26: =VLOOKUP(Z26,'3'!A$8:F$85,3,FALSE) -> 3.519 | T26: =(D26*H26*S26)/1000 -> 0 | U26: =(T26*100)/380 -> 0 | V26: 4C-10mm2 | X26: 5 | Y26: 2 | Z26: 13 | AA26: 9
B27: PF2 | C27: LOAD | D27: 0 | E27: =VLOOKUP(Y27,'3'!A$95:B$98,2,FALSE) -> ABOVE CEILING | F27: =VLOOKUP(X27,'3'!A$88:B$92,2,FALSE) -> CONDUIT | G27: 0 | H27: =(G27*1000)/(SQRT(3)*380) -> 0 | I27: =H27*1.5 -> 0 | J27: =VLOOKUP(AA27,'1'!A$15:X$50,2,FALSE) -> 40 | N27: =VLOOKUP(X27,'3'!A$88:C$92,3,FALSE) -> 1 | O27: =VLOOKUP(Y27,'3'!A$95:C$98,3,FALSE) -> 0.91 | P27: =IF(J27<=0,"",J27/(N27*O27)) -> 43.956044 | Q27: =VLOOKUP(Z27,'3'!A$8:F$85,6,FALSE) -> 49 | R27: =VLOOKUP(Z27,'3'!A$8:F$85,2,FALSE) -> 2C-4.0mm2 Cu PVC/PVC CABLE | S27: =VLOOKUP(Z27,'3'!A$8:F$85,3,FALSE) -> 8.624 | T27: =(D27*H27*S27)/1000 -> 0 | U27: =(T27*100)/380 -> 0 | X27: 4 | Y27: 2 | Z27: 3 | AA27: 9
B28: SMDP2 | C28: PF3 | D28: 0 | E28: =VLOOKUP(Y28,'3'!A$95:B$98,2,FALSE) -> ABOVE CEILING | F28: =VLOOKUP(X28,'3'!A$88:B$92,2,FALSE) -> CABLE TRAY | G28: 0 | H28: =(G28*1000)/(SQRT(3)*380) -> 0 | I28: =H28*1.5 -> 0 | J28: =VLOOKUP(AA28,'1'!A$15:X$50,2,FALSE) -> 40 | N28: =VLOOKUP(X28,'3'!A$88:C$92,3,FALSE) -> 0.85 | O28: =VLOOKUP(Y28,'3'!A$95:C$98,3,FALSE) -> 0.91 | P28: =IF(J28<=0,"",J28/(N28*O28)) -> 51.712993 | Q28: =VLOOKUP(Z28,'3'!A$8:F$85,6,FALSE) -> 76 | R28: =VLOOKUP(Z28,'3'!A$8:F$85,2,FALSE) -> 4C-10mm2 Cu XLPE PVC CABLE | S28: =VLOOKUP(Z28,'3'!A$8:F$85,3,FALSE) -> 3.519 | T28: =(D28*H28*S28)/1000 -> 0 | U28: =(T28*100)/380 -> 0 | V28: 4C-10mm2 | X28: 5 | Y28: 2 | Z28: 13 | AA28: 9
B29: PF3 | C29: LOAD | D29: 0 | E29: =VLOOKUP(Y29,'3'!A$95:B$98,2,FALSE) -> ABOVE CEILING | F29: =VLOOKUP(X29,'3'!A$88:B$92,2,FALSE) -> CONDUIT | G29: 0 | H29: =(G29*1000)/(SQRT(3)*380) -> 0 | I29: =H29*1.5 -> 0 | J29: =VLOOKUP(AA29,'1'!A$15:X$50,2,FALSE) -> 40 | N29: =VLOOKUP(X29,'3'!A$88:C$92,3,FALSE) -> 1 | O29: =VLOOKUP(Y29,'3'!A$95:C$98,3,FALSE) -> 0.91 | P29: =IF(J29<=0,"",J29/(N29*O29)) -> 43.956044 | Q29: =VLOOKUP(Z29,'3'!A$8:F$85,6,FALSE) -> 49 | R29: =VLOOKUP(Z29,'3'!A$8:F$85,2,FALSE) -> 2C-4.0mm2 Cu PVC/PVC CABLE | S29: =VLOOKUP(Z29,'3'!A$8:F$85,3,FALSE) -> 8.624 | T29: =(D29*H29*S29)/1000 -> 0 | U29: =(T29*100)/380 -> 0 | X29: 4 | Y29: 2 | Z29: 3 | AA29: 9
B30: SMDP2 | C30: PR | D30: 0 | E30: =VLOOKUP(Y30,'3'!A$95:B$98,2,FALSE) -> ABOVE CEILING | F30: =VLOOKUP(X30,'3'!A$88:B$92,2,FALSE) -> CABLE TRAY | G30: 0 | H30: =(G30*1000)/(SQRT(3)*380) -> 0 | I30: =H30*1.5 -> 0 | J30: =VLOOKUP(AA30,'1'!A$15:X$50,2,FALSE) -> 40 | N30: =VLOOKUP(X30,'3'!A$88:C$92,3,FALSE) -> 0.85 | O30: =VLOOKUP(Y30,'3'!A$95:C$98,3,FALSE) -> 0.91 | P30: =IF(J30<=0,"",J30/(N30*O30)) -> 51.712993 | Q30: =VLOOKUP(Z30,'3'!A$8:F$85,6,FALSE) -> 76 | R30: =VLOOKUP(Z30,'3'!A$8:F$85,2,FALSE) -> 4C-10mm2 Cu XLPE PVC CABLE | S30: =VLOOKUP(Z30,'3'!A$8:F$85,3,FALSE) -> 3.519 | T30: =(D30*H30*S30)/1000 -> 0 | U30: =(T30*100)/380 -> 0 | V30: 4C-10mm2 | X30: 5 | Y30: 2 | Z30: 13 | AA30: 9
B31: PR | C31: LOAD | D31: 0 | E31: =VLOOKUP(Y31,'3'!A$95:B$98,2,FALSE) -> OUTDOOR | F31: =VLOOKUP(X31,'3'!A$88:B$92,2,FALSE) -> CONDUIT | G31: 0 | H31: =(G31*1000)/(SQRT(3)*380) -> 0 | I31: =H31*1.5 -> 0 | J31: =VLOOKUP(AA31,'1'!A$15:X$50,2,FALSE) -> 40 | N31: =VLOOKUP(X31,'3'!A$88:C$92,3,FALSE) -> 1 | O31: =VLOOKUP(Y31,'3'!A$95:C$98,3,FALSE) -> 0.82 | P31: =IF(J31<=0,"",J31/(N31*O31)) -> 48.780488 | Q31: =VLOOKUP(Z31,'3'!A$8:F$85,6,FALSE) -> 49 | R31: =VLOOKUP(Z31,'3'!A$8:F$85,2,FALSE) -> 2C-4.0mm2 Cu PVC/PVC CABLE | S31: =VLOOKUP(Z31,'3'!A$8:F$85,3,FALSE) -> 8.624 | T31: =(D31*H31*S31)/1000 -> 0 | U31: =(T31*100)/380 -> 0 | X31: 4 | Y31: 4 | Z31: 3 | AA31: 9
B32: MDP1 | C32: GHOUSE | D32: 0 | E32: =VLOOKUP(Y32,'3'!A$95:B$98,2,FALSE) -> OUTDOOR | F32: =VLOOKUP(X32,'3'!A$88:B$92,2,FALSE) -> PVC DUCT | G32: 0 | H32: =(G32*1000)/(SQRT(3)*380) -> 0 | I32: =H32*1.5 -> 0 | J32: =VLOOKUP(AA32,'1'!A$15:X$50,2,FALSE) -> 40 | N32: =VLOOKUP(X32,'3'!A$88:C$92,3,FALSE) -> 1 | O32: =VLOOKUP(Y32,'3'!A$95:C$98,3,FALSE) -> 0.82 | P32: =IF(J32<=0,"",J32/(N32*O32)) -> 48.780488 | Q32: =VLOOKUP(Z32,'3'!A$8:F$85,6,FALSE) -> 56 | R32: =VLOOKUP(Z32,'3'!A$8:F$85,2,FALSE) -> 4C-6.0mm2 Cu XLPE PVC CABLE | S32: =VLOOKUP(Z32,'3'!A$8:F$85,3,FALSE) -> 5.871 | T32: =(D32*H32*S32)/1000 -> 0 | U32: =(T32*100)/380 -> 0 | V32: 4C-6mm2 | X32: 1 | Y32: 4 | Z32: 12 | AA32: 9
B33: GHOUSE | C33: LOAD | D33: 0 | E33: =VLOOKUP(Y33,'3'!A$95:B$98,2,FALSE) -> NO CEILING | F33: =VLOOKUP(X33,'3'!A$88:B$92,2,FALSE) -> CONDUIT | G33: 0 | H33: =(G33*1000)/(SQRT(3)*380) -> 0 | I33: =H33*1.5 -> 0 | J33: =VLOOKUP(AA33,'1'!A$15:X$50,2,FALSE) -> 40 | N33: =VLOOKUP(X33,'3'!A$88:C$92,3,FALSE) -> 1 | O33: =VLOOKUP(Y33,'3'!A$95:C$98,3,FALSE) -> 0.96 | P33: =IF(J33<=0,"",J33/(N33*O33)) -> 41.666667 | Q33: =VLOOKUP(Z33,'3'!A$8:F$85,6,FALSE) -> 49 | R33: =VLOOKUP(Z33,'3'!A$8:F$85,2,FALSE) -> 2C-4.0mm2 Cu PVC/PVC CABLE | S33: =VLOOKUP(Z33,'3'!A$8:F$85,3,FALSE) -> 8.624 | T33: =(D33*H33*S33)/1000 -> 0 | U33: =(T33*100)/380 -> 0 | X33: 4 | Y33: 3 | Z33: 3 | AA33: 9
B34: MDP1 | C34: KIDNEY | D34: 0 | E34: =VLOOKUP(Y34,'3'!A$95:B$98,2,FALSE) -> OUTDOOR | F34: =VLOOKUP(X34,'3'!A$88:B$92,2,FALSE) -> PVC DUCT | G34: 0 | H34: =(G34*1000)/(SQRT(3)*380) -> 0 | I34: =H34*1.5 -> 0 | J34: =VLOOKUP(AA34,'1'!A$15:X$50,2,FALSE) -> 40 | N34: =VLOOKUP(X34,'3'!A$88:C$92,3,FALSE) -> 1 | O34: =VLOOKUP(Y34,'3'!A$95:C$98,3,FALSE) -> 0.82 | P34: =IF(J34<=0,"",J34/(N34*O34)) -> 48.780488 | Q34: =VLOOKUP(Z34,'3'!A$8:F$85,6,FALSE) -> 690 | R34: =VLOOKUP(Z34,'3'!A$8:F$85,2,FALSE) -> 2(4C-120mm2 Cu XLPE PVC CABLE) | S34: =VLOOKUP(Z34,'3'!A$8:F$85,3,FALSE) -> 0.184 | T34: =(D34*H34*S34)/1000 -> 0 | U34: =(T34*100)/380 -> 0 | V34: 2(4C-120mm2) | X34: 1 | Y34: 4 | Z34: 58 | AA34: 9
B35: MDP1 | C35: NSTAFF | D35: 0 | E35: =VLOOKUP(Y35,'3'!A$95:B$98,2,FALSE) -> OUTDOOR | F35: =VLOOKUP(X35,'3'!A$88:B$92,2,FALSE) -> PVC DUCT | G35: 0 | H35: =(G35*1000)/(SQRT(3)*380) -> 0 | I35: =H35*1.5 -> 0 | J35: =VLOOKUP(AA35,'1'!A$15:X$50,2,FALSE) -> 40 | N35: =VLOOKUP(X35,'3'!A$88:C$92,3,FALSE) -> 1 | O35: =VLOOKUP(Y35,'3'!A$95:C$98,3,FALSE) -> 0.82 | P35: =IF(J35<=0,"",J35/(N35*O35)) -> 48.780488 | Q35: =VLOOKUP(Z35,'3'!A$8:F$85,6,FALSE) -> 538 | R35: =VLOOKUP(Z35,'3'!A$8:F$85,2,FALSE) -> 4C-240mm2 Cu XLPE PVC CABLE | S35: =VLOOKUP(Z35,'3'!A$8:F$85,3,FALSE) -> 0.226 | T35: =(D35*H35*S35)/1000 -> 0 | U35: =(T35*100)/380 -> 0 | V35: 4C-240mm2 | X35: 1 | Y35: 4 | Z35: 33 | AA35: 9
B36: MDP1 | C36: PA-ANC | D36: 0 | E36: =VLOOKUP(Y36,'3'!A$95:B$98,2,FALSE) -> NO CEILING | F36: =VLOOKUP(X36,'3'!A$88:B$92,2,FALSE) -> CABLE TRAY | G36: 0 | H36: =(G36*1000)/(SQRT(3)*380) -> 0 | I36: =H36*1.5 -> 0 | J36: =VLOOKUP(AA36,'1'!A$15:X$50,2,FALSE) -> 40 | N36: =VLOOKUP(X36,'3'!A$88:C$92,3,FALSE) -> 0.85 | O36: =VLOOKUP(Y36,'3'!A$95:C$98,3,FALSE) -> 0.96 | P36: =IF(J36<=0,"",J36/(N36*O36)) -> 49.019608 | Q36: =VLOOKUP(Z36,'3'!A$8:F$85,6,FALSE) -> 99 | R36: =VLOOKUP(Z36,'3'!A$8:F$85,2,FALSE) -> 4C-16mm2 Cu XLPE PVC CABLE | S36: =VLOOKUP(Z36,'3'!A$8:F$85,3,FALSE) -> 2.239 | T36: =(D36*H36*S36)/1000 -> 0 | U36: =(T36*100)/380 -> 0 | V36: 4C-16mm2 | X36: 5 | Y36: 3 | Z36: 14 | AA36: 9
B37: SW1 | C37: MDPAC1 | D37: 0 | E37: =VLOOKUP(Y37,'3'!A$95:B$98,2,FALSE) -> NO CEILING | F37: =VLOOKUP(X37,'3'!A$88:B$92,2,FALSE) -> CABLE TRAY | G37: 0 | H37: =(G37*1000)/(SQRT(3)*380) -> 0 | I37: =H37*1.5 -> 0 | J37: =VLOOKUP(AA37,'1'!A$15:X$50,2,FALSE) -> 40 | N37: =VLOOKUP(X37,'3'!A$88:C$92,3,FALSE) -> 0.85 | O37: =VLOOKUP(Y37,'3'!A$95:C$98,3,FALSE) -> 0.96 | P37: =IF(J37<=0,"",J37/(N37*O37)) -> 49.019608 | Q37: =VLOOKUP(Z37,'3'!A$8:F$85,6,FALSE) -> 1878 | R37: =VLOOKUP(Z37,'3'!A$8:F$85,2,FALSE) -> 3(3.5C-300mm2 Cu XLPE PVC CABLE) | S37: =VLOOKUP(Z37,'3'!A$8:F$85,3,FALSE) -> 0.066 | T37: =(D37*H37*S37)/1000 -> 0 | U37: =(T37*100)/380 -> 0 | V37: 3(3.5C-300mm2) | X37: 5 | Y37: 3 | Z37: 48 | AA37: 9
B38: MDPAC1 | C38: SMDPAC1 | D38: 0 | E38: =VLOOKUP(Y38,'3'!A$95:B$98,2,FALSE) -> OUTDOOR | F38: =VLOOKUP(X38,'3'!A$88:B$92,2,FALSE) -> PVC DUCT | G38: 0 | H38: =(G38*1000)/(SQRT(3)*380) -> 0 | I38: =H38*1.5 -> 0 | J38: =VLOOKUP(AA38,'1'!A$15:X$50,2,FALSE) -> 40 | N38: =VLOOKUP(X38,'3'!A$88:C$92,3,FALSE) -> 1 | O38: =VLOOKUP(Y38,'3'!A$95:C$98,3,FALSE) -> 0.82 | P38: =IF(J38<=0,"",J38/(N38*O38)) -> 48.780488 | Q38: =VLOOKUP(Z38,'3'!A$8:F$85,6,FALSE) -> 440 | R38: =VLOOKUP(Z38,'3'!A$8:F$85,2,FALSE) -> 3.5C-185mm2 Cu XLPE PVC CABLE | S38: =VLOOKUP(Z38,'3'!A$8:F$85,3,FALSE) -> 0.27 | T38: =(D38*H38*S38)/1000 -> 0 | U38: =(T38*100)/380 -> 0 | V38: 3.5C-185mm2 | X38: 1 | Y38: 4 | Z38: 22 | AA38: 9
B39: SMDPAC1 | C39: PGAC1 | D39: 0 | E39: =VLOOKUP(Y39,'3'!A$95:B$98,2,FALSE) -> ABOVE CEILING | F39: =VLOOKUP(X39,'3'!A$88:B$92,2,FALSE) -> CABLE TRAY | G39: 0 | H39: =(G39*1000)/(SQRT(3)*380) -> 0 | I39: =H39*1.5 -> 0 | J39: =VLOOKUP(AA39,'1'!A$15:X$50,2,FALSE) -> 40 | N39: =VLOOKUP(X39,'3'!A$88:C$92,3,FALSE) -> 0.85 | O39: =VLOOKUP(Y39,'3'!A$95:C$98,3,FALSE) -> 0.91 | P39: =IF(J39<=0,"",J39/(N39*O39)) -> 51.712993 | Q39: =VLOOKUP(Z39,'3'!A$8:F$85,6,FALSE) -> 135 | R39: =VLOOKUP(Z39,'3'!A$8:F$85,2,FALSE) -> 4C-25mm2 Cu XLPE PVC CABLE | S39: =VLOOKUP(Z39,'3'!A$8:F$85,3,FALSE) -> 1.114 | T39: =(D39*H39*S39)/1000 -> 0 | U39: =(T39*100)/380 -> 0 | V39: 4C-25mm2 | X39: 5 | Y39: 2 | Z39: 15 | AA39: 9
B40: PGAC1 | C40: LOAD | D40: 0 | E40: =VLOOKUP(Y40,'3'!A$95:B$98,2,FALSE) -> ABOVE CEILING | F40: =VLOOKUP(X40,'3'!A$88:B$92,2,FALSE) -> CONDUIT | G40: 0 | H40: =(G40*1000)/(SQRT(3)*380) -> 0 | I40: =H40*1.5 -> 0 | J40: =VLOOKUP(AA40,'1'!A$15:X$50,2,FALSE) -> 40 | N40: =VLOOKUP(X40,'3'!A$88:C$92,3,FALSE) -> 1 | O40: =VLOOKUP(Y40,'3'!A$95:C$98,3,FALSE) -> 0.91 | P40: =IF(J40<=0,"",J40/(N40*O40)) -> 43.956044 | Q40: =VLOOKUP(Z40,'3'!A$8:F$85,6,FALSE) -> 49 | R40: =VLOOKUP(Z40,'3'!A$8:F$85,2,FALSE) -> 2C-4.0mm2 Cu PVC/PVC CABLE | S40: =VLOOKUP(Z40,'3'!A$8:F$85,3,FALSE) -> 8.624 | T40: =(D40*H40*S40)/1000 -> 0 | U40: =(T40*100)/380 -> 0 | X40: 4 | Y40: 2 | Z40: 3 | AA40: 9
B41: SMDPAC1 | C41: KITCHEN | D41: 0 | E41: =VLOOKUP(Y41,'3'!A$95:B$98,2,FALSE) -> ABOVE CEILING | F41: =VLOOKUP(X41,'3'!A$88:B$92,2,FALSE) -> CABLE TRAY | G41: 0 | H41: =(G41*1000)/(SQRT(3)*380) -> 0 | I41: =H41*1.5 -> 0 | J41: =VLOOKUP(AA41,'1'!A$15:X$50,2,FALSE) -> 40 | N41: =VLOOKUP(X41,'3'!A$88:C$92,3,FALSE) -> 0.85 | O41: =VLOOKUP(Y41,'3'!A$95:C$98,3,FALSE) -> 0.91 | P41: =IF(J41<=0,"",J41/(N41*O41)) -> 51.712993 | Q41: =VLOOKUP(Z41,'3'!A$8:F$85,6,FALSE) -> 298 | R41: =VLOOKUP(Z41,'3'!A$8:F$85,2,FALSE) -> 3.5C-95mm2 Cu XLPE PVC CABLE | S41: =VLOOKUP(Z41,'3'!A$8:F$85,3,FALSE) -> 0.444 | T41: =(D41*H41*S41)/1000 -> 0 | U41: =(T41*100)/380 -> 0 | V41: 3.5C-95mm2 | X41: 5 | Y41: 2 | Z41: 19 | AA41: 9
B42: SMDPAC1 | C42: STRELI | D42: 0 | E42: =VLOOKUP(Y42,'3'!A$95:B$98,2,FALSE) -> ABOVE CEILING | F42: =VLOOKUP(X42,'3'!A$88:B$92,2,FALSE) -> CABLE TRAY | G42: 0 | H42: =(G42*1000)/(SQRT(3)*380) -> 0 | I42: =H42*1.5 -> 0 | J42: =VLOOKUP(AA42,'1'!A$15:X$50,2,FALSE) -> 40 | N42: =VLOOKUP(X42,'3'!A$88:C$92,3,FALSE) -> 0.85 | O42: =VLOOKUP(Y42,'3'!A$95:C$98,3,FALSE) -> 0.91 | P42: =IF(J42<=0,"",J42/(N42*O42)) -> 51.712993 | Q42: =VLOOKUP(Z42,'3'!A$8:F$85,6,FALSE) -> 240 | R42: =VLOOKUP(Z42,'3'!A$8:F$85,2,FALSE) -> 4C-70mm2 Cu XLPE PVC CABLE | S42: =VLOOKUP(Z42,'3'!A$8:F$85,3,FALSE) -> 0.585 | T42: =(D42*H42*S42)/1000 -> 0 | U42: =(T42*100)/380 -> 0 | V42: 4C-70mm2 | X42: 5 | Y42: 2 | Z42: 28 | AA42: 9
B43: SMDPAC1 | C43: PGAC2 | D43: 0 | E43: =VLOOKUP(Y43,'3'!A$95:B$98,2,FALSE) -> ABOVE CEILING | F43: =VLOOKUP(X43,'3'!A$88:B$92,2,FALSE) -> CABLE TRAY | G43: 0 | H43: =(G43*1000)/(SQRT(3)*380) -> 0 | I43: =H43*1.5 -> 0 | J43: =VLOOKUP(AA43,'1'!A$15:X$50,2,FALSE) -> 40 | N43: =VLOOKUP(X43,'3'!A$88:C$92,3,FALSE) -> 0.85 | O43: =VLOOKUP(Y43,'3'!A$95:C$98,3,FALSE) -> 0.91 | P43: =IF(J43<=0,"",J43/(N43*O43)) -> 51.712993 | Q43: =VLOOKUP(Z43,'3'!A$8:F$85,6,FALSE) -> 135 | R43: =VLOOKUP(Z43,'3'!A$8:F$85,2,FALSE) -> 4C-25mm2 Cu XLPE PVC CABLE | S43: =VLOOKUP(Z43,'3'!A$8:F$85,3,FALSE) -> 1.114 | T43: =(D43*H43*S43)/1000 -> 0 | U43: =(T43*100)/380 -> 0 | V43: 4C-25mm2 | X43: 5 | Y43: 2 | Z43: 15 | AA43: 9
...

Sheet 1
B2: STANDARD CIRCUIT BREAKER RATING
B4: BREAKER (AT) | C4: BREAKER (AF) | D4: TYPE | E4: BREAKER (AF) | F4: TYPE | G4: BREAKER (AF) | H4: TYPE | I4: BREAKER (AF) | J4: TYPE | K4: BREAKER (AF) | L4: TYPE | M4: BREAKER (AF) | N4: TYPE | O4: BREAKER (AF) | P4: TYPE | Q4: BREAKER (AF) | R4: TYPE | S4: WIRE & CABLE | U4: GROUND | W4: REMARKS
S5: mm2 | T5: AWG | U5: mm2 | V5: AWG
B6: 0.5 | C6: 63 | D6: MCB
B7: 0.75 | C7: 63 | D7: MCB
B8: 1 | C8: 63 | D8: MCB
B9: 2 | C9: 63 | D9: MCB
B10: 2.5 | E10: 100 | F10: MCCB | G10: 160 | H10: MCCB | I10: 250 | J10: MCCB
B11: 3 | C11: 63 | D11: MCB
B12: 4 | C12: 63 | D12: MCB
B13: 6 | C13: 63 | D13: MCB
B14: 6.3 | E14: 100 | F14: MCCB | G14: 160 | H14: MCCB | I14: 250 | J14: MCCB
A15: 1 | B15: 10 | C15: 63 | D15: MCB | E15: 100 | F15: MCCB | G15: 160 | H15: MCCB | I15: 250 | J15: MCCB
A16: 2 | B16: 12.5 | E16: 100 | F16: MCCB | G16: 160 | H16: MCCB | I16: 250 | J16: MCCB
A17: 3 | B17: 13 | C17: 63 | D17: MCB
A18: 4 | B18: 15 | C18: 63 | D18: MCB | S18: 2.5 | T18: 14 | U18: 2.5 | V18: 14 | W18: BRANCH CIRCUIT
A19: 5 | B19: 16 | C19: 63 | D19: MCB | E19: 100 | F19: MCCB | G19: 160 | H19: MCCB | I19: 250 | J19: MCCB | S19: 2.5 | T19: 14 | U19: 2.5 | V19: 14 | W19: BRANCH CIRCUIT
A20: 6 | B20: 20 | C20: 63 | D20: MCB | E20: 100 | F20: MCCB | G20: 160 | H20: MCCB | I20: 250 | J20: MCCB | S20: 4 | T20: 12 | U20: 4 | V20: 12 | W20: BRANCH CIRCUIT
A21: 7 | B21: 25 | C21: 63 | D21: MCB | E21: 100 | F21: MCCB | G21: 160 | H21: MCCB | I21: 250 | J21: MCCB | S21: 4 | T21: 12 | U21: 4 | V21: 12 | W21: BRANCH CIRCUIT
A22: 8 | B22: 32 | C22: 63 | D22: MCB | E22: 100 | F22: MCCB | G22: 160 | H22: MCCB | I22: 250 | J22: MCCB | S22: 6 | T22: 10 | U22: 6 | V22: 10 | W22: BRANCH CIRCUIT
A23: 9 | B23: 40 | C23: 63 | D23: MCB | E23: 100 | F23: MCCB | G23: 160 | H23: MCCB | I23: 250 | J23: MCCB | S23: 10 | T23: 8 | U23: 6 | V23: 10 | W23: BRANCH CIRCUIT
A24: 10 | B24: 50 | C24: 63 | D24: MCB | E24: 100 | F24: MCCB | G24: 160 | H24: MCCB | I24: 250 | J24: MCCB | S24: 16 | T24: 6 | U24: 6 | V24: 10 | W24: BRANCH CIRCUIT
A25: 11 | B25: 63 | C25: 63 | D25: MCB | E25: 100 | F25: MCCB | G25: 160 | H25: MCCB | I25: 250 | J25: MCCB | U25: 6 | V25: 10
A26: 12 | B26: 80 | E26: 100 | F26: MCCB | G26: 160 | H26: MCCB | I26: 250 | J26: MCCB | U26: 6 | V26: 10 | X26: 80 / 100
A27: 13 | B27: 100 | E27: 100 | F27: MCCB | G27: 160 | H27: MCCB | I27: 250 | J27: MCCB | U27: 6 | V27: 10 | X27: 100 / 100
A28: 14 | B28: 120 | K28: 400 | L28: MCCB | U28: 10 | V28: 8 | X28: 120 / 120
A29: 15 | B29: 125 | G29: 160 | H29: MCCB | I29: 250 | J29: MCCB | U29: 10 | V29: 8 | X29: 125 / 160
A30: 16 | B30: 150 | G30: 160 | H30: MCCB | I30: 250 | J30: MCCB | K30: 400 | L30: MCCB | U30: 10 | V30: 8 | X30: 150 / 160
A31: 17 | B31: 160 | G31: 160 | H31: MCCB | I31: 250 | J31: MCCB | U31: 10 | V31: 8 | X31: 160 / 160
A32: 18 | B32: 200 | I32: 250 | J32: MCCB | K32: 400 | L32: MCCB | U32: 16 | V32: 6 | X32: 200 / 250
A33: 19 | B33: 220 | I33: 250 | J33: MCCB | U33: 16 | V33: 6 | X33: 220 / 250
A34: 20 | B34: 250 | I34: 250 | J34: MCCB | K34: 400 | L34: MCCB | U34: 16 | V34: 6 | X34: 250 / 250
A35: 21 | B35: 300 | U35: 25 | V35: 4 | X35: 300 / 300
A36: 22 | B36: 320 | K36: 400 | L36: MCCB | U36: 35 | V36: 3 | X36: 320 / 400
A37: 23 | B37: 400 | K37: 400 | L37: MCCB | U37: 50 | V37: 1 | X37: 400 / 400
A38: 24 | B38: 500 | M38: 630 | N38: MCCB | U38: 70 | V38: 1 | X38: 500 / 630
A39: 25 | B39: 630 | M39: 630 | N39: MCCB | O39: 630 | P39: MCCB | Q39: 630 | R39: ACB | U39: 95 | V39: 3 | X39: 630 / 630
A40: 26 | B40: 800 | O40: 800 | P40: MCCB | Q40: 800 | R40: ACB | U40: 95 | V40: 3 | X40: 800 / 800
A41: 27 | B41: 1000 | O41: 1000 | P41: MCCB | Q41: 1000 | R41: ACB | U41: 95 | V41: 3 | X41: 1000 / 1000
A42: 28 | B42: 1200 | Q42: 1200 | R42: ACB | U42: 95 | V42: 3 | X42: 1200 / 1200
...

Sheet 3
A3: CABLE SIZING CALCULATION
A5: Serial No. | B5: DESCRIPTION | C5: VOLTAGE DROP (Mv/Amp/meter) | D5: AMPACITY
D7: IN GROUND | E7: IN DUCT | F7: IN AIR
A8: 1 | B8: 2C-1.5mm2 Cu PVC/PVC CABLE | C8: 22.476 | D8: 33 | E8: 27 | F8: 27
A9: 2 | B9: 2C-2.5mm2 Cu PVC/PVC CABLE | C9: 13.8 | D9: 41 | E9: 35 | F9: 35
A10: 3 | B10: 2C-4.0mm2 Cu PVC/PVC CABLE | C10: 8.624 | D10: 55 | E10: 45 | F10: 49
A11: 4 | B11: 2C-6.0mm2 Cu PVC/PVC CABLE | C11: 5.791 | D11: 68 | E11: 56 | F11: 63
A12: 5 | B12: 2C-10mm2 Cu PVC/PVC CABLE | C12: 3.474 | D12: 89 | E12: 77 | F12: 84
A13: 6 | B13: 2C-16mm2 Cu PVC/PVC CABLE | C13: 2.212 | D13: 116 | E13: 91 | F13: 112
A14: 7 | B14: 2C-25mm2 Cu PVC/PVC CABLE | C14: 1.43 | D14: 150 | E14: 119 | F14: 147
A15: 8 | B15: 2C-35mm2 Cu PVC/PVC CABLE | C15: 1.053 | D15: 177 | E15: 147 | F15: 182
A16: 9 | B16: 4C-1.5mm2 Cu XLPE PVC CABLE | C16: 22.82 | D16: 30 | E16: 27 | F16: 25
A17: 10 | B17: 4C-2.5mm2 Cu XLPE PVC CABLE | C17: 14.01 | D17: 40 | E17: 34 | F17: 36
A18: 11 | B18: 4C-4.0mm2 Cu XLPE PVC CABLE | C18: 8.747 | D18: 51 | E18: 42 | F18: 46
A19: 12 | B19: 4C-6.0mm2 Cu XLPE PVC CABLE | C19: 5.871 | D19: 65 | E19: 53 | F19: 56
... A85: 78 | B85: 4(4C-500mm2 Cu XLPE PVC CABLE) | C85: 0.0395 | D85: 2872 | E85: 2480 | F85: 3276
B87: GROUPING FACTOR
A88: 1 | B88: PVC DUCT | C88: 1
A89: 2 | B89: PVC DUCT(2Ckt.) | C89: 0.81
A90: 3 | B90: PVC DUCT(More) | C90: 0.7
A91: 4 | B91: CONDUIT | C91: 1
A92: 5 | B92: CABLE TRAY | C92: 0.85
B94: TEMPERATURE FACTOR
A95: 1 | B95: TUNNEL | C95: 0.87
A96: 2 | B96: ABOVE CEILING | C96: 0.91
A97: 3 | B97: NO CEILING | C97: 0.96
A98: 4 | B98: OUTDOOR | C98: 0.82
