Workbook

Sheet 2X16
A1: BILL OF MATERIAL
A2: PV MODULE MOUNTING SYSTEM (GROUND MOUNT 2X16 TABLE)
A3: FLASYS DESIGN
B4: PROJECT:
B5: ADDRESS:
B6: TOTAL CAPACITY: | C6: 400.4kWp | D6: MODULE (Wp): | E6: 325
B7: TILT: | C7: 25 DEGREE | D7: TABLE: | E7: 11 Nos
A8: STRUCTURE MEMBERS
A9: S.NO. | B9: DESCRIPTION | C9: SIZE(MM) | D9: LENGTH(MM) | E9: MATERIAL | F9: QUANTITY/TABLE | G9: TOTAL QUANTITY | H9: Weight/Meter or per piece (kg/m) | I9: Total weight
A10: 1 | B10: RAFTER | C10: C120X60X20X3.15 | D10: 3235 | E10: HOT DIP GALVANISED STEEL | F10: 6 | G10: =F10*11 -> 66 | H10: 6.92 | I10: =((H10*D10)/1000)*G10 -> 1477.4892
A11: 2 | B11: COLUMN | C11: C120X60X20X3.15 | D11: 2912 | E11: HOT DIP GALVANISED STEEL | F11: 6 | G11: =F11*11 -> 66 | H11: 6.92 | I11: =((H11*D11)/1000)*G11 -> 1329.9686
A12: 3 | B12: PURLIN 1 | C12: C80X40X15X2 | D12: 5550 | E12: HOT DIP GALVANISED STEEL | F12: 4 | G12: =F12*11 -> 44 | H12: 4.7 | I12: =((H12*D12)/1000)*G12 -> 1147.74
A13: 4 | B13: PURLIN 2 | C13: C80X40X15X2 | D13: 5050 | E13: HOT DIP GALVANISED STEEL | F13: 4 | G13: =F13*11 -> 44 | H13: 4.7 | I13: =((H13*D13)/1000)*G13 -> 1044.34
A14: 5 | B14: PURLIN 3 | C14: C80X40X15X2 | D14: 5550 | E14: HOT DIP GALVANISED STEEL | F14: 4 | G14: =F14*11 -> 44 | H14: 4.7 | I14: =((H14*D14)/1000)*G14 -> 1147.74
A15: 6 | B15: BRACING-1 | C15: ISA-50X50X4 | D15: 1314 | E15: HOT DIP GALVANISED STEEL | F15: 6 | G15: =F15*11 -> 66 | H15: 3.14 | I15: =((H15*D15)/1000)*G15 -> 272.31336
A16: 7 | B16: BRACING-2 | C16: ISA-50X50X4 | D16: 3043 | E16: HOT DIP GALVANISED STEEL | F16: 4 | G16: =F16*11 -> 44 | H16: 3.14 | I16: =((H16*D16)/1000)*G16 -> 420.42088
A17: 8 | B17: BRACING CONNECTOR | C17: PL-150X100X4 | D17: 150 | E17: HOT DIP GALVANISED STEEL | F17: 6 | G17: =F17*11 -> 66 | H17: 0.471 | I17: =H17*G17 -> 31.086
A18: 9 | B18: L-ANGLE CONNECTOR | C18: L-85X85X4 | D18: 85 | E18: HOT DIP GALVANISED STEEL | F18: 24 | G18: =F18*11 -> 264 | H18: 0.23 | I18: =H18*G18 -> 60.72
A19: 11 | B19: PURLIN CONNECTOR | C19: PL-150X65X3 | D19: 150 | E19: HOT DIP GALVANISED STEEL | F19: 8 | G19: =F19*11 -> 88 | H19: 0.23 | I19: =H19*G19 -> 20.24
I20: =SUM(I10:I19) -> 6952.0581
A21: FASTENERS /CLAMPS
A22: S.NO. | B22: DESCRIPTION | C22: SIZE(MM) | D22: LENGTH(MM) | E22: MATERIAL | F22: QUANTITY/TABLE | G22: TOTAL QUANTITY
A23: 1 | B23: HEX BOLT FOR MODULE | C23: M6 | E23: SS-304 | F23: 128 | G23: =F23*11 -> 1408
A24: 2 | B24: HEX NUT FOR MODULE | C24: M6 | E24: SS-304 | F24: 128 | G24: =F24*11 -> 1408
A25: 3 | B25: PLAIN WASHER | C25: M6 | E25: SS-304 | F25: 128 | G25: =F25*11 -> 1408
A26: 4 | B26: SPRING WASHER | C26: M6 | E26: SS-304 | F26: 128 | G26: =F26*11 -> 1408
A27: 5 | B27: HEX BOLT FOR COLUMN TO RAFTER CONNECTION | C27: M10 | E27: SS-304 | F27: 24 | G27: =F27*11 -> 264
A28: 6 | B28: HEX NUT FOR COLUMN TO RAFTER CONNECTION | C28: M10 | E28: SS-304 | F28: 24 | G28: =F28*11 -> 264
A29: 7 | B29: PLAIN WASHER | C29: M10 | E29: SS-304 | F29: 24 | G29: =F29*11 -> 264
A30: 8 | B30: HEX BOLT FOR L-CONNECTOR CONNECTION | C30: M10 | E30: SS-304 | F30: 48 | G30: =F30*11 -> 528
A31: 9 | B31: HEX NUT FOR L-CONNECTOR CONNECTION | C31: M10 | E31: SS-304 | F31: 48 | G31: =F31*11 -> 528
A32: 10 | B32: SPRING WASHER | C32: M10 | E32: SS-304 | F32: 48 | G32: =F32*11 -> 528
A33: 11 | B33: PLAIN WASHER | C33: M10 | E33: SS-304 | F33: 48 | G33: =F33*11 -> 528
A34: 12 | B34: HEX BOLT FOR BRACING CONNECTION | C34: M12 | E34: SS-304 | F34: 24 | G34: =F34*11 -> 264
... A40: 18 | B40: SPRING WASHER | C40: M10 | E40: SS-304 | F40: 64 | G40: =F40*11 -> 704
A41: 19 | B41: SAG ROD (NUT & WASHER) | C41: M10 | D41: 1120 | E41: SS-304 | F41: 5 | G41: =F41*11 -> 55
A42: 20 | B42: HEX BOLT FOR BRACING-2 CONNECTION | C42: M10 | E42: SS-304 | F42: 8 | G42: =F42*11 -> 88
A43: 21 | B43: HEX NUT FOR BRACING-2 CONNECTION | C43: M10 | E43: SS-304 | F43: 8 | G43: =F43*11 -> 88
A44: 22 | B44: PLAIN WASHER | C44: M10 | E44: SS-304 | F44: 8 | G44: =F44*11 -> 88

Sheet 2X15
A1: BILL OF MATERIAL
A2: PV MODULE MOUNTING SYSTEM (GROUND MOUNT 2X15 TABLE)
A3: FLASYS DESIGN
B4: PROJECT:
B5: ADDRESS:
B6: TOTAL CAPACITY: | C6: 400.4kWp | D6: MODULE (Wp): | E6: 325
B7: TILT: | C7: 25 DEGREE | D7: TABLE: | E7: 24 Nos (30 Modules/Table)
A8: STRUCTURE MEMBERS
A9: S.NO. | B9: DESCRIPTION | C9: SIZE(MM) | D9: LENGTH(MM) | E9: MATERIAL | F9: QUANTITY/TABLE | G9: TOTAL QUANTITY | H9: Weight/Meter or per piece (kg/m) | I9: Total weight
A10: 1 | B10: RAFTER | C10: C120X50X15X2 | D10: 3235 | E10: HOT DIP GALVANISED STEEL | F10: 6 | G10: =F10*24 -> 144 | H10: 3.92 | I10: =((H10*D10)/1000)*G10 -> 1826.0928
A11: 2 | B11: COLUMN | C11: C120X60X20X3.15 | D11: 1912 | E11: HOT DIP GALVANISED STEEL | F11: 6 | G11: =F11*24 -> 144 | H11: 6.6 | I11: =((H11*D11)/1000)*G11 -> 1817.1648
A12: 3 | B12: PURLIN 1 | C12: C80X40X15X2 | D12: 5550 | E12: HOT DIP GALVANISED STEEL | F12: 4 | G12: =F12*24 -> 96 | H12: 4.7 | I12: =((H12*D12)/1000)*G12 -> 2504.16
A13: 4 | B13: PURLIN 2 | C13: C80X40X15X2 | D13: 5045 | E13: HOT DIP GALVANISED STEEL | F13: 4 | G13: =F13*24 -> 96 | H13: 4.7 | I13: =((H13*D13)/1000)*G13 -> 2276.304
A14: 5 | B14: PURLIN 3 | C14: C80X40X15X2 | D14: 5550 | E14: HOT DIP GALVANISED STEEL | F14: 4 | G14: =F14*24 -> 96 | H14: 4.7 | I14: =((H14*D14)/1000)*G14 -> 2504.16
A15: 6 | B15: BRACING-1 | C15: ISA-50X50X4 | D15: 1314 | E15: HOT DIP GALVANISED STEEL | F15: 6 | G15: =F15*24 -> 144 | H15: 3.14 | I15: =((H15*D15)/1000)*G15 -> 594.13824
A16: 7 | B16: BRACING-2 | C16: ISA-50X50X4 | D16: 3043 | E16: HOT DIP GALVANISED STEEL | F16: 4 | G16: =F16*24 -> 96 | H16: 3.14 | I16: =((H16*D16)/1000)*G16 -> 917.28192
A17: 8 | B17: BRACING CONNECTOR | C17: PL-150X100X4 | D17: 150 | E17: HOT DIP GALVANISED STEEL | F17: 6 | G17: =F17*24 -> 144 | H17: 0.471 | I17: =H17*G17 -> 67.824
A18: 9 | B18: L-ANGLE CONNECTOR | C18: L-85X85X4 | D18: 85 | E18: HOT DIP GALVANISED STEEL | F18: 24 | G18: =F18*24 -> 576 | H18: 0.23 | I18: =H18*G18 -> 132.48
A19: 11 | B19: PURLIN CONNECTOR | C19: PL-150X65X3 | D19: 150 | E19: HOT DIP GALVANISED STEEL | F19: 8 | G19: =F19*24 -> 192 | H19: 0.23 | I19: =H19*G19 -> 44.16
I20: =SUM(I10:I19) -> 12683.766
A21: FASTENERS /CLAMPS
A22: S.NO. | B22: DESCRIPTION | C22: SIZE(MM) | D22: LENGTH(MM) | E22: MATERIAL | F22: QUANTITY/TABLE | G22: TOTAL QUANTITY
A23: 1 | B23: HEX BOLT FOR MODULE | C23: M6 | E23: SS-304 | F23: 120 | G23: =F23*24 -> 2880 | H23: 10 | I23: =H23*G23 -> 28800
A24: 2 | B24: HEX NUT FOR MODULE | C24: M6 | E24: SS-304 | F24: 120 | G24: =F24*24 -> 2880
A25: 3 | B25: PLAIN WASHER | C25: M6 | E25: SS-304 | F25: 120 | G25: =F25*24 -> 2880
A26: 4 | B26: SPRING WASHER | C26: M6 | E26: SS-304 | F26: 120 | G26: =F26*24 -> 2880
A27: 5 | B27: HEX BOLT FOR COLUMN TO RAFTER CONNECTION | C27: M10 | E27: SS-304 | F27: 24 | G27: =F27*24 -> 576 | H27: 11 | I27: =H27*G27 -> 6336
A28: 6 | B28: HEX NUT FOR COLUMN TO RAFTER CONNECTION | C28: M10 | E28: SS-304 | F28: 24 | G28: =F28*24 -> 576
A29: 7 | B29: PLAIN WASHER | C29: M10 | E29: SS-304 | F29: 24 | G29: =F29*24 -> 576
A30: 8 | B30: HEX BOLT FOR L-CONNECTOR CONNECTION | C30: M10 | E30: SS-304 | F30: 48 | G30: =F30*24 -> 1152 | H30: 11 | I30: =H30*G30 -> 12672
A31: 9 | B31: HEX NUT FOR L-CONNECTOR CONNECTION | C31: M10 | E31: SS-304 | F31: 48 | G31: =F31*24 -> 1152
A32: 10 | B32: SPRING WASHER | C32: M10 | E32: SS-304 | F32: 48 | G32: =F32*24 -> 1152
A33: 11 | B33: PLAIN WASHER | C33: M10 | E33: SS-304 | F33: 48 | G33: =F33*24 -> 1152
A34: 12 | B34: HEX BOLT FOR BRACING CONNECTION | C34: M12 | E34: SS-304 | F34: 24 | G34: =F34*24 -> 576 | H34: 28 | I34: =H34*G34 -> 16128
A35: 13 | B35: HEX NUT FOR BRACING CONNECTION | C35: M12 | E35: SS-304 | F35: 24 | G35: =F35*24 -> 576
A36: 14 | B36: PLAIN WASHER | C36: M12 | E36: SS-304 | F36: 24 | G36: =F36*24 -> 576
A37: 15 | B37: HEX BOLT FOR PURLIN CONNECTION | C37: M10 | E37: SS-304 | F37: 64 | G37: =F37*24 -> 1536 | H37: 11 | I37: =H37*G37 -> 16896
A38: 16 | B38: HEX NUT FOR PURLIN CONNECTION | C38: M10 | E38: SS-304 | F38: 64 | G38: =F38*24 -> 1536
A39: 17 | B39: PLAIN WASHER | C39: M10 | E39: SS-304 | F39: 64 | G39: =F39*24 -> 1536
A40: 18 | B40: SPRING WASHER | C40: M10 | E40: SS-304 | F40: 64 | G40: =F40*24 -> 1536
...

Sheet 2X8
A1: BILL OF MATERIAL
A2: PV MODULE MOUNTING SYSTEM (GROUND MOUNT 2X8 TABLE)
A3: FLASYS DESIGN
B4: PROJECT:
B5: ADDRESS:
B6: TOTAL CAPACITY: | C6: 400.4kWp | D6: MODULE (Wp): | E6: 325
B7: TILT: | C7: 25 DEGREE | D7: TABLE: | E7: 10 Nos
A8: STRUCTURE MEMBERS
A9: S.NO. | B9: DESCRIPTION | C9: SIZE(MM) | D9: LENGTH(MM) | E9: MATERIAL | F9: QUANTITY/TABLE | G9: TOTAL QUANTITY | H9: Weight/Meter or per piece (kg/m) | I9: Total weight
A10: 1 | B10: RAFTER | C10: C120X60X20X3.15 | D10: 3235 | E10: HOT DIP GALVANISED STEEL | F10: 3 | G10: =F10*10 -> 30 | H10: 6.92 | I10: =((H10*D10)/1000)*G10 -> 671.586
A11: 2 | B11: COLUMN | C11: C120X60X20X3.15 | D11: 2912 | E11: HOT DIP GALVANISED STEEL | F11: 3 | G11: =F11*10 -> 30 | H11: 6.92 | I11: =((H11*D11)/1000)*G11 -> 604.5312
A12: 3 | B12: PURLIN 1 | C12: C80X40X15X2 | D12: 4500 | E12: HOT DIP GALVANISED STEEL | F12: 4 | G12: =F12*10 -> 40 | H12: 4.7 | I12: =((H12*D12)/1000)*G12 -> 846
A13: 4 | B13: PURLIN 2 | C13: C80X40X15X2 | D13: 3575 | E13: HOT DIP GALVANISED STEEL | F13: 4 | G13: =F13*10 -> 40 | H13: 4.7 | I13: =((H13*D13)/1000)*G13 -> 672.1
A14: 6 | B14: BRACING-1 | C14: ISA-50X50X4 | D14: 1314 | E14: HOT DIP GALVANISED STEEL | F14: 3 | G14: =F14*10 -> 30 | H14: 3.14 | I14: =((H14*D14)/1000)*G14 -> 123.7788
A15: 7 | B15: BRACING-2 | C15: ISA-50X50X4 | D15: 3043 | E15: HOT DIP GALVANISED STEEL | F15: 2 | G15: =F15*10 -> 20 | H15: 3.14 | I15: =((H15*D15)/1000)*G15 -> 191.1004
A16: 8 | B16: BRACING CONNECTOR | C16: PL-150X100X4 | D16: 150 | E16: HOT DIP GALVANISED STEEL | F16: 3 | G16: =F16*10 -> 30 | H16: 0.471 | I16: =H16*G16 -> 14.13
A17: 9 | B17: L-ANGLE CONNECTOR | C17: L-85X85X4 | D17: 85 | E17: HOT DIP GALVANISED STEEL | F17: 4 | G17: =F17*10 -> 40 | H17: 0.23 | I17: =H17*G17 -> 9.2
A18: 10 | B18: PURLIN CONNECTOR | C18: PL-150X65X3 | D18: 150 | E18: HOT DIP GALVANISED STEEL | F18: 4 | G18: =F18*10 -> 40 | H18: 0.23 | I18: =H18*G18 -> 9.2 | K18: 6952
I19: =SUM(I10:I18) -> 3141.6264 | K19: 15165
A20: FASTENERS /CLAMPS | K20: 3142
A21: S.NO. | B21: DESCRIPTION | C21: SIZE(MM) | D21: LENGTH(MM) | E21: MATERIAL | F21: QUANTITY/TABLE | G21: TOTAL QUANTITY
A22: 1 | B22: HEX BOLT FOR MODULE | C22: M6 | E22: SS-304 | F22: 64 | G22: =F22*10 -> 640 | K22: =SUM(K18:K20) -> 25259
A23: 2 | B23: HEX NUT FOR MODULE | C23: M6 | E23: SS-304 | F23: 64 | G23: =F23*10 -> 640
A24: 3 | B24: PLAIN WASHER | C24: M6 | E24: SS-304 | F24: 64 | G24: =F24*10 -> 640
A25: 4 | B25: SPRING WASHER | C25: M6 | E25: SS-304 | F25: 64 | G25: =F25*10 -> 640
A26: 5 | B26: HEX BOLT FOR COLUMN TO RAFTER CONNECTION | C26: M10 | E26: SS-304 | F26: 12 | G26: =F26*10 -> 120
A27: 6 | B27: HEX NUT FOR COLUMN TO RAFTER CONNECTION | C27: M10 | E27: SS-304 | F27: 12 | G27: =F27*10 -> 120
A28: 7 | B28: PLAIN WASHER | C28: M10 | E28: SS-304 | F28: 12 | G28: =F28*10 -> 120
A29: 8 | B29: HEX BOLT FOR L-CONNECTOR CONNECTION | C29: M10 | E29: SS-304 | F29: 8 | G29: =F29*10 -> 80
A30: 9 | B30: HEX NUT FOR L-CONNECTOR CONNECTION | C30: M10 | E30: SS-304 | F30: 8 | G30: =F30*10 -> 80
A31: 10 | B31: SPRING WASHER | C31: M10 | E31: SS-304 | F31: 8 | G31: =F31*10 -> 80
A32: 11 | B32: PLAIN WASHER | C32: M10 | E32: SS-304 | F32: 8 | G32: =F32*10 -> 80
A33: 12 | B33: HEX BOLT FOR BRACING-1 CONNECTION | C33: M12 | E33: SS-304 | F33: 12 | G33: =F33*10 -> 120
A34: 13 | B34: HEX NUT FOR BRACING-1 CONNECTION | C34: M12 | E34: SS-304 | F34: 12 | G34: =F34*10 -> 120
... A39: 18 | B39: SPRING WASHER | C39: M10 | E39: SS-304 | F39: 32 | G39: =F39*10 -> 320
A40: 19 | B40: SAG ROD (NUT & WASHER) | C40: M10 | D40: 1120 | E40: SS-304 | F40: 2 | G40: =F40*10 -> 20
A41: 20 | B41: HEX BOLT FOR BRACING-2 CONNECTION | C41: M10 | E41: SS-304 | F41: 4 | G41: =F41*10 -> 40
A42: 21 | B42: HEX NUT FOR BRACING-2 CONNECTION | C42: M10 | E42: SS-304 | F42: 4 | G42: =F42*10 -> 40
A43: 22 | B43: PLAIN WASHER | C43: M10 | E43: SS-304 | F43: 4 | G43: =F43*10 -> 40

Sheet OTHER
A1: BILL OF MATERIAL
A2: PV MODULE MOUNTING SYSTEM (GROUND MOUNT)
A3: FLASYS DESIGN
B4: PROJECT:
B5: ADDRESS:
B6: TOTAL CAPACITY: | C6: 400.4kWp | D6: MODULE (Wp): | E6: 325
B7: TILT: | C7: 25 DEGREE | D7: MUDULE DIM. | E7: 1960X990X40
A8: STRUCTURE MEMBERS
A9: S.NO. | B9: DESCRIPTION | C9: SIZE(MM) | D9: LENGTH(MM) | E9: MATERIAL | F9: ACTUAL QUANTITY | G9: SPARE | H9: TOTAL QUANTITY | I9: Weight/Meter or per piece (kg/m)
A10: 1 | B10: RAFTER | C10: C120X60X20X3.15 | D10: 3215 | E10: HOT DIP GALVANISED STEEL | F10: =SUM('2X8'!G10,'2X15'!G10,'2X16'!G10) -> 240 | G10: 0 | H10: =SUM(F10:G10) -> 240 | I10: 6.92
A11: 2 | B11: COLUMN | C11: C120X60X20X3.15 | D11: 2912 | E11: HOT DIP GALVANISED STEEL | F11: =SUM('2X8'!G11,'2X15'!G11,'2X16'!G11) -> 240 | G11: 0 | H11: =SUM(F11:G11) -> 240 | I11: 6.92
A12: 3 | B12: PURLIN 1 (2X16 TABLE) | C12: C80X40X15X2 | D12: 5550 | E12: HOT DIP GALVANISED STEEL | F12: 44 | G12: 0 | H12: =SUM(F12:G12) -> 44 | I12: 4.7
A13: 4 | B13: PURLIN 2 (2X16 TABLE) | C13: C80X40X15X2 | D13: 5050 | E13: HOT DIP GALVANISED STEEL | F13: 44 | G13: 0 | H13: =SUM(F13:G13) -> 44 | I13: 4.7
A14: 5 | B14: PURLIN 3 (2X16 TABLE) | C14: C80X40X15X2 | D14: 5550 | E14: HOT DIP GALVANISED STEEL | F14: 44 | G14: 0 | H14: =SUM(F14:G14) -> 44 | I14: 4.7
A15: 3 | B15: PURLIN 1 (2X16 TABLE) | C15: C80X40X15X2 | D15: 5550 | E15: HOT DIP GALVANISED STEEL | F15: 96 | G15: 0 | H15: =SUM(F15:G15) -> 96 | I15: 4.7
A16: 4 | B16: PURLIN 2 (2X16 TABLE) | C16: C80X40X15X2 | D16: 5045 | E16: HOT DIP GALVANISED STEEL | F16: 96 | G16: 0 | H16: =SUM(F16:G16) -> 96 | I16: 4.7
A17: 5 | B17: PURLIN 3 (2X16 TABLE) | C17: C80X40X15X2 | D17: 5550 | E17: HOT DIP GALVANISED STEEL | F17: 96 | G17: 0 | H17: =SUM(F17:G17) -> 96 | I17: 4.7
A18: 3 | B18: PURLIN 1 (2X8 TABLE) | C18: C80X40X15X2 | D18: 4500 | E18: HOT DIP GALVANISED STEEL | F18: 40 | G18: 0 | H18: =SUM(F18:G18) -> 40 | I18: 4.7
A19: 4 | B19: PURLIN 2 (2X8 TABLE) | C19: C80X40X15X2 | D19: 3575 | E19: HOT DIP GALVANISED STEEL | F19: 40 | G19: 0 | H19: =SUM(F19:G19) -> 40 | I19: 4.7
A20: 6 | B20: BRACING-1 | C20: ISA-50X50X4 | D20: 1314 | E20: HOT DIP GALVANISED STEEL | F20: =SUM('2X8'!G14,'2X15'!G15,'2X16'!G15) -> 240 | G20: 1 | H20: =SUM(F20:G20) -> 241 | I20: 3.14
A21: 7 | B21: BRACING-2 | C21: ISA-50X50X4 | D21: 3043 | E21: HOT DIP GALVANISED STEEL | F21: =SUM('2X8'!G15,'2X15'!G16,'2X16'!G16) -> 160 | G21: 1 | H21: =SUM(F21:G21) -> 161 | I21: 3.14
A22: 8 | B22: BRACING CONNECTOR | C22: PL-150X100X4 | D22: 150 | E22: HOT DIP GALVANISED STEEL | F22: =SUM('2X8'!G16,'2X15'!G17,'2X16'!G17) -> 240 | G22: 8 | H22: =SUM(F22:G22) -> 248 | I22: 0.471
A23: 9 | B23: L-ANGLE CONNECTOR | C23: L-85X85X4 | D23: 85 | E23: HOT DIP GALVANISED STEEL | F23: =SUM('2X8'!G17,'2X15'!G18,'2X16'!G18) -> 880 | G23: 8 | H23: =SUM(F23:G23) -> 888 | I23: 0.23
A24: 11 | B24: PURLIN CONNECTOR | C24: PL-150X65X3 | D24: 150 | E24: HOT DIP GALVANISED STEEL | F24: =SUM('2X8'!G18,'2X15'!G19,'2X16'!G19) -> 320 | G24: 8 | H24: =SUM(F24:G24) -> 328
A26: FASTENERS /CLAMPS
A27: S.NO. | B27: DESCRIPTION | C27: SIZE(MM) | D27: LENGTH(MM) | E27: MATERIAL | F27: TOTAL QUANTITY | G27: SPARE | H27: TOTAL QUANTITY
A28: 1 | B28: HEX BOLT FOR MODULE | C28: M6 | D28: 20 | E28: SS-304 | F28: =SUM('2X8'!G22,'2X15'!G23,'2X16'!G23) -> 4928 | G28: 20 | H28: =SUM(F28:G28) -> 4948
A29: 2 | B29: HEX NUT FOR MODULE | C29: M6 | D29: - | E29: SS-304 | F29: =SUM('2X8'!G23,'2X15'!G24,'2X16'!G24) -> 4928 | G29: 20 | H29: =SUM(F29:G29) -> 4948
A30: 3 | B30: PLAIN WASHER | C30: M6 | D30: - | E30: SS-304 | F30: =SUM('2X8'!G24,'2X15'!G25,'2X16'!G25) -> 4928 | G30: 60 | H30: =SUM(F30:G30) -> 4988
A31: 4 | B31: SPRING WASHER | C31: M6 | D31: - | E31: SS-304 | F31: =SUM('2X8'!G25,'2X15'!G26,'2X16'!G26) -> 4928 | G31: 60 | H31: =SUM(F31:G31) -> 4988
A32: 5 | B32: HEX BOLT FOR COLUMN TO RAFTER CONNECTION | C32: M10 | D32: 30 | E32: SS-304 | F32: =SUM('2X8'!G26,'2X15'!G27,'2X16'!G27) -> 960 | G32: 20 | H32: =SUM(F32:G32) -> 980
A33: 6 | B33: HEX NUT FOR COLUMN TO RAFTER CONNECTION | C33: M10 | D33: - | E33: SS-304 | F33: =SUM('2X8'!G27,'2X15'!G28,'2X16'!G28) -> 960 | G33: 20 | H33: =SUM(F33:G33) -> 980
A34: 7 | B34: PLAIN WASHER | C34: M10 | D34: - | E34: SS-304 | F34: =SUM('2X8'!G28,'2X15'!G29,'2X16'!G29) -> 960 | G34: 20 | H34: =SUM(F34:G34) -> 980
A35: 8 | B35: HEX BOLT FOR L-CONNECTOR CONNECTION | C35: M10 | D35: 30 | E35: SS-304 | F35: =SUM('2X8'!G29,'2X15'!G30,'2X16'!G30) -> 1760 | G35: 20 | H35: =SUM(F35:G35) -> 1780
A36: 9 | B36: HEX NUT FOR L-CONNECTOR CONNECTION | C36: M10 | D36: - | E36: SS-304 | F36: =SUM('2X8'!G30,'2X15'!G31,'2X16'!G31) -> 1760 | G36: 60 | H36: =SUM(F36:G36) -> 1820
A37: 10 | B37: SPRING WASHER | C37: M10 | D37: - | E37: SS-304 | F37: =SUM('2X8'!G31,'2X15'!G32,'2X16'!G32) -> 1760 | G37: 60 | H37: =SUM(F37:G37) -> 1820
A38: 11 | B38: PLAIN WASHER | C38: M10 | D38: - | E38: SS-304 | F38: =SUM('2X8'!G32,'2X15'!G33,'2X16'!G33) -> 1760 | G38: 60 | H38: =SUM(F38:G38) -> 1820
A39: 12 | B39: HEX BOLT FOR BRACING-1 CONNECTION | C39: M12 | D39: 40 | E39: SS-304 | F39: =SUM('2X8'!G33,'2X15'!G34,'2X16'!G34) -> 960 | G39: 10 | H39: =SUM(F39:G39) -> 970
A40: 13 | B40: HEX NUT FOR BRACING-1 CONNECTION | C40: M12 | D40: - | E40: SS-304 | F40: =SUM('2X8'!G34,'2X15'!G35,'2X16'!G35) -> 960 | G40: 10 | H40: =SUM(F40:G40) -> 970
A41: 14 | B41: PLAIN WASHER | C41: M12 | D41: - | E41: SS-304 | F41: =SUM('2X8'!G35,'2X15'!G36,'2X16'!G36) -> 960 | G41: 20 | H41: =SUM(F41:G41) -> 980
...
